#VRML_SIM R2025a utf8

PROTO CelegansRobot [
  field SFVec3f     translation 0 0.03 0
  field SFRotation  rotation 0 1 0 0
  field SFString    name "celegans_robot"
  field SFString    controller "nao_nn_controller_uds"
  field MFString    controllerArgs [
    "NM_BRAINS=default"
  ]
  field MFNode      extensionSlot [ ]
]
{
  Robot {
    translation IS translation
    rotation IS rotation
    name IS name
    controller IS controller
    controllerArgs IS controllerArgs
    customData "{\"network\":\"../../network_celegans.json\",\"config\":\"../configs/config_celegans_webots.json\"}"
    children [
      Shape {
        appearance PBRAppearance {
          baseColor 0.88 0.63 0.43
          roughness 0.75
          metalness 0
        }
        geometry Capsule {
          radius 0.028
          height 0.34
        }
      }
      # Inertial + contact sensing
      Accelerometer {
        name "celegans_accel"
      }
      Gyro {
        name "celegans_gyro"
      }
      TouchSensor {
        name "celegans_bumper_front"
        type "bumper"
        translation 0.19 0.0 0.0
      }
      TouchSensor {
        name "celegans_bumper_rear"
        type "bumper"
        translation -0.19 0.0 0.0
      }
      # Multi-directional proximity sensing to create rich directional gradients.
      DistanceSensor {
        name "celegans_front"
        type "infra-red"
        translation 0.19000 0.0 0.00000
        lookupTable [
          0 1000 0
          1.40 0 0
        ]
      }
      DistanceSensor {
        name "celegans_front_left"
        type "infra-red"
        translation 0.15000 0.0 0.08000
        rotation 0 1 0 0.55000
        lookupTable [
          0 1000 0
          1.30 0 0
        ]
      }
      DistanceSensor {
        name "celegans_front_right"
        type "infra-red"
        translation 0.15000 0.0 -0.08000
        rotation 0 1 0 -0.55000
        lookupTable [
          0 1000 0
          1.30 0 0
        ]
      }
      DistanceSensor {
        name "celegans_front_far_left"
        type "infra-red"
        translation 0.10000 0.0 0.11000
        rotation 0 1 0 1.05000
        lookupTable [
          0 1000 0
          1.10 0 0
        ]
      }
      DistanceSensor {
        name "celegans_front_far_right"
        type "infra-red"
        translation 0.10000 0.0 -0.11000
        rotation 0 1 0 -1.05000
        lookupTable [
          0 1000 0
          1.10 0 0
        ]
      }
      DistanceSensor {
        name "celegans_left"
        type "infra-red"
        translation 0.00000 0.0 0.12000
        rotation 0 1 0 1.57080
        lookupTable [
          0 1000 0
          1.00 0 0
        ]
      }
      DistanceSensor {
        name "celegans_right"
        type "infra-red"
        translation 0.00000 0.0 -0.12000
        rotation 0 1 0 -1.57080
        lookupTable [
          0 1000 0
          1.00 0 0
        ]
      }
      DistanceSensor {
        name "celegans_rear_left"
        type "infra-red"
        translation -0.11000 0.0 0.08000
        rotation 0 1 0 2.60000
        lookupTable [
          0 1000 0
          1.10 0 0
        ]
      }
      DistanceSensor {
        name "celegans_rear_right"
        type "infra-red"
        translation -0.11000 0.0 -0.08000
        rotation 0 1 0 -2.60000
        lookupTable [
          0 1000 0
          1.10 0 0
        ]
      }
      DistanceSensor {
        name "celegans_rear_far_left"
        type "infra-red"
        translation -0.15000 0.0 0.06000
        rotation 0 1 0 2.20000
        lookupTable [
          0 1000 0
          1.20 0 0
        ]
      }
      DistanceSensor {
        name "celegans_rear_far_right"
        type "infra-red"
        translation -0.15000 0.0 -0.06000
        rotation 0 1 0 -2.20000
        lookupTable [
          0 1000 0
          1.20 0 0
        ]
      }
      DistanceSensor {
        name "celegans_rear"
        type "infra-red"
        translation -0.19000 0.0 0.00000
        rotation 0 1 0 3.14159
        lookupTable [
          0 1000 0
          1.40 0 0
        ]
      }

    DEF JOINT_0_MDL01 HingeJoint {
      jointParameters HingeJointParameters {
        anchor -0.17000 0.0 0.01800
        axis 0 1 0
      }
      device [
        RotationalMotor {
          name "MDL01"
          maxVelocity 8
          minPosition -1.3
          maxPosition 1.3
        }
      ]
      endPoint DEF SEGMENT_0_MDL01 Solid {
        name "SEGMENT_0_MDL01"
        translation -0.17000 0.0 0.01800
        children [
          Shape {
            appearance PBRAppearance {
              baseColor 0.78 0.46 0.29
              roughness 0.45
              metalness 0
            }
            geometry Sphere {
              radius 0.006
            }
          }
        ]
        boundingObject Sphere {
          radius 0.006
        }
        physics Physics {
          density -1
          mass 0.001
        }
      }
    }
    DEF JOINT_1_MDL02 HingeJoint {
      jointParameters HingeJointParameters {
        anchor -0.16642 0.0 -0.01800
        axis 0 1 0
      }
      device [
        RotationalMotor {
          name "MDL02"
          maxVelocity 8
          minPosition -1.3
          maxPosition 1.3
        }
      ]
      endPoint DEF SEGMENT_1_MDL02 Solid {
        name "SEGMENT_1_MDL02"
        translation -0.16642 0.0 -0.01800
        children [
          Shape {
            appearance PBRAppearance {
              baseColor 0.78 0.46 0.29
              roughness 0.45
              metalness 0
            }
            geometry Sphere {
              radius 0.006
            }
          }
        ]
        boundingObject Sphere {
          radius 0.006
        }
        physics Physics {
          density -1
          mass 0.001
        }
      }
    }
    DEF JOINT_2_MDL03 HingeJoint {
      jointParameters HingeJointParameters {
        anchor -0.16284 0.0 0.01800
        axis 0 1 0
      }
      device [
        RotationalMotor {
          name "MDL03"
          maxVelocity 8
          minPosition -1.3
          maxPosition 1.3
        }
      ]
      endPoint DEF SEGMENT_2_MDL03 Solid {
        name "SEGMENT_2_MDL03"
        translation -0.16284 0.0 0.01800
        children [
          Shape {
            appearance PBRAppearance {
              baseColor 0.78 0.46 0.29
              roughness 0.45
              metalness 0
            }
            geometry Sphere {
              radius 0.006
            }
          }
        ]
        boundingObject Sphere {
          radius 0.006
        }
        physics Physics {
          density -1
          mass 0.001
        }
      }
    }
    DEF JOINT_3_MDL04 HingeJoint {
      jointParameters HingeJointParameters {
        anchor -0.15926 0.0 -0.01800
        axis 0 1 0
      }
      device [
        RotationalMotor {
          name "MDL04"
          maxVelocity 8
          minPosition -1.3
          maxPosition 1.3
        }
      ]
      endPoint DEF SEGMENT_3_MDL04 Solid {
        name "SEGMENT_3_MDL04"
        translation -0.15926 0.0 -0.01800
        children [
          Shape {
            appearance PBRAppearance {
              baseColor 0.78 0.46 0.29
              roughness 0.45
              metalness 0
            }
            geometry Sphere {
              radius 0.006
            }
          }
        ]
        boundingObject Sphere {
          radius 0.006
        }
        physics Physics {
          density -1
          mass 0.001
        }
      }
    }
    DEF JOINT_4_MDL05 HingeJoint {
      jointParameters HingeJointParameters {
        anchor -0.15568 0.0 0.01800
        axis 0 1 0
      }
      device [
        RotationalMotor {
          name "MDL05"
          maxVelocity 8
          minPosition -1.3
          maxPosition 1.3
        }
      ]
      endPoint DEF SEGMENT_4_MDL05 Solid {
        name "SEGMENT_4_MDL05"
        translation -0.15568 0.0 0.01800
        children [
          Shape {
            appearance PBRAppearance {
              baseColor 0.78 0.46 0.29
              roughness 0.45
              metalness 0
            }
            geometry Sphere {
              radius 0.006
            }
          }
        ]
        boundingObject Sphere {
          radius 0.006
        }
        physics Physics {
          density -1
          mass 0.001
        }
      }
    }
    DEF JOINT_5_MDL06 HingeJoint {
      jointParameters HingeJointParameters {
        anchor -0.15211 0.0 -0.01800
        axis 0 1 0
      }
      device [
        RotationalMotor {
          name "MDL06"
          maxVelocity 8
          minPosition -1.3
          maxPosition 1.3
        }
      ]
      endPoint DEF SEGMENT_5_MDL06 Solid {
        name "SEGMENT_5_MDL06"
        translation -0.15211 0.0 -0.01800
        children [
          Shape {
            appearance PBRAppearance {
              baseColor 0.78 0.46 0.29
              roughness 0.45
              metalness 0
            }
            geometry Sphere {
              radius 0.006
            }
          }
        ]
        boundingObject Sphere {
          radius 0.006
        }
        physics Physics {
          density -1
          mass 0.001
        }
      }
    }
    DEF JOINT_6_MDL07 HingeJoint {
      jointParameters HingeJointParameters {
        anchor -0.14853 0.0 0.01800
        axis 0 1 0
      }
      device [
        RotationalMotor {
          name "MDL07"
          maxVelocity 8
          minPosition -1.3
          maxPosition 1.3
        }
      ]
      endPoint DEF SEGMENT_6_MDL07 Solid {
        name "SEGMENT_6_MDL07"
        translation -0.14853 0.0 0.01800
        children [
          Shape {
            appearance PBRAppearance {
              baseColor 0.78 0.46 0.29
              roughness 0.45
              metalness 0
            }
            geometry Sphere {
              radius 0.006
            }
          }
        ]
        boundingObject Sphere {
          radius 0.006
        }
        physics Physics {
          density -1
          mass 0.001
        }
      }
    }
    DEF JOINT_7_MDL08 HingeJoint {
      jointParameters HingeJointParameters {
        anchor -0.14495 0.0 -0.01800
        axis 0 1 0
      }
      device [
        RotationalMotor {
          name "MDL08"
          maxVelocity 8
          minPosition -1.3
          maxPosition 1.3
        }
      ]
      endPoint DEF SEGMENT_7_MDL08 Solid {
        name "SEGMENT_7_MDL08"
        translation -0.14495 0.0 -0.01800
        children [
          Shape {
            appearance PBRAppearance {
              baseColor 0.78 0.46 0.29
              roughness 0.45
              metalness 0
            }
            geometry Sphere {
              radius 0.006
            }
          }
        ]
        boundingObject Sphere {
          radius 0.006
        }
        physics Physics {
          density -1
          mass 0.001
        }
      }
    }
    DEF JOINT_8_MDL09 HingeJoint {
      jointParameters HingeJointParameters {
        anchor -0.14137 0.0 0.01800
        axis 0 1 0
      }
      device [
        RotationalMotor {
          name "MDL09"
          maxVelocity 8
          minPosition -1.3
          maxPosition 1.3
        }
      ]
      endPoint DEF SEGMENT_8_MDL09 Solid {
        name "SEGMENT_8_MDL09"
        translation -0.14137 0.0 0.01800
        children [
          Shape {
            appearance PBRAppearance {
              baseColor 0.78 0.46 0.29
              roughness 0.45
              metalness 0
            }
            geometry Sphere {
              radius 0.006
            }
          }
        ]
        boundingObject Sphere {
          radius 0.006
        }
        physics Physics {
          density -1
          mass 0.001
        }
      }
    }
    DEF JOINT_9_MDL10 HingeJoint {
      jointParameters HingeJointParameters {
        anchor -0.13779 0.0 -0.01800
        axis 0 1 0
      }
      device [
        RotationalMotor {
          name "MDL10"
          maxVelocity 8
          minPosition -1.3
          maxPosition 1.3
        }
      ]
      endPoint DEF SEGMENT_9_MDL10 Solid {
        name "SEGMENT_9_MDL10"
        translation -0.13779 0.0 -0.01800
        children [
          Shape {
            appearance PBRAppearance {
              baseColor 0.78 0.46 0.29
              roughness 0.45
              metalness 0
            }
            geometry Sphere {
              radius 0.006
            }
          }
        ]
        boundingObject Sphere {
          radius 0.006
        }
        physics Physics {
          density -1
          mass 0.001
        }
      }
    }
    DEF JOINT_10_MDL11 HingeJoint {
      jointParameters HingeJointParameters {
        anchor -0.13421 0.0 0.01800
        axis 0 1 0
      }
      device [
        RotationalMotor {
          name "MDL11"
          maxVelocity 8
          minPosition -1.3
          maxPosition 1.3
        }
      ]
      endPoint DEF SEGMENT_10_MDL11 Solid {
        name "SEGMENT_10_MDL11"
        translation -0.13421 0.0 0.01800
        children [
          Shape {
            appearance PBRAppearance {
              baseColor 0.78 0.46 0.29
              roughness 0.45
              metalness 0
            }
            geometry Sphere {
              radius 0.006
            }
          }
        ]
        boundingObject Sphere {
          radius 0.006
        }
        physics Physics {
          density -1
          mass 0.001
        }
      }
    }
    DEF JOINT_11_MDL12 HingeJoint {
      jointParameters HingeJointParameters {
        anchor -0.13063 0.0 -0.01800
        axis 0 1 0
      }
      device [
        RotationalMotor {
          name "MDL12"
          maxVelocity 8
          minPosition -1.3
          maxPosition 1.3
        }
      ]
      endPoint DEF SEGMENT_11_MDL12 Solid {
        name "SEGMENT_11_MDL12"
        translation -0.13063 0.0 -0.01800
        children [
          Shape {
            appearance PBRAppearance {
              baseColor 0.78 0.46 0.29
              roughness 0.45
              metalness 0
            }
            geometry Sphere {
              radius 0.006
            }
          }
        ]
        boundingObject Sphere {
          radius 0.006
        }
        physics Physics {
          density -1
          mass 0.001
        }
      }
    }
    DEF JOINT_12_MDL13 HingeJoint {
      jointParameters HingeJointParameters {
        anchor -0.12705 0.0 0.01800
        axis 0 1 0
      }
      device [
        RotationalMotor {
          name "MDL13"
          maxVelocity 8
          minPosition -1.3
          maxPosition 1.3
        }
      ]
      endPoint DEF SEGMENT_12_MDL13 Solid {
        name "SEGMENT_12_MDL13"
        translation -0.12705 0.0 0.01800
        children [
          Shape {
            appearance PBRAppearance {
              baseColor 0.78 0.46 0.29
              roughness 0.45
              metalness 0
            }
            geometry Sphere {
              radius 0.006
            }
          }
        ]
        boundingObject Sphere {
          radius 0.006
        }
        physics Physics {
          density -1
          mass 0.001
        }
      }
    }
    DEF JOINT_13_MDL14 HingeJoint {
      jointParameters HingeJointParameters {
        anchor -0.12347 0.0 -0.01800
        axis 0 1 0
      }
      device [
        RotationalMotor {
          name "MDL14"
          maxVelocity 8
          minPosition -1.3
          maxPosition 1.3
        }
      ]
      endPoint DEF SEGMENT_13_MDL14 Solid {
        name "SEGMENT_13_MDL14"
        translation -0.12347 0.0 -0.01800
        children [
          Shape {
            appearance PBRAppearance {
              baseColor 0.78 0.46 0.29
              roughness 0.45
              metalness 0
            }
            geometry Sphere {
              radius 0.006
            }
          }
        ]
        boundingObject Sphere {
          radius 0.006
        }
        physics Physics {
          density -1
          mass 0.001
        }
      }
    }
    DEF JOINT_14_MDL15 HingeJoint {
      jointParameters HingeJointParameters {
        anchor -0.11989 0.0 0.01800
        axis 0 1 0
      }
      device [
        RotationalMotor {
          name "MDL15"
          maxVelocity 8
          minPosition -1.3
          maxPosition 1.3
        }
      ]
      endPoint DEF SEGMENT_14_MDL15 Solid {
        name "SEGMENT_14_MDL15"
        translation -0.11989 0.0 0.01800
        children [
          Shape {
            appearance PBRAppearance {
              baseColor 0.78 0.46 0.29
              roughness 0.45
              metalness 0
            }
            geometry Sphere {
              radius 0.006
            }
          }
        ]
        boundingObject Sphere {
          radius 0.006
        }
        physics Physics {
          density -1
          mass 0.001
        }
      }
    }
    DEF JOINT_15_MDL16 HingeJoint {
      jointParameters HingeJointParameters {
        anchor -0.11632 0.0 -0.01800
        axis 0 1 0
      }
      device [
        RotationalMotor {
          name "MDL16"
          maxVelocity 8
          minPosition -1.3
          maxPosition 1.3
        }
      ]
      endPoint DEF SEGMENT_15_MDL16 Solid {
        name "SEGMENT_15_MDL16"
        translation -0.11632 0.0 -0.01800
        children [
          Shape {
            appearance PBRAppearance {
              baseColor 0.78 0.46 0.29
              roughness 0.45
              metalness 0
            }
            geometry Sphere {
              radius 0.006
            }
          }
        ]
        boundingObject Sphere {
          radius 0.006
        }
        physics Physics {
          density -1
          mass 0.001
        }
      }
    }
    DEF JOINT_16_MDL17 HingeJoint {
      jointParameters HingeJointParameters {
        anchor -0.11274 0.0 0.01800
        axis 0 1 0
      }
      device [
        RotationalMotor {
          name "MDL17"
          maxVelocity 8
          minPosition -1.3
          maxPosition 1.3
        }
      ]
      endPoint DEF SEGMENT_16_MDL17 Solid {
        name "SEGMENT_16_MDL17"
        translation -0.11274 0.0 0.01800
        children [
          Shape {
            appearance PBRAppearance {
              baseColor 0.78 0.46 0.29
              roughness 0.45
              metalness 0
            }
            geometry Sphere {
              radius 0.006
            }
          }
        ]
        boundingObject Sphere {
          radius 0.006
        }
        physics Physics {
          density -1
          mass 0.001
        }
      }
    }
    DEF JOINT_17_MDL18 HingeJoint {
      jointParameters HingeJointParameters {
        anchor -0.10916 0.0 -0.01800
        axis 0 1 0
      }
      device [
        RotationalMotor {
          name "MDL18"
          maxVelocity 8
          minPosition -1.3
          maxPosition 1.3
        }
      ]
      endPoint DEF SEGMENT_17_MDL18 Solid {
        name "SEGMENT_17_MDL18"
        translation -0.10916 0.0 -0.01800
        children [
          Shape {
            appearance PBRAppearance {
              baseColor 0.78 0.46 0.29
              roughness 0.45
              metalness 0
            }
            geometry Sphere {
              radius 0.006
            }
          }
        ]
        boundingObject Sphere {
          radius 0.006
        }
        physics Physics {
          density -1
          mass 0.001
        }
      }
    }
    DEF JOINT_18_MDL19 HingeJoint {
      jointParameters HingeJointParameters {
        anchor -0.10558 0.0 0.01800
        axis 0 1 0
      }
      device [
        RotationalMotor {
          name "MDL19"
          maxVelocity 8
          minPosition -1.3
          maxPosition 1.3
        }
      ]
      endPoint DEF SEGMENT_18_MDL19 Solid {
        name "SEGMENT_18_MDL19"
        translation -0.10558 0.0 0.01800
        children [
          Shape {
            appearance PBRAppearance {
              baseColor 0.78 0.46 0.29
              roughness 0.45
              metalness 0
            }
            geometry Sphere {
              radius 0.006
            }
          }
        ]
        boundingObject Sphere {
          radius 0.006
        }
        physics Physics {
          density -1
          mass 0.001
        }
      }
    }
    DEF JOINT_19_MDL20 HingeJoint {
      jointParameters HingeJointParameters {
        anchor -0.10200 0.0 -0.01800
        axis 0 1 0
      }
      device [
        RotationalMotor {
          name "MDL20"
          maxVelocity 8
          minPosition -1.3
          maxPosition 1.3
        }
      ]
      endPoint DEF SEGMENT_19_MDL20 Solid {
        name "SEGMENT_19_MDL20"
        translation -0.10200 0.0 -0.01800
        children [
          Shape {
            appearance PBRAppearance {
              baseColor 0.78 0.46 0.29
              roughness 0.45
              metalness 0
            }
            geometry Sphere {
              radius 0.006
            }
          }
        ]
        boundingObject Sphere {
          radius 0.006
        }
        physics Physics {
          density -1
          mass 0.001
        }
      }
    }
    DEF JOINT_20_MDL21 HingeJoint {
      jointParameters HingeJointParameters {
        anchor -0.09842 0.0 0.01800
        axis 0 1 0
      }
      device [
        RotationalMotor {
          name "MDL21"
          maxVelocity 8
          minPosition -1.3
          maxPosition 1.3
        }
      ]
      endPoint DEF SEGMENT_20_MDL21 Solid {
        name "SEGMENT_20_MDL21"
        translation -0.09842 0.0 0.01800
        children [
          Shape {
            appearance PBRAppearance {
              baseColor 0.78 0.46 0.29
              roughness 0.45
              metalness 0
            }
            geometry Sphere {
              radius 0.006
            }
          }
        ]
        boundingObject Sphere {
          radius 0.006
        }
        physics Physics {
          density -1
          mass 0.001
        }
      }
    }
    DEF JOINT_21_MDL22 HingeJoint {
      jointParameters HingeJointParameters {
        anchor -0.09484 0.0 -0.01800
        axis 0 1 0
      }
      device [
        RotationalMotor {
          name "MDL22"
          maxVelocity 8
          minPosition -1.3
          maxPosition 1.3
        }
      ]
      endPoint DEF SEGMENT_21_MDL22 Solid {
        name "SEGMENT_21_MDL22"
        translation -0.09484 0.0 -0.01800
        children [
          Shape {
            appearance PBRAppearance {
              baseColor 0.78 0.46 0.29
              roughness 0.45
              metalness 0
            }
            geometry Sphere {
              radius 0.006
            }
          }
        ]
        boundingObject Sphere {
          radius 0.006
        }
        physics Physics {
          density -1
          mass 0.001
        }
      }
    }
    DEF JOINT_22_MDL23 HingeJoint {
      jointParameters HingeJointParameters {
        anchor -0.09126 0.0 0.01800
        axis 0 1 0
      }
      device [
        RotationalMotor {
          name "MDL23"
          maxVelocity 8
          minPosition -1.3
          maxPosition 1.3
        }
      ]
      endPoint DEF SEGMENT_22_MDL23 Solid {
        name "SEGMENT_22_MDL23"
        translation -0.09126 0.0 0.01800
        children [
          Shape {
            appearance PBRAppearance {
              baseColor 0.78 0.46 0.29
              roughness 0.45
              metalness 0
            }
            geometry Sphere {
              radius 0.006
            }
          }
        ]
        boundingObject Sphere {
          radius 0.006
        }
        physics Physics {
          density -1
          mass 0.001
        }
      }
    }
    DEF JOINT_23_MDL24 HingeJoint {
      jointParameters HingeJointParameters {
        anchor -0.08768 0.0 -0.01800
        axis 0 1 0
      }
      device [
        RotationalMotor {
          name "MDL24"
          maxVelocity 8
          minPosition -1.3
          maxPosition 1.3
        }
      ]
      endPoint DEF SEGMENT_23_MDL24 Solid {
        name "SEGMENT_23_MDL24"
        translation -0.08768 0.0 -0.01800
        children [
          Shape {
            appearance PBRAppearance {
              baseColor 0.78 0.46 0.29
              roughness 0.45
              metalness 0
            }
            geometry Sphere {
              radius 0.006
            }
          }
        ]
        boundingObject Sphere {
          radius 0.006
        }
        physics Physics {
          density -1
          mass 0.001
        }
      }
    }
    DEF JOINT_24_MDR01 HingeJoint {
      jointParameters HingeJointParameters {
        anchor -0.08411 0.0 0.01800
        axis 0 1 0
      }
      device [
        RotationalMotor {
          name "MDR01"
          maxVelocity 8
          minPosition -1.3
          maxPosition 1.3
        }
      ]
      endPoint DEF SEGMENT_24_MDR01 Solid {
        name "SEGMENT_24_MDR01"
        translation -0.08411 0.0 0.01800
        children [
          Shape {
            appearance PBRAppearance {
              baseColor 0.78 0.46 0.29
              roughness 0.45
              metalness 0
            }
            geometry Sphere {
              radius 0.006
            }
          }
        ]
        boundingObject Sphere {
          radius 0.006
        }
        physics Physics {
          density -1
          mass 0.001
        }
      }
    }
    DEF JOINT_25_MDR02 HingeJoint {
      jointParameters HingeJointParameters {
        anchor -0.08053 0.0 -0.01800
        axis 0 1 0
      }
      device [
        RotationalMotor {
          name "MDR02"
          maxVelocity 8
          minPosition -1.3
          maxPosition 1.3
        }
      ]
      endPoint DEF SEGMENT_25_MDR02 Solid {
        name "SEGMENT_25_MDR02"
        translation -0.08053 0.0 -0.01800
        children [
          Shape {
            appearance PBRAppearance {
              baseColor 0.78 0.46 0.29
              roughness 0.45
              metalness 0
            }
            geometry Sphere {
              radius 0.006
            }
          }
        ]
        boundingObject Sphere {
          radius 0.006
        }
        physics Physics {
          density -1
          mass 0.001
        }
      }
    }
    DEF JOINT_26_MDR03 HingeJoint {
      jointParameters HingeJointParameters {
        anchor -0.07695 0.0 0.01800
        axis 0 1 0
      }
      device [
        RotationalMotor {
          name "MDR03"
          maxVelocity 8
          minPosition -1.3
          maxPosition 1.3
        }
      ]
      endPoint DEF SEGMENT_26_MDR03 Solid {
        name "SEGMENT_26_MDR03"
        translation -0.07695 0.0 0.01800
        children [
          Shape {
            appearance PBRAppearance {
              baseColor 0.78 0.46 0.29
              roughness 0.45
              metalness 0
            }
            geometry Sphere {
              radius 0.006
            }
          }
        ]
        boundingObject Sphere {
          radius 0.006
        }
        physics Physics {
          density -1
          mass 0.001
        }
      }
    }
    DEF JOINT_27_MDR04 HingeJoint {
      jointParameters HingeJointParameters {
        anchor -0.07337 0.0 -0.01800
        axis 0 1 0
      }
      device [
        RotationalMotor {
          name "MDR04"
          maxVelocity 8
          minPosition -1.3
          maxPosition 1.3
        }
      ]
      endPoint DEF SEGMENT_27_MDR04 Solid {
        name "SEGMENT_27_MDR04"
        translation -0.07337 0.0 -0.01800
        children [
          Shape {
            appearance PBRAppearance {
              baseColor 0.78 0.46 0.29
              roughness 0.45
              metalness 0
            }
            geometry Sphere {
              radius 0.006
            }
          }
        ]
        boundingObject Sphere {
          radius 0.006
        }
        physics Physics {
          density -1
          mass 0.001
        }
      }
    }
    DEF JOINT_28_MDR05 HingeJoint {
      jointParameters HingeJointParameters {
        anchor -0.06979 0.0 0.01800
        axis 0 1 0
      }
      device [
        RotationalMotor {
          name "MDR05"
          maxVelocity 8
          minPosition -1.3
          maxPosition 1.3
        }
      ]
      endPoint DEF SEGMENT_28_MDR05 Solid {
        name "SEGMENT_28_MDR05"
        translation -0.06979 0.0 0.01800
        children [
          Shape {
            appearance PBRAppearance {
              baseColor 0.78 0.46 0.29
              roughness 0.45
              metalness 0
            }
            geometry Sphere {
              radius 0.006
            }
          }
        ]
        boundingObject Sphere {
          radius 0.006
        }
        physics Physics {
          density -1
          mass 0.001
        }
      }
    }
    DEF JOINT_29_MDR06 HingeJoint {
      jointParameters HingeJointParameters {
        anchor -0.06621 0.0 -0.01800
        axis 0 1 0
      }
      device [
        RotationalMotor {
          name "MDR06"
          maxVelocity 8
          minPosition -1.3
          maxPosition 1.3
        }
      ]
      endPoint DEF SEGMENT_29_MDR06 Solid {
        name "SEGMENT_29_MDR06"
        translation -0.06621 0.0 -0.01800
        children [
          Shape {
            appearance PBRAppearance {
              baseColor 0.78 0.46 0.29
              roughness 0.45
              metalness 0
            }
            geometry Sphere {
              radius 0.006
            }
          }
        ]
        boundingObject Sphere {
          radius 0.006
        }
        physics Physics {
          density -1
          mass 0.001
        }
      }
    }
    DEF JOINT_30_MDR07 HingeJoint {
      jointParameters HingeJointParameters {
        anchor -0.06263 0.0 0.01800
        axis 0 1 0
      }
      device [
        RotationalMotor {
          name "MDR07"
          maxVelocity 8
          minPosition -1.3
          maxPosition 1.3
        }
      ]
      endPoint DEF SEGMENT_30_MDR07 Solid {
        name "SEGMENT_30_MDR07"
        translation -0.06263 0.0 0.01800
        children [
          Shape {
            appearance PBRAppearance {
              baseColor 0.78 0.46 0.29
              roughness 0.45
              metalness 0
            }
            geometry Sphere {
              radius 0.006
            }
          }
        ]
        boundingObject Sphere {
          radius 0.006
        }
        physics Physics {
          density -1
          mass 0.001
        }
      }
    }
    DEF JOINT_31_MDR08 HingeJoint {
      jointParameters HingeJointParameters {
        anchor -0.05905 0.0 -0.01800
        axis 0 1 0
      }
      device [
        RotationalMotor {
          name "MDR08"
          maxVelocity 8
          minPosition -1.3
          maxPosition 1.3
        }
      ]
      endPoint DEF SEGMENT_31_MDR08 Solid {
        name "SEGMENT_31_MDR08"
        translation -0.05905 0.0 -0.01800
        children [
          Shape {
            appearance PBRAppearance {
              baseColor 0.78 0.46 0.29
              roughness 0.45
              metalness 0
            }
            geometry Sphere {
              radius 0.006
            }
          }
        ]
        boundingObject Sphere {
          radius 0.006
        }
        physics Physics {
          density -1
          mass 0.001
        }
      }
    }
    DEF JOINT_32_MDR09 HingeJoint {
      jointParameters HingeJointParameters {
        anchor -0.05547 0.0 0.01800
        axis 0 1 0
      }
      device [
        RotationalMotor {
          name "MDR09"
          maxVelocity 8
          minPosition -1.3
          maxPosition 1.3
        }
      ]
      endPoint DEF SEGMENT_32_MDR09 Solid {
        name "SEGMENT_32_MDR09"
        translation -0.05547 0.0 0.01800
        children [
          Shape {
            appearance PBRAppearance {
              baseColor 0.78 0.46 0.29
              roughness 0.45
              metalness 0
            }
            geometry Sphere {
              radius 0.006
            }
          }
        ]
        boundingObject Sphere {
          radius 0.006
        }
        physics Physics {
          density -1
          mass 0.001
        }
      }
    }
    DEF JOINT_33_MDR10 HingeJoint {
      jointParameters HingeJointParameters {
        anchor -0.05189 0.0 -0.01800
        axis 0 1 0
      }
      device [
        RotationalMotor {
          name "MDR10"
          maxVelocity 8
          minPosition -1.3
          maxPosition 1.3
        }
      ]
      endPoint DEF SEGMENT_33_MDR10 Solid {
        name "SEGMENT_33_MDR10"
        translation -0.05189 0.0 -0.01800
        children [
          Shape {
            appearance PBRAppearance {
              baseColor 0.78 0.46 0.29
              roughness 0.45
              metalness 0
            }
            geometry Sphere {
              radius 0.006
            }
          }
        ]
        boundingObject Sphere {
          radius 0.006
        }
        physics Physics {
          density -1
          mass 0.001
        }
      }
    }
    DEF JOINT_34_MDR11 HingeJoint {
      jointParameters HingeJointParameters {
        anchor -0.04832 0.0 0.01800
        axis 0 1 0
      }
      device [
        RotationalMotor {
          name "MDR11"
          maxVelocity 8
          minPosition -1.3
          maxPosition 1.3
        }
      ]
      endPoint DEF SEGMENT_34_MDR11 Solid {
        name "SEGMENT_34_MDR11"
        translation -0.04832 0.0 0.01800
        children [
          Shape {
            appearance PBRAppearance {
              baseColor 0.78 0.46 0.29
              roughness 0.45
              metalness 0
            }
            geometry Sphere {
              radius 0.006
            }
          }
        ]
        boundingObject Sphere {
          radius 0.006
        }
        physics Physics {
          density -1
          mass 0.001
        }
      }
    }
    DEF JOINT_35_MDR12 HingeJoint {
      jointParameters HingeJointParameters {
        anchor -0.04474 0.0 -0.01800
        axis 0 1 0
      }
      device [
        RotationalMotor {
          name "MDR12"
          maxVelocity 8
          minPosition -1.3
          maxPosition 1.3
        }
      ]
      endPoint DEF SEGMENT_35_MDR12 Solid {
        name "SEGMENT_35_MDR12"
        translation -0.04474 0.0 -0.01800
        children [
          Shape {
            appearance PBRAppearance {
              baseColor 0.78 0.46 0.29
              roughness 0.45
              metalness 0
            }
            geometry Sphere {
              radius 0.006
            }
          }
        ]
        boundingObject Sphere {
          radius 0.006
        }
        physics Physics {
          density -1
          mass 0.001
        }
      }
    }
    DEF JOINT_36_MDR13 HingeJoint {
      jointParameters HingeJointParameters {
        anchor -0.04116 0.0 0.01800
        axis 0 1 0
      }
      device [
        RotationalMotor {
          name "MDR13"
          maxVelocity 8
          minPosition -1.3
          maxPosition 1.3
        }
      ]
      endPoint DEF SEGMENT_36_MDR13 Solid {
        name "SEGMENT_36_MDR13"
        translation -0.04116 0.0 0.01800
        children [
          Shape {
            appearance PBRAppearance {
              baseColor 0.78 0.46 0.29
              roughness 0.45
              metalness 0
            }
            geometry Sphere {
              radius 0.006
            }
          }
        ]
        boundingObject Sphere {
          radius 0.006
        }
        physics Physics {
          density -1
          mass 0.001
        }
      }
    }
    DEF JOINT_37_MDR14 HingeJoint {
      jointParameters HingeJointParameters {
        anchor -0.03758 0.0 -0.01800
        axis 0 1 0
      }
      device [
        RotationalMotor {
          name "MDR14"
          maxVelocity 8
          minPosition -1.3
          maxPosition 1.3
        }
      ]
      endPoint DEF SEGMENT_37_MDR14 Solid {
        name "SEGMENT_37_MDR14"
        translation -0.03758 0.0 -0.01800
        children [
          Shape {
            appearance PBRAppearance {
              baseColor 0.78 0.46 0.29
              roughness 0.45
              metalness 0
            }
            geometry Sphere {
              radius 0.006
            }
          }
        ]
        boundingObject Sphere {
          radius 0.006
        }
        physics Physics {
          density -1
          mass 0.001
        }
      }
    }
    DEF JOINT_38_MDR15 HingeJoint {
      jointParameters HingeJointParameters {
        anchor -0.03400 0.0 0.01800
        axis 0 1 0
      }
      device [
        RotationalMotor {
          name "MDR15"
          maxVelocity 8
          minPosition -1.3
          maxPosition 1.3
        }
      ]
      endPoint DEF SEGMENT_38_MDR15 Solid {
        name "SEGMENT_38_MDR15"
        translation -0.03400 0.0 0.01800
        children [
          Shape {
            appearance PBRAppearance {
              baseColor 0.78 0.46 0.29
              roughness 0.45
              metalness 0
            }
            geometry Sphere {
              radius 0.006
            }
          }
        ]
        boundingObject Sphere {
          radius 0.006
        }
        physics Physics {
          density -1
          mass 0.001
        }
      }
    }
    DEF JOINT_39_MDR16 HingeJoint {
      jointParameters HingeJointParameters {
        anchor -0.03042 0.0 -0.01800
        axis 0 1 0
      }
      device [
        RotationalMotor {
          name "MDR16"
          maxVelocity 8
          minPosition -1.3
          maxPosition 1.3
        }
      ]
      endPoint DEF SEGMENT_39_MDR16 Solid {
        name "SEGMENT_39_MDR16"
        translation -0.03042 0.0 -0.01800
        children [
          Shape {
            appearance PBRAppearance {
              baseColor 0.78 0.46 0.29
              roughness 0.45
              metalness 0
            }
            geometry Sphere {
              radius 0.006
            }
          }
        ]
        boundingObject Sphere {
          radius 0.006
        }
        physics Physics {
          density -1
          mass 0.001
        }
      }
    }
    DEF JOINT_40_MDR17 HingeJoint {
      jointParameters HingeJointParameters {
        anchor -0.02684 0.0 0.01800
        axis 0 1 0
      }
      device [
        RotationalMotor {
          name "MDR17"
          maxVelocity 8
          minPosition -1.3
          maxPosition 1.3
        }
      ]
      endPoint DEF SEGMENT_40_MDR17 Solid {
        name "SEGMENT_40_MDR17"
        translation -0.02684 0.0 0.01800
        children [
          Shape {
            appearance PBRAppearance {
              baseColor 0.78 0.46 0.29
              roughness 0.45
              metalness 0
            }
            geometry Sphere {
              radius 0.006
            }
          }
        ]
        boundingObject Sphere {
          radius 0.006
        }
        physics Physics {
          density -1
          mass 0.001
        }
      }
    }
    DEF JOINT_41_MDR18 HingeJoint {
      jointParameters HingeJointParameters {
        anchor -0.02326 0.0 -0.01800
        axis 0 1 0
      }
      device [
        RotationalMotor {
          name "MDR18"
          maxVelocity 8
          minPosition -1.3
          maxPosition 1.3
        }
      ]
      endPoint DEF SEGMENT_41_MDR18 Solid {
        name "SEGMENT_41_MDR18"
        translation -0.02326 0.0 -0.01800
        children [
          Shape {
            appearance PBRAppearance {
              baseColor 0.78 0.46 0.29
              roughness 0.45
              metalness 0
            }
            geometry Sphere {
              radius 0.006
            }
          }
        ]
        boundingObject Sphere {
          radius 0.006
        }
        physics Physics {
          density -1
          mass 0.001
        }
      }
    }
    DEF JOINT_42_MDR19 HingeJoint {
      jointParameters HingeJointParameters {
        anchor -0.01968 0.0 0.01800
        axis 0 1 0
      }
      device [
        RotationalMotor {
          name "MDR19"
          maxVelocity 8
          minPosition -1.3
          maxPosition 1.3
        }
      ]
      endPoint DEF SEGMENT_42_MDR19 Solid {
        name "SEGMENT_42_MDR19"
        translation -0.01968 0.0 0.01800
        children [
          Shape {
            appearance PBRAppearance {
              baseColor 0.78 0.46 0.29
              roughness 0.45
              metalness 0
            }
            geometry Sphere {
              radius 0.006
            }
          }
        ]
        boundingObject Sphere {
          radius 0.006
        }
        physics Physics {
          density -1
          mass 0.001
        }
      }
    }
    DEF JOINT_43_MDR20 HingeJoint {
      jointParameters HingeJointParameters {
        anchor -0.01611 0.0 -0.01800
        axis 0 1 0
      }
      device [
        RotationalMotor {
          name "MDR20"
          maxVelocity 8
          minPosition -1.3
          maxPosition 1.3
        }
      ]
      endPoint DEF SEGMENT_43_MDR20 Solid {
        name "SEGMENT_43_MDR20"
        translation -0.01611 0.0 -0.01800
        children [
          Shape {
            appearance PBRAppearance {
              baseColor 0.78 0.46 0.29
              roughness 0.45
              metalness 0
            }
            geometry Sphere {
              radius 0.006
            }
          }
        ]
        boundingObject Sphere {
          radius 0.006
        }
        physics Physics {
          density -1
          mass 0.001
        }
      }
    }
    DEF JOINT_44_MDR21 HingeJoint {
      jointParameters HingeJointParameters {
        anchor -0.01253 0.0 0.01800
        axis 0 1 0
      }
      device [
        RotationalMotor {
          name "MDR21"
          maxVelocity 8
          minPosition -1.3
          maxPosition 1.3
        }
      ]
      endPoint DEF SEGMENT_44_MDR21 Solid {
        name "SEGMENT_44_MDR21"
        translation -0.01253 0.0 0.01800
        children [
          Shape {
            appearance PBRAppearance {
              baseColor 0.78 0.46 0.29
              roughness 0.45
              metalness 0
            }
            geometry Sphere {
              radius 0.006
            }
          }
        ]
        boundingObject Sphere {
          radius 0.006
        }
        physics Physics {
          density -1
          mass 0.001
        }
      }
    }
    DEF JOINT_45_MDR22 HingeJoint {
      jointParameters HingeJointParameters {
        anchor -0.00895 0.0 -0.01800
        axis 0 1 0
      }
      device [
        RotationalMotor {
          name "MDR22"
          maxVelocity 8
          minPosition -1.3
          maxPosition 1.3
        }
      ]
      endPoint DEF SEGMENT_45_MDR22 Solid {
        name "SEGMENT_45_MDR22"
        translation -0.00895 0.0 -0.01800
        children [
          Shape {
            appearance PBRAppearance {
              baseColor 0.78 0.46 0.29
              roughness 0.45
              metalness 0
            }
            geometry Sphere {
              radius 0.006
            }
          }
        ]
        boundingObject Sphere {
          radius 0.006
        }
        physics Physics {
          density -1
          mass 0.001
        }
      }
    }
    DEF JOINT_46_MDR23 HingeJoint {
      jointParameters HingeJointParameters {
        anchor -0.00537 0.0 0.01800
        axis 0 1 0
      }
      device [
        RotationalMotor {
          name "MDR23"
          maxVelocity 8
          minPosition -1.3
          maxPosition 1.3
        }
      ]
      endPoint DEF SEGMENT_46_MDR23 Solid {
        name "SEGMENT_46_MDR23"
        translation -0.00537 0.0 0.01800
        children [
          Shape {
            appearance PBRAppearance {
              baseColor 0.78 0.46 0.29
              roughness 0.45
              metalness 0
            }
            geometry Sphere {
              radius 0.006
            }
          }
        ]
        boundingObject Sphere {
          radius 0.006
        }
        physics Physics {
          density -1
          mass 0.001
        }
      }
    }
    DEF JOINT_47_MDR24 HingeJoint {
      jointParameters HingeJointParameters {
        anchor -0.00179 0.0 -0.01800
        axis 0 1 0
      }
      device [
        RotationalMotor {
          name "MDR24"
          maxVelocity 8
          minPosition -1.3
          maxPosition 1.3
        }
      ]
      endPoint DEF SEGMENT_47_MDR24 Solid {
        name "SEGMENT_47_MDR24"
        translation -0.00179 0.0 -0.01800
        children [
          Shape {
            appearance PBRAppearance {
              baseColor 0.78 0.46 0.29
              roughness 0.45
              metalness 0
            }
            geometry Sphere {
              radius 0.006
            }
          }
        ]
        boundingObject Sphere {
          radius 0.006
        }
        physics Physics {
          density -1
          mass 0.001
        }
      }
    }
    DEF JOINT_48_MVL01 HingeJoint {
      jointParameters HingeJointParameters {
        anchor 0.00179 0.0 0.01800
        axis 0 1 0
      }
      device [
        RotationalMotor {
          name "MVL01"
          maxVelocity 8
          minPosition -1.3
          maxPosition 1.3
        }
      ]
      endPoint DEF SEGMENT_48_MVL01 Solid {
        name "SEGMENT_48_MVL01"
        translation 0.00179 0.0 0.01800
        children [
          Shape {
            appearance PBRAppearance {
              baseColor 0.78 0.46 0.29
              roughness 0.45
              metalness 0
            }
            geometry Sphere {
              radius 0.006
            }
          }
        ]
        boundingObject Sphere {
          radius 0.006
        }
        physics Physics {
          density -1
          mass 0.001
        }
      }
    }
    DEF JOINT_49_MVL02 HingeJoint {
      jointParameters HingeJointParameters {
        anchor 0.00537 0.0 -0.01800
        axis 0 1 0
      }
      device [
        RotationalMotor {
          name "MVL02"
          maxVelocity 8
          minPosition -1.3
          maxPosition 1.3
        }
      ]
      endPoint DEF SEGMENT_49_MVL02 Solid {
        name "SEGMENT_49_MVL02"
        translation 0.00537 0.0 -0.01800
        children [
          Shape {
            appearance PBRAppearance {
              baseColor 0.78 0.46 0.29
              roughness 0.45
              metalness 0
            }
            geometry Sphere {
              radius 0.006
            }
          }
        ]
        boundingObject Sphere {
          radius 0.006
        }
        physics Physics {
          density -1
          mass 0.001
        }
      }
    }
    DEF JOINT_50_MVL03 HingeJoint {
      jointParameters HingeJointParameters {
        anchor 0.00895 0.0 0.01800
        axis 0 1 0
      }
      device [
        RotationalMotor {
          name "MVL03"
          maxVelocity 8
          minPosition -1.3
          maxPosition 1.3
        }
      ]
      endPoint DEF SEGMENT_50_MVL03 Solid {
        name "SEGMENT_50_MVL03"
        translation 0.00895 0.0 0.01800
        children [
          Shape {
            appearance PBRAppearance {
              baseColor 0.78 0.46 0.29
              roughness 0.45
              metalness 0
            }
            geometry Sphere {
              radius 0.006
            }
          }
        ]
        boundingObject Sphere {
          radius 0.006
        }
        physics Physics {
          density -1
          mass 0.001
        }
      }
    }
    DEF JOINT_51_MVL04 HingeJoint {
      jointParameters HingeJointParameters {
        anchor 0.01253 0.0 -0.01800
        axis 0 1 0
      }
      device [
        RotationalMotor {
          name "MVL04"
          maxVelocity 8
          minPosition -1.3
          maxPosition 1.3
        }
      ]
      endPoint DEF SEGMENT_51_MVL04 Solid {
        name "SEGMENT_51_MVL04"
        translation 0.01253 0.0 -0.01800
        children [
          Shape {
            appearance PBRAppearance {
              baseColor 0.78 0.46 0.29
              roughness 0.45
              metalness 0
            }
            geometry Sphere {
              radius 0.006
            }
          }
        ]
        boundingObject Sphere {
          radius 0.006
        }
        physics Physics {
          density -1
          mass 0.001
        }
      }
    }
    DEF JOINT_52_MVL05 HingeJoint {
      jointParameters HingeJointParameters {
        anchor 0.01611 0.0 0.01800
        axis 0 1 0
      }
      device [
        RotationalMotor {
          name "MVL05"
          maxVelocity 8
          minPosition -1.3
          maxPosition 1.3
        }
      ]
      endPoint DEF SEGMENT_52_MVL05 Solid {
        name "SEGMENT_52_MVL05"
        translation 0.01611 0.0 0.01800
        children [
          Shape {
            appearance PBRAppearance {
              baseColor 0.78 0.46 0.29
              roughness 0.45
              metalness 0
            }
            geometry Sphere {
              radius 0.006
            }
          }
        ]
        boundingObject Sphere {
          radius 0.006
        }
        physics Physics {
          density -1
          mass 0.001
        }
      }
    }
    DEF JOINT_53_MVL06 HingeJoint {
      jointParameters HingeJointParameters {
        anchor 0.01968 0.0 -0.01800
        axis 0 1 0
      }
      device [
        RotationalMotor {
          name "MVL06"
          maxVelocity 8
          minPosition -1.3
          maxPosition 1.3
        }
      ]
      endPoint DEF SEGMENT_53_MVL06 Solid {
        name "SEGMENT_53_MVL06"
        translation 0.01968 0.0 -0.01800
        children [
          Shape {
            appearance PBRAppearance {
              baseColor 0.78 0.46 0.29
              roughness 0.45
              metalness 0
            }
            geometry Sphere {
              radius 0.006
            }
          }
        ]
        boundingObject Sphere {
          radius 0.006
        }
        physics Physics {
          density -1
          mass 0.001
        }
      }
    }
    DEF JOINT_54_MVL07 HingeJoint {
      jointParameters HingeJointParameters {
        anchor 0.02326 0.0 0.01800
        axis 0 1 0
      }
      device [
        RotationalMotor {
          name "MVL07"
          maxVelocity 8
          minPosition -1.3
          maxPosition 1.3
        }
      ]
      endPoint DEF SEGMENT_54_MVL07 Solid {
        name "SEGMENT_54_MVL07"
        translation 0.02326 0.0 0.01800
        children [
          Shape {
            appearance PBRAppearance {
              baseColor 0.78 0.46 0.29
              roughness 0.45
              metalness 0
            }
            geometry Sphere {
              radius 0.006
            }
          }
        ]
        boundingObject Sphere {
          radius 0.006
        }
        physics Physics {
          density -1
          mass 0.001
        }
      }
    }
    DEF JOINT_55_MVL08 HingeJoint {
      jointParameters HingeJointParameters {
        anchor 0.02684 0.0 -0.01800
        axis 0 1 0
      }
      device [
        RotationalMotor {
          name "MVL08"
          maxVelocity 8
          minPosition -1.3
          maxPosition 1.3
        }
      ]
      endPoint DEF SEGMENT_55_MVL08 Solid {
        name "SEGMENT_55_MVL08"
        translation 0.02684 0.0 -0.01800
        children [
          Shape {
            appearance PBRAppearance {
              baseColor 0.78 0.46 0.29
              roughness 0.45
              metalness 0
            }
            geometry Sphere {
              radius 0.006
            }
          }
        ]
        boundingObject Sphere {
          radius 0.006
        }
        physics Physics {
          density -1
          mass 0.001
        }
      }
    }
    DEF JOINT_56_MVL09 HingeJoint {
      jointParameters HingeJointParameters {
        anchor 0.03042 0.0 0.01800
        axis 0 1 0
      }
      device [
        RotationalMotor {
          name "MVL09"
          maxVelocity 8
          minPosition -1.3
          maxPosition 1.3
        }
      ]
      endPoint DEF SEGMENT_56_MVL09 Solid {
        name "SEGMENT_56_MVL09"
        translation 0.03042 0.0 0.01800
        children [
          Shape {
            appearance PBRAppearance {
              baseColor 0.78 0.46 0.29
              roughness 0.45
              metalness 0
            }
            geometry Sphere {
              radius 0.006
            }
          }
        ]
        boundingObject Sphere {
          radius 0.006
        }
        physics Physics {
          density -1
          mass 0.001
        }
      }
    }
    DEF JOINT_57_MVL10 HingeJoint {
      jointParameters HingeJointParameters {
        anchor 0.03400 0.0 -0.01800
        axis 0 1 0
      }
      device [
        RotationalMotor {
          name "MVL10"
          maxVelocity 8
          minPosition -1.3
          maxPosition 1.3
        }
      ]
      endPoint DEF SEGMENT_57_MVL10 Solid {
        name "SEGMENT_57_MVL10"
        translation 0.03400 0.0 -0.01800
        children [
          Shape {
            appearance PBRAppearance {
              baseColor 0.78 0.46 0.29
              roughness 0.45
              metalness 0
            }
            geometry Sphere {
              radius 0.006
            }
          }
        ]
        boundingObject Sphere {
          radius 0.006
        }
        physics Physics {
          density -1
          mass 0.001
        }
      }
    }
    DEF JOINT_58_MVL11 HingeJoint {
      jointParameters HingeJointParameters {
        anchor 0.03758 0.0 0.01800
        axis 0 1 0
      }
      device [
        RotationalMotor {
          name "MVL11"
          maxVelocity 8
          minPosition -1.3
          maxPosition 1.3
        }
      ]
      endPoint DEF SEGMENT_58_MVL11 Solid {
        name "SEGMENT_58_MVL11"
        translation 0.03758 0.0 0.01800
        children [
          Shape {
            appearance PBRAppearance {
              baseColor 0.78 0.46 0.29
              roughness 0.45
              metalness 0
            }
            geometry Sphere {
              radius 0.006
            }
          }
        ]
        boundingObject Sphere {
          radius 0.006
        }
        physics Physics {
          density -1
          mass 0.001
        }
      }
    }
    DEF JOINT_59_MVL12 HingeJoint {
      jointParameters HingeJointParameters {
        anchor 0.04116 0.0 -0.01800
        axis 0 1 0
      }
      device [
        RotationalMotor {
          name "MVL12"
          maxVelocity 8
          minPosition -1.3
          maxPosition 1.3
        }
      ]
      endPoint DEF SEGMENT_59_MVL12 Solid {
        name "SEGMENT_59_MVL12"
        translation 0.04116 0.0 -0.01800
        children [
          Shape {
            appearance PBRAppearance {
              baseColor 0.78 0.46 0.29
              roughness 0.45
              metalness 0
            }
            geometry Sphere {
              radius 0.006
            }
          }
        ]
        boundingObject Sphere {
          radius 0.006
        }
        physics Physics {
          density -1
          mass 0.001
        }
      }
    }
    DEF JOINT_60_MVL13 HingeJoint {
      jointParameters HingeJointParameters {
        anchor 0.04474 0.0 0.01800
        axis 0 1 0
      }
      device [
        RotationalMotor {
          name "MVL13"
          maxVelocity 8
          minPosition -1.3
          maxPosition 1.3
        }
      ]
      endPoint DEF SEGMENT_60_MVL13 Solid {
        name "SEGMENT_60_MVL13"
        translation 0.04474 0.0 0.01800
        children [
          Shape {
            appearance PBRAppearance {
              baseColor 0.78 0.46 0.29
              roughness 0.45
              metalness 0
            }
            geometry Sphere {
              radius 0.006
            }
          }
        ]
        boundingObject Sphere {
          radius 0.006
        }
        physics Physics {
          density -1
          mass 0.001
        }
      }
    }
    DEF JOINT_61_MVL14 HingeJoint {
      jointParameters HingeJointParameters {
        anchor 0.04832 0.0 -0.01800
        axis 0 1 0
      }
      device [
        RotationalMotor {
          name "MVL14"
          maxVelocity 8
          minPosition -1.3
          maxPosition 1.3
        }
      ]
      endPoint DEF SEGMENT_61_MVL14 Solid {
        name "SEGMENT_61_MVL14"
        translation 0.04832 0.0 -0.01800
        children [
          Shape {
            appearance PBRAppearance {
              baseColor 0.78 0.46 0.29
              roughness 0.45
              metalness 0
            }
            geometry Sphere {
              radius 0.006
            }
          }
        ]
        boundingObject Sphere {
          radius 0.006
        }
        physics Physics {
          density -1
          mass 0.001
        }
      }
    }
    DEF JOINT_62_MVL15 HingeJoint {
      jointParameters HingeJointParameters {
        anchor 0.05189 0.0 0.01800
        axis 0 1 0
      }
      device [
        RotationalMotor {
          name "MVL15"
          maxVelocity 8
          minPosition -1.3
          maxPosition 1.3
        }
      ]
      endPoint DEF SEGMENT_62_MVL15 Solid {
        name "SEGMENT_62_MVL15"
        translation 0.05189 0.0 0.01800
        children [
          Shape {
            appearance PBRAppearance {
              baseColor 0.78 0.46 0.29
              roughness 0.45
              metalness 0
            }
            geometry Sphere {
              radius 0.006
            }
          }
        ]
        boundingObject Sphere {
          radius 0.006
        }
        physics Physics {
          density -1
          mass 0.001
        }
      }
    }
    DEF JOINT_63_MVL16 HingeJoint {
      jointParameters HingeJointParameters {
        anchor 0.05547 0.0 -0.01800
        axis 0 1 0
      }
      device [
        RotationalMotor {
          name "MVL16"
          maxVelocity 8
          minPosition -1.3
          maxPosition 1.3
        }
      ]
      endPoint DEF SEGMENT_63_MVL16 Solid {
        name "SEGMENT_63_MVL16"
        translation 0.05547 0.0 -0.01800
        children [
          Shape {
            appearance PBRAppearance {
              baseColor 0.78 0.46 0.29
              roughness 0.45
              metalness 0
            }
            geometry Sphere {
              radius 0.006
            }
          }
        ]
        boundingObject Sphere {
          radius 0.006
        }
        physics Physics {
          density -1
          mass 0.001
        }
      }
    }
    DEF JOINT_64_MVL17 HingeJoint {
      jointParameters HingeJointParameters {
        anchor 0.05905 0.0 0.01800
        axis 0 1 0
      }
      device [
        RotationalMotor {
          name "MVL17"
          maxVelocity 8
          minPosition -1.3
          maxPosition 1.3
        }
      ]
      endPoint DEF SEGMENT_64_MVL17 Solid {
        name "SEGMENT_64_MVL17"
        translation 0.05905 0.0 0.01800
        children [
          Shape {
            appearance PBRAppearance {
              baseColor 0.78 0.46 0.29
              roughness 0.45
              metalness 0
            }
            geometry Sphere {
              radius 0.006
            }
          }
        ]
        boundingObject Sphere {
          radius 0.006
        }
        physics Physics {
          density -1
          mass 0.001
        }
      }
    }
    DEF JOINT_65_MVL18 HingeJoint {
      jointParameters HingeJointParameters {
        anchor 0.06263 0.0 -0.01800
        axis 0 1 0
      }
      device [
        RotationalMotor {
          name "MVL18"
          maxVelocity 8
          minPosition -1.3
          maxPosition 1.3
        }
      ]
      endPoint DEF SEGMENT_65_MVL18 Solid {
        name "SEGMENT_65_MVL18"
        translation 0.06263 0.0 -0.01800
        children [
          Shape {
            appearance PBRAppearance {
              baseColor 0.78 0.46 0.29
              roughness 0.45
              metalness 0
            }
            geometry Sphere {
              radius 0.006
            }
          }
        ]
        boundingObject Sphere {
          radius 0.006
        }
        physics Physics {
          density -1
          mass 0.001
        }
      }
    }
    DEF JOINT_66_MVL19 HingeJoint {
      jointParameters HingeJointParameters {
        anchor 0.06621 0.0 0.01800
        axis 0 1 0
      }
      device [
        RotationalMotor {
          name "MVL19"
          maxVelocity 8
          minPosition -1.3
          maxPosition 1.3
        }
      ]
      endPoint DEF SEGMENT_66_MVL19 Solid {
        name "SEGMENT_66_MVL19"
        translation 0.06621 0.0 0.01800
        children [
          Shape {
            appearance PBRAppearance {
              baseColor 0.78 0.46 0.29
              roughness 0.45
              metalness 0
            }
            geometry Sphere {
              radius 0.006
            }
          }
        ]
        boundingObject Sphere {
          radius 0.006
        }
        physics Physics {
          density -1
          mass 0.001
        }
      }
    }
    DEF JOINT_67_MVL20 HingeJoint {
      jointParameters HingeJointParameters {
        anchor 0.06979 0.0 -0.01800
        axis 0 1 0
      }
      device [
        RotationalMotor {
          name "MVL20"
          maxVelocity 8
          minPosition -1.3
          maxPosition 1.3
        }
      ]
      endPoint DEF SEGMENT_67_MVL20 Solid {
        name "SEGMENT_67_MVL20"
        translation 0.06979 0.0 -0.01800
        children [
          Shape {
            appearance PBRAppearance {
              baseColor 0.78 0.46 0.29
              roughness 0.45
              metalness 0
            }
            geometry Sphere {
              radius 0.006
            }
          }
        ]
        boundingObject Sphere {
          radius 0.006
        }
        physics Physics {
          density -1
          mass 0.001
        }
      }
    }
    DEF JOINT_68_MVL21 HingeJoint {
      jointParameters HingeJointParameters {
        anchor 0.07337 0.0 0.01800
        axis 0 1 0
      }
      device [
        RotationalMotor {
          name "MVL21"
          maxVelocity 8
          minPosition -1.3
          maxPosition 1.3
        }
      ]
      endPoint DEF SEGMENT_68_MVL21 Solid {
        name "SEGMENT_68_MVL21"
        translation 0.07337 0.0 0.01800
        children [
          Shape {
            appearance PBRAppearance {
              baseColor 0.78 0.46 0.29
              roughness 0.45
              metalness 0
            }
            geometry Sphere {
              radius 0.006
            }
          }
        ]
        boundingObject Sphere {
          radius 0.006
        }
        physics Physics {
          density -1
          mass 0.001
        }
      }
    }
    DEF JOINT_69_MVL22 HingeJoint {
      jointParameters HingeJointParameters {
        anchor 0.07695 0.0 -0.01800
        axis 0 1 0
      }
      device [
        RotationalMotor {
          name "MVL22"
          maxVelocity 8
          minPosition -1.3
          maxPosition 1.3
        }
      ]
      endPoint DEF SEGMENT_69_MVL22 Solid {
        name "SEGMENT_69_MVL22"
        translation 0.07695 0.0 -0.01800
        children [
          Shape {
            appearance PBRAppearance {
              baseColor 0.78 0.46 0.29
              roughness 0.45
              metalness 0
            }
            geometry Sphere {
              radius 0.006
            }
          }
        ]
        boundingObject Sphere {
          radius 0.006
        }
        physics Physics {
          density -1
          mass 0.001
        }
      }
    }
    DEF JOINT_70_MVL23 HingeJoint {
      jointParameters HingeJointParameters {
        anchor 0.08053 0.0 0.01800
        axis 0 1 0
      }
      device [
        RotationalMotor {
          name "MVL23"
          maxVelocity 8
          minPosition -1.3
          maxPosition 1.3
        }
      ]
      endPoint DEF SEGMENT_70_MVL23 Solid {
        name "SEGMENT_70_MVL23"
        translation 0.08053 0.0 0.01800
        children [
          Shape {
            appearance PBRAppearance {
              baseColor 0.78 0.46 0.29
              roughness 0.45
              metalness 0
            }
            geometry Sphere {
              radius 0.006
            }
          }
        ]
        boundingObject Sphere {
          radius 0.006
        }
        physics Physics {
          density -1
          mass 0.001
        }
      }
    }
    DEF JOINT_71_MVR01 HingeJoint {
      jointParameters HingeJointParameters {
        anchor 0.08411 0.0 -0.01800
        axis 0 1 0
      }
      device [
        RotationalMotor {
          name "MVR01"
          maxVelocity 8
          minPosition -1.3
          maxPosition 1.3
        }
      ]
      endPoint DEF SEGMENT_71_MVR01 Solid {
        name "SEGMENT_71_MVR01"
        translation 0.08411 0.0 -0.01800
        children [
          Shape {
            appearance PBRAppearance {
              baseColor 0.78 0.46 0.29
              roughness 0.45
              metalness 0
            }
            geometry Sphere {
              radius 0.006
            }
          }
        ]
        boundingObject Sphere {
          radius 0.006
        }
        physics Physics {
          density -1
          mass 0.001
        }
      }
    }
    DEF JOINT_72_MVR02 HingeJoint {
      jointParameters HingeJointParameters {
        anchor 0.08768 0.0 0.01800
        axis 0 1 0
      }
      device [
        RotationalMotor {
          name "MVR02"
          maxVelocity 8
          minPosition -1.3
          maxPosition 1.3
        }
      ]
      endPoint DEF SEGMENT_72_MVR02 Solid {
        name "SEGMENT_72_MVR02"
        translation 0.08768 0.0 0.01800
        children [
          Shape {
            appearance PBRAppearance {
              baseColor 0.78 0.46 0.29
              roughness 0.45
              metalness 0
            }
            geometry Sphere {
              radius 0.006
            }
          }
        ]
        boundingObject Sphere {
          radius 0.006
        }
        physics Physics {
          density -1
          mass 0.001
        }
      }
    }
    DEF JOINT_73_MVR03 HingeJoint {
      jointParameters HingeJointParameters {
        anchor 0.09126 0.0 -0.01800
        axis 0 1 0
      }
      device [
        RotationalMotor {
          name "MVR03"
          maxVelocity 8
          minPosition -1.3
          maxPosition 1.3
        }
      ]
      endPoint DEF SEGMENT_73_MVR03 Solid {
        name "SEGMENT_73_MVR03"
        translation 0.09126 0.0 -0.01800
        children [
          Shape {
            appearance PBRAppearance {
              baseColor 0.78 0.46 0.29
              roughness 0.45
              metalness 0
            }
            geometry Sphere {
              radius 0.006
            }
          }
        ]
        boundingObject Sphere {
          radius 0.006
        }
        physics Physics {
          density -1
          mass 0.001
        }
      }
    }
    DEF JOINT_74_MVR04 HingeJoint {
      jointParameters HingeJointParameters {
        anchor 0.09484 0.0 0.01800
        axis 0 1 0
      }
      device [
        RotationalMotor {
          name "MVR04"
          maxVelocity 8
          minPosition -1.3
          maxPosition 1.3
        }
      ]
      endPoint DEF SEGMENT_74_MVR04 Solid {
        name "SEGMENT_74_MVR04"
        translation 0.09484 0.0 0.01800
        children [
          Shape {
            appearance PBRAppearance {
              baseColor 0.78 0.46 0.29
              roughness 0.45
              metalness 0
            }
            geometry Sphere {
              radius 0.006
            }
          }
        ]
        boundingObject Sphere {
          radius 0.006
        }
        physics Physics {
          density -1
          mass 0.001
        }
      }
    }
    DEF JOINT_75_MVR05 HingeJoint {
      jointParameters HingeJointParameters {
        anchor 0.09842 0.0 -0.01800
        axis 0 1 0
      }
      device [
        RotationalMotor {
          name "MVR05"
          maxVelocity 8
          minPosition -1.3
          maxPosition 1.3
        }
      ]
      endPoint DEF SEGMENT_75_MVR05 Solid {
        name "SEGMENT_75_MVR05"
        translation 0.09842 0.0 -0.01800
        children [
          Shape {
            appearance PBRAppearance {
              baseColor 0.78 0.46 0.29
              roughness 0.45
              metalness 0
            }
            geometry Sphere {
              radius 0.006
            }
          }
        ]
        boundingObject Sphere {
          radius 0.006
        }
        physics Physics {
          density -1
          mass 0.001
        }
      }
    }
    DEF JOINT_76_MVR06 HingeJoint {
      jointParameters HingeJointParameters {
        anchor 0.10200 0.0 0.01800
        axis 0 1 0
      }
      device [
        RotationalMotor {
          name "MVR06"
          maxVelocity 8
          minPosition -1.3
          maxPosition 1.3
        }
      ]
      endPoint DEF SEGMENT_76_MVR06 Solid {
        name "SEGMENT_76_MVR06"
        translation 0.10200 0.0 0.01800
        children [
          Shape {
            appearance PBRAppearance {
              baseColor 0.78 0.46 0.29
              roughness 0.45
              metalness 0
            }
            geometry Sphere {
              radius 0.006
            }
          }
        ]
        boundingObject Sphere {
          radius 0.006
        }
        physics Physics {
          density -1
          mass 0.001
        }
      }
    }
    DEF JOINT_77_MVR07 HingeJoint {
      jointParameters HingeJointParameters {
        anchor 0.10558 0.0 -0.01800
        axis 0 1 0
      }
      device [
        RotationalMotor {
          name "MVR07"
          maxVelocity 8
          minPosition -1.3
          maxPosition 1.3
        }
      ]
      endPoint DEF SEGMENT_77_MVR07 Solid {
        name "SEGMENT_77_MVR07"
        translation 0.10558 0.0 -0.01800
        children [
          Shape {
            appearance PBRAppearance {
              baseColor 0.78 0.46 0.29
              roughness 0.45
              metalness 0
            }
            geometry Sphere {
              radius 0.006
            }
          }
        ]
        boundingObject Sphere {
          radius 0.006
        }
        physics Physics {
          density -1
          mass 0.001
        }
      }
    }
    DEF JOINT_78_MVR08 HingeJoint {
      jointParameters HingeJointParameters {
        anchor 0.10916 0.0 0.01800
        axis 0 1 0
      }
      device [
        RotationalMotor {
          name "MVR08"
          maxVelocity 8
          minPosition -1.3
          maxPosition 1.3
        }
      ]
      endPoint DEF SEGMENT_78_MVR08 Solid {
        name "SEGMENT_78_MVR08"
        translation 0.10916 0.0 0.01800
        children [
          Shape {
            appearance PBRAppearance {
              baseColor 0.78 0.46 0.29
              roughness 0.45
              metalness 0
            }
            geometry Sphere {
              radius 0.006
            }
          }
        ]
        boundingObject Sphere {
          radius 0.006
        }
        physics Physics {
          density -1
          mass 0.001
        }
      }
    }
    DEF JOINT_79_MVR09 HingeJoint {
      jointParameters HingeJointParameters {
        anchor 0.11274 0.0 -0.01800
        axis 0 1 0
      }
      device [
        RotationalMotor {
          name "MVR09"
          maxVelocity 8
          minPosition -1.3
          maxPosition 1.3
        }
      ]
      endPoint DEF SEGMENT_79_MVR09 Solid {
        name "SEGMENT_79_MVR09"
        translation 0.11274 0.0 -0.01800
        children [
          Shape {
            appearance PBRAppearance {
              baseColor 0.78 0.46 0.29
              roughness 0.45
              metalness 0
            }
            geometry Sphere {
              radius 0.006
            }
          }
        ]
        boundingObject Sphere {
          radius 0.006
        }
        physics Physics {
          density -1
          mass 0.001
        }
      }
    }
    DEF JOINT_80_MVR10 HingeJoint {
      jointParameters HingeJointParameters {
        anchor 0.11632 0.0 0.01800
        axis 0 1 0
      }
      device [
        RotationalMotor {
          name "MVR10"
          maxVelocity 8
          minPosition -1.3
          maxPosition 1.3
        }
      ]
      endPoint DEF SEGMENT_80_MVR10 Solid {
        name "SEGMENT_80_MVR10"
        translation 0.11632 0.0 0.01800
        children [
          Shape {
            appearance PBRAppearance {
              baseColor 0.78 0.46 0.29
              roughness 0.45
              metalness 0
            }
            geometry Sphere {
              radius 0.006
            }
          }
        ]
        boundingObject Sphere {
          radius 0.006
        }
        physics Physics {
          density -1
          mass 0.001
        }
      }
    }
    DEF JOINT_81_MVR11 HingeJoint {
      jointParameters HingeJointParameters {
        anchor 0.11989 0.0 -0.01800
        axis 0 1 0
      }
      device [
        RotationalMotor {
          name "MVR11"
          maxVelocity 8
          minPosition -1.3
          maxPosition 1.3
        }
      ]
      endPoint DEF SEGMENT_81_MVR11 Solid {
        name "SEGMENT_81_MVR11"
        translation 0.11989 0.0 -0.01800
        children [
          Shape {
            appearance PBRAppearance {
              baseColor 0.78 0.46 0.29
              roughness 0.45
              metalness 0
            }
            geometry Sphere {
              radius 0.006
            }
          }
        ]
        boundingObject Sphere {
          radius 0.006
        }
        physics Physics {
          density -1
          mass 0.001
        }
      }
    }
    DEF JOINT_82_MVR12 HingeJoint {
      jointParameters HingeJointParameters {
        anchor 0.12347 0.0 0.01800
        axis 0 1 0
      }
      device [
        RotationalMotor {
          name "MVR12"
          maxVelocity 8
          minPosition -1.3
          maxPosition 1.3
        }
      ]
      endPoint DEF SEGMENT_82_MVR12 Solid {
        name "SEGMENT_82_MVR12"
        translation 0.12347 0.0 0.01800
        children [
          Shape {
            appearance PBRAppearance {
              baseColor 0.78 0.46 0.29
              roughness 0.45
              metalness 0
            }
            geometry Sphere {
              radius 0.006
            }
          }
        ]
        boundingObject Sphere {
          radius 0.006
        }
        physics Physics {
          density -1
          mass 0.001
        }
      }
    }
    DEF JOINT_83_MVR13 HingeJoint {
      jointParameters HingeJointParameters {
        anchor 0.12705 0.0 -0.01800
        axis 0 1 0
      }
      device [
        RotationalMotor {
          name "MVR13"
          maxVelocity 8
          minPosition -1.3
          maxPosition 1.3
        }
      ]
      endPoint DEF SEGMENT_83_MVR13 Solid {
        name "SEGMENT_83_MVR13"
        translation 0.12705 0.0 -0.01800
        children [
          Shape {
            appearance PBRAppearance {
              baseColor 0.78 0.46 0.29
              roughness 0.45
              metalness 0
            }
            geometry Sphere {
              radius 0.006
            }
          }
        ]
        boundingObject Sphere {
          radius 0.006
        }
        physics Physics {
          density -1
          mass 0.001
        }
      }
    }
    DEF JOINT_84_MVR14 HingeJoint {
      jointParameters HingeJointParameters {
        anchor 0.13063 0.0 0.01800
        axis 0 1 0
      }
      device [
        RotationalMotor {
          name "MVR14"
          maxVelocity 8
          minPosition -1.3
          maxPosition 1.3
        }
      ]
      endPoint DEF SEGMENT_84_MVR14 Solid {
        name "SEGMENT_84_MVR14"
        translation 0.13063 0.0 0.01800
        children [
          Shape {
            appearance PBRAppearance {
              baseColor 0.78 0.46 0.29
              roughness 0.45
              metalness 0
            }
            geometry Sphere {
              radius 0.006
            }
          }
        ]
        boundingObject Sphere {
          radius 0.006
        }
        physics Physics {
          density -1
          mass 0.001
        }
      }
    }
    DEF JOINT_85_MVR15 HingeJoint {
      jointParameters HingeJointParameters {
        anchor 0.13421 0.0 -0.01800
        axis 0 1 0
      }
      device [
        RotationalMotor {
          name "MVR15"
          maxVelocity 8
          minPosition -1.3
          maxPosition 1.3
        }
      ]
      endPoint DEF SEGMENT_85_MVR15 Solid {
        name "SEGMENT_85_MVR15"
        translation 0.13421 0.0 -0.01800
        children [
          Shape {
            appearance PBRAppearance {
              baseColor 0.78 0.46 0.29
              roughness 0.45
              metalness 0
            }
            geometry Sphere {
              radius 0.006
            }
          }
        ]
        boundingObject Sphere {
          radius 0.006
        }
        physics Physics {
          density -1
          mass 0.001
        }
      }
    }
    DEF JOINT_86_MVR16 HingeJoint {
      jointParameters HingeJointParameters {
        anchor 0.13779 0.0 0.01800
        axis 0 1 0
      }
      device [
        RotationalMotor {
          name "MVR16"
          maxVelocity 8
          minPosition -1.3
          maxPosition 1.3
        }
      ]
      endPoint DEF SEGMENT_86_MVR16 Solid {
        name "SEGMENT_86_MVR16"
        translation 0.13779 0.0 0.01800
        children [
          Shape {
            appearance PBRAppearance {
              baseColor 0.78 0.46 0.29
              roughness 0.45
              metalness 0
            }
            geometry Sphere {
              radius 0.006
            }
          }
        ]
        boundingObject Sphere {
          radius 0.006
        }
        physics Physics {
          density -1
          mass 0.001
        }
      }
    }
    DEF JOINT_87_MVR17 HingeJoint {
      jointParameters HingeJointParameters {
        anchor 0.14137 0.0 -0.01800
        axis 0 1 0
      }
      device [
        RotationalMotor {
          name "MVR17"
          maxVelocity 8
          minPosition -1.3
          maxPosition 1.3
        }
      ]
      endPoint DEF SEGMENT_87_MVR17 Solid {
        name "SEGMENT_87_MVR17"
        translation 0.14137 0.0 -0.01800
        children [
          Shape {
            appearance PBRAppearance {
              baseColor 0.78 0.46 0.29
              roughness 0.45
              metalness 0
            }
            geometry Sphere {
              radius 0.006
            }
          }
        ]
        boundingObject Sphere {
          radius 0.006
        }
        physics Physics {
          density -1
          mass 0.001
        }
      }
    }
    DEF JOINT_88_MVR18 HingeJoint {
      jointParameters HingeJointParameters {
        anchor 0.14495 0.0 0.01800
        axis 0 1 0
      }
      device [
        RotationalMotor {
          name "MVR18"
          maxVelocity 8
          minPosition -1.3
          maxPosition 1.3
        }
      ]
      endPoint DEF SEGMENT_88_MVR18 Solid {
        name "SEGMENT_88_MVR18"
        translation 0.14495 0.0 0.01800
        children [
          Shape {
            appearance PBRAppearance {
              baseColor 0.78 0.46 0.29
              roughness 0.45
              metalness 0
            }
            geometry Sphere {
              radius 0.006
            }
          }
        ]
        boundingObject Sphere {
          radius 0.006
        }
        physics Physics {
          density -1
          mass 0.001
        }
      }
    }
    DEF JOINT_89_MVR19 HingeJoint {
      jointParameters HingeJointParameters {
        anchor 0.14853 0.0 -0.01800
        axis 0 1 0
      }
      device [
        RotationalMotor {
          name "MVR19"
          maxVelocity 8
          minPosition -1.3
          maxPosition 1.3
        }
      ]
      endPoint DEF SEGMENT_89_MVR19 Solid {
        name "SEGMENT_89_MVR19"
        translation 0.14853 0.0 -0.01800
        children [
          Shape {
            appearance PBRAppearance {
              baseColor 0.78 0.46 0.29
              roughness 0.45
              metalness 0
            }
            geometry Sphere {
              radius 0.006
            }
          }
        ]
        boundingObject Sphere {
          radius 0.006
        }
        physics Physics {
          density -1
          mass 0.001
        }
      }
    }
    DEF JOINT_90_MVR20 HingeJoint {
      jointParameters HingeJointParameters {
        anchor 0.15211 0.0 0.01800
        axis 0 1 0
      }
      device [
        RotationalMotor {
          name "MVR20"
          maxVelocity 8
          minPosition -1.3
          maxPosition 1.3
        }
      ]
      endPoint DEF SEGMENT_90_MVR20 Solid {
        name "SEGMENT_90_MVR20"
        translation 0.15211 0.0 0.01800
        children [
          Shape {
            appearance PBRAppearance {
              baseColor 0.78 0.46 0.29
              roughness 0.45
              metalness 0
            }
            geometry Sphere {
              radius 0.006
            }
          }
        ]
        boundingObject Sphere {
          radius 0.006
        }
        physics Physics {
          density -1
          mass 0.001
        }
      }
    }
    DEF JOINT_91_MVR21 HingeJoint {
      jointParameters HingeJointParameters {
        anchor 0.15568 0.0 -0.01800
        axis 0 1 0
      }
      device [
        RotationalMotor {
          name "MVR21"
          maxVelocity 8
          minPosition -1.3
          maxPosition 1.3
        }
      ]
      endPoint DEF SEGMENT_91_MVR21 Solid {
        name "SEGMENT_91_MVR21"
        translation 0.15568 0.0 -0.01800
        children [
          Shape {
            appearance PBRAppearance {
              baseColor 0.78 0.46 0.29
              roughness 0.45
              metalness 0
            }
            geometry Sphere {
              radius 0.006
            }
          }
        ]
        boundingObject Sphere {
          radius 0.006
        }
        physics Physics {
          density -1
          mass 0.001
        }
      }
    }
    DEF JOINT_92_MVR22 HingeJoint {
      jointParameters HingeJointParameters {
        anchor 0.15926 0.0 0.01800
        axis 0 1 0
      }
      device [
        RotationalMotor {
          name "MVR22"
          maxVelocity 8
          minPosition -1.3
          maxPosition 1.3
        }
      ]
      endPoint DEF SEGMENT_92_MVR22 Solid {
        name "SEGMENT_92_MVR22"
        translation 0.15926 0.0 0.01800
        children [
          Shape {
            appearance PBRAppearance {
              baseColor 0.78 0.46 0.29
              roughness 0.45
              metalness 0
            }
            geometry Sphere {
              radius 0.006
            }
          }
        ]
        boundingObject Sphere {
          radius 0.006
        }
        physics Physics {
          density -1
          mass 0.001
        }
      }
    }
    DEF JOINT_93_MVR23 HingeJoint {
      jointParameters HingeJointParameters {
        anchor 0.16284 0.0 -0.01800
        axis 0 1 0
      }
      device [
        RotationalMotor {
          name "MVR23"
          maxVelocity 8
          minPosition -1.3
          maxPosition 1.3
        }
      ]
      endPoint DEF SEGMENT_93_MVR23 Solid {
        name "SEGMENT_93_MVR23"
        translation 0.16284 0.0 -0.01800
        children [
          Shape {
            appearance PBRAppearance {
              baseColor 0.78 0.46 0.29
              roughness 0.45
              metalness 0
            }
            geometry Sphere {
              radius 0.006
            }
          }
        ]
        boundingObject Sphere {
          radius 0.006
        }
        physics Physics {
          density -1
          mass 0.001
        }
      }
    }
    DEF JOINT_94_MVR24 HingeJoint {
      jointParameters HingeJointParameters {
        anchor 0.16642 0.0 0.01800
        axis 0 1 0
      }
      device [
        RotationalMotor {
          name "MVR24"
          maxVelocity 8
          minPosition -1.3
          maxPosition 1.3
        }
      ]
      endPoint DEF SEGMENT_94_MVR24 Solid {
        name "SEGMENT_94_MVR24"
        translation 0.16642 0.0 0.01800
        children [
          Shape {
            appearance PBRAppearance {
              baseColor 0.78 0.46 0.29
              roughness 0.45
              metalness 0
            }
            geometry Sphere {
              radius 0.006
            }
          }
        ]
        boundingObject Sphere {
          radius 0.006
        }
        physics Physics {
          density -1
          mass 0.001
        }
      }
    }
    DEF JOINT_95_MVULVA HingeJoint {
      jointParameters HingeJointParameters {
        anchor 0.17000 0.0 -0.01800
        axis 0 1 0
      }
      device [
        RotationalMotor {
          name "MVULVA"
          maxVelocity 8
          minPosition -1.3
          maxPosition 1.3
        }
      ]
      endPoint DEF SEGMENT_95_MVULVA Solid {
        name "SEGMENT_95_MVULVA"
        translation 0.17000 0.0 -0.01800
        children [
          Shape {
            appearance PBRAppearance {
              baseColor 0.78 0.46 0.29
              roughness 0.45
              metalness 0
            }
            geometry Sphere {
              radius 0.006
            }
          }
        ]
        boundingObject Sphere {
          radius 0.006
        }
        physics Physics {
          density -1
          mass 0.001
        }
      }
    }

      Group {
        children IS extensionSlot
      }
    ]
    boundingObject Capsule {
      radius 0.03
      height 0.34
    }
    physics Physics {
      density -1
      mass 0.25
    }
  }
}
