#VRML_SIM R2025a utf8

PROTO DrosophilaRobot [
  field SFVec3f     translation 0 0.008 0
  field SFRotation  rotation 0 1 0 0
  field SFString    name "drosophila_robot"
  field SFString    controller "nao_nn_controller_uds"
  field MFString    controllerArgs [
    "NM_BRAINS=default"
  ]
  field MFNode      extensionSlot [ ]
]
{
  Robot {
    translation IS translation
    rotation IS rotation
    name IS name
    controller IS controller
    controllerArgs IS controllerArgs
    customData "{\"network\":\"../../network_drosophila.json\",\"config\":\"../configs/config_drosophila_webots.json\"}"
    children [
      # Head-thorax-abdomen body axis
      Transform {
        translation 0.0062 0.0029 0
        children [
          Shape {
            appearance PBRAppearance {
              baseColor 0.78 0.59 0.34
              roughness 0.38
              metalness 0
            }
            geometry Sphere {
              radius 0.0026
            }
          }
        ]
      }
      Transform {
        translation 0.0002 0.0027 0
        rotation 0 0 1 1.5708
        children [
          Shape {
            appearance PBRAppearance {
              baseColor 0.52 0.37 0.22
              roughness 0.40
              metalness 0
            }
            geometry Capsule {
              radius 0.0033
              height 0.0078
            }
          }
        ]
      }
      Transform {
        translation -0.0064 0.0026 0
        rotation 0 0 1 1.5708
        children [
          Shape {
            appearance PBRAppearance {
              baseColor 0.67 0.49 0.29
              roughness 0.46
              metalness 0
            }
            geometry Capsule {
              radius 0.0030
              height 0.0102
            }
          }
        ]
      }
      Transform {
        translation -0.0122 0.0023 0
        children [
          Shape {
            appearance PBRAppearance {
              baseColor 0.55 0.38 0.22
              roughness 0.52
            }
            geometry Sphere {
              radius 0.0019
            }
          }
        ]
      }
      # Abdomen striping
      Transform {
        translation -0.0093 0.0028 0
        children [ Shape { appearance PBRAppearance { baseColor 0.22 0.17 0.13 roughness 0.62 } geometry Box { size 0.0007 0.0058 0.0062 } } ]
      }
      Transform {
        translation -0.0071 0.0028 0
        children [ Shape { appearance PBRAppearance { baseColor 0.22 0.17 0.13 roughness 0.62 } geometry Box { size 0.0007 0.0062 0.0065 } } ]
      }
      Transform {
        translation -0.0049 0.0028 0
        children [ Shape { appearance PBRAppearance { baseColor 0.22 0.17 0.13 roughness 0.62 } geometry Box { size 0.0007 0.0064 0.0068 } } ]
      }
      # Compound eyes
      Transform {
        translation 0.0072 0.0031 0.0022
        children [
          Shape {
            appearance PBRAppearance {
              baseColor 0.86 0.10 0.08
              roughness 0.20
              metalness 0
            }
            geometry Sphere {
              radius 0.0019
            }
          }
        ]
      }
      Transform {
        translation 0.0072 0.0031 -0.0022
        children [
          Shape {
            appearance PBRAppearance {
              baseColor 0.86 0.10 0.08
              roughness 0.20
              metalness 0
            }
            geometry Sphere {
              radius 0.0019
            }
          }
        ]
      }
      # Ocelli
      Transform {
        translation 0.0068 0.0048 0
        children [ Shape { appearance PBRAppearance { baseColor 0.10 0.07 0.05 roughness 0.35 } geometry Sphere { radius 0.00024 } } ]
      }
      Transform {
        translation 0.0065 0.0046 0.00045
        children [ Shape { appearance PBRAppearance { baseColor 0.10 0.07 0.05 roughness 0.35 } geometry Sphere { radius 0.00020 } } ]
      }
      Transform {
        translation 0.0065 0.0046 -0.00045
        children [ Shape { appearance PBRAppearance { baseColor 0.10 0.07 0.05 roughness 0.35 } geometry Sphere { radius 0.00020 } } ]
      }
      # Antennae and proboscis
      Transform {
        translation 0.0081 0.0033 0.00095
        rotation 0 0 1 0.56
        children [ Shape { appearance PBRAppearance { baseColor 0.66 0.53 0.38 roughness 0.74 } geometry Capsule { radius 0.00014 height 0.0030 } } ]
      }
      Transform {
        translation 0.0081 0.0033 -0.00095
        rotation 0 0 1 -0.56
        children [ Shape { appearance PBRAppearance { baseColor 0.66 0.53 0.38 roughness 0.74 } geometry Capsule { radius 0.00014 height 0.0030 } } ]
      }
      Transform {
        translation 0.0078 0.0012 0
        rotation 0 0 1 0.12
        children [ Shape { appearance PBRAppearance { baseColor 0.70 0.56 0.40 roughness 0.77 } geometry Capsule { radius 0.00022 height 0.0028 } } ]
      }
      # Wings
      Transform {
        translation -0.0012 0.0050 0.0029
        rotation 0 1 0 0.14
        scale 0.0108 0.00008 0.0030
        children [
          Shape {
            appearance PBRAppearance {
              baseColor 0.94 0.95 0.91
              roughness 0.10
              metalness 0
              transparency 0.48
            }
            geometry Sphere {
              radius 1
            }
          }
        ]
      }
      Transform {
        translation -0.0012 0.0050 -0.0029
        rotation 0 1 0 -0.14
        scale 0.0108 0.00008 0.0030
        children [
          Shape {
            appearance PBRAppearance {
              baseColor 0.94 0.95 0.91
              roughness 0.10
              metalness 0
              transparency 0.48
            }
            geometry Sphere {
              radius 1
            }
          }
        ]
      }
      # Wing veins
      Transform {
        translation -0.0001 0.0052 0.0032
        rotation 0 0 1 1.30
        children [ Shape { appearance PBRAppearance { baseColor 0.58 0.51 0.39 roughness 0.74 transparency 0.34 } geometry Capsule { radius 0.00005 height 0.0070 } } ]
      }
      Transform {
        translation -0.0029 0.0053 0.0028
        rotation 0 0 1 1.74
        children [ Shape { appearance PBRAppearance { baseColor 0.58 0.51 0.39 roughness 0.74 transparency 0.36 } geometry Capsule { radius 0.000045 height 0.0044 } } ]
      }
      Transform {
        translation -0.0001 0.0052 -0.0032
        rotation 0 0 1 -1.30
        children [ Shape { appearance PBRAppearance { baseColor 0.58 0.51 0.39 roughness 0.74 transparency 0.34 } geometry Capsule { radius 0.00005 height 0.0070 } } ]
      }
      Transform {
        translation -0.0029 0.0053 -0.0028
        rotation 0 0 1 -1.74
        children [ Shape { appearance PBRAppearance { baseColor 0.58 0.51 0.39 roughness 0.74 transparency 0.36 } geometry Capsule { radius 0.000045 height 0.0044 } } ]
      }
      # Halteres
      Transform {
        translation -0.0035 0.0039 0.0018
        rotation 0 0 1 0.66
        children [ Shape { appearance PBRAppearance { baseColor 0.79 0.70 0.52 roughness 0.63 } geometry Capsule { radius 0.00016 height 0.0018 } } ]
      }
      Transform {
        translation -0.0035 0.0039 -0.0018
        rotation 0 0 1 -0.66
        children [ Shape { appearance PBRAppearance { baseColor 0.79 0.70 0.52 roughness 0.63 } geometry Capsule { radius 0.00016 height 0.0018 } } ]
      }
      # Front legs
      Transform {
        translation 0.0034 0.0011 0.0024
        rotation 0 0 1 1.03
        children [ Shape { appearance PBRAppearance { baseColor 0.83 0.69 0.48 roughness 0.76 } geometry Capsule { radius 0.00017 height 0.0048 } } ]
      }
      Transform {
        translation 0.0058 -0.0019 0.0037
        rotation 0 0 1 0.34
        children [ Shape { appearance PBRAppearance { baseColor 0.83 0.69 0.48 roughness 0.78 } geometry Capsule { radius 0.00013 height 0.0052 } } ]
      }
      Transform {
        translation 0.0075 -0.0048 0.0045
        children [ Shape { appearance PBRAppearance { baseColor 0.12 0.10 0.08 roughness 0.57 } geometry Sphere { radius 0.00016 } } ]
      }
      Transform {
        translation 0.0034 0.0011 -0.0024
        rotation 0 0 1 -1.03
        children [ Shape { appearance PBRAppearance { baseColor 0.83 0.69 0.48 roughness 0.76 } geometry Capsule { radius 0.00017 height 0.0048 } } ]
      }
      Transform {
        translation 0.0058 -0.0019 -0.0037
        rotation 0 0 1 -0.34
        children [ Shape { appearance PBRAppearance { baseColor 0.83 0.69 0.48 roughness 0.78 } geometry Capsule { radius 0.00013 height 0.0052 } } ]
      }
      Transform {
        translation 0.0075 -0.0048 -0.0045
        children [ Shape { appearance PBRAppearance { baseColor 0.12 0.10 0.08 roughness 0.57 } geometry Sphere { radius 0.00016 } } ]
      }
      # Middle legs
      Transform {
        translation -0.0003 0.0010 0.0029
        rotation 0 0 1 0.88
        children [ Shape { appearance PBRAppearance { baseColor 0.83 0.69 0.48 roughness 0.76 } geometry Capsule { radius 0.00017 height 0.0052 } } ]
      }
      Transform {
        translation 0.0020 -0.0022 0.0044
        rotation 0 0 1 0.24
        children [ Shape { appearance PBRAppearance { baseColor 0.83 0.69 0.48 roughness 0.78 } geometry Capsule { radius 0.00013 height 0.0054 } } ]
      }
      Transform {
        translation 0.0036 -0.0052 0.0053
        children [ Shape { appearance PBRAppearance { baseColor 0.12 0.10 0.08 roughness 0.57 } geometry Sphere { radius 0.00016 } } ]
      }
      Transform {
        translation -0.0003 0.0010 -0.0029
        rotation 0 0 1 -0.88
        children [ Shape { appearance PBRAppearance { baseColor 0.83 0.69 0.48 roughness 0.76 } geometry Capsule { radius 0.00017 height 0.0052 } } ]
      }
      Transform {
        translation 0.0020 -0.0022 -0.0044
        rotation 0 0 1 -0.24
        children [ Shape { appearance PBRAppearance { baseColor 0.83 0.69 0.48 roughness 0.78 } geometry Capsule { radius 0.00013 height 0.0054 } } ]
      }
      Transform {
        translation 0.0036 -0.0052 -0.0053
        children [ Shape { appearance PBRAppearance { baseColor 0.12 0.10 0.08 roughness 0.57 } geometry Sphere { radius 0.00016 } } ]
      }
      # Rear legs
      Transform {
        translation -0.0040 0.0010 0.0027
        rotation 0 0 1 0.71
        children [ Shape { appearance PBRAppearance { baseColor 0.83 0.69 0.48 roughness 0.76 } geometry Capsule { radius 0.00017 height 0.0057 } } ]
      }
      Transform {
        translation -0.0020 -0.0027 0.0042
        rotation 0 0 1 0.10
        children [ Shape { appearance PBRAppearance { baseColor 0.83 0.69 0.48 roughness 0.78 } geometry Capsule { radius 0.00013 height 0.0058 } } ]
      }
      Transform {
        translation -0.0007 -0.0058 0.0051
        children [ Shape { appearance PBRAppearance { baseColor 0.12 0.10 0.08 roughness 0.57 } geometry Sphere { radius 0.00016 } } ]
      }
      Transform {
        translation -0.0040 0.0010 -0.0027
        rotation 0 0 1 -0.71
        children [ Shape { appearance PBRAppearance { baseColor 0.83 0.69 0.48 roughness 0.76 } geometry Capsule { radius 0.00017 height 0.0057 } } ]
      }
      Transform {
        translation -0.0020 -0.0027 -0.0042
        rotation 0 0 1 -0.10
        children [ Shape { appearance PBRAppearance { baseColor 0.83 0.69 0.48 roughness 0.78 } geometry Capsule { radius 0.00013 height 0.0058 } } ]
      }
      Transform {
        translation -0.0007 -0.0058 -0.0051
        children [ Shape { appearance PBRAppearance { baseColor 0.12 0.10 0.08 roughness 0.57 } geometry Sphere { radius 0.00016 } } ]
      }

      # Inertial sensing
      Accelerometer {
        name "fly_accel"
      }
      Gyro {
        name "fly_gyro"
      }
      # Contact sensing around body perimeter
      TouchSensor {
        name "fly_touch_front"
        type "bumper"
        translation 0.010 0.0015 0.0
      }
      TouchSensor {
        name "fly_touch_rear"
        type "bumper"
        translation -0.024 0.0009 0.0
      }
      TouchSensor {
        name "fly_touch_left"
        type "bumper"
        translation -0.004 0.0015 0.010
      }
      TouchSensor {
        name "fly_touch_right"
        type "bumper"
        translation -0.004 0.0015 -0.010
      }
      # Directional proximity ring for odor/obstacle gradient response.
      DistanceSensor {
        name "fly_prox_00"
        type "infra-red"
        translation 0.00800 0.0034 0.00000
        rotation 0 1 0 0.00000
        lookupTable [
          0 1000 0
          0.18 0 0
        ]
      }
      DistanceSensor {
        name "fly_prox_01"
        type "infra-red"
        translation 0.00759 0.0034 0.00246
        rotation 0 1 0 0.26180
        lookupTable [
          0 1000 0
          0.18 0 0
        ]
      }
      DistanceSensor {
        name "fly_prox_02"
        type "infra-red"
        translation 0.00639 0.0034 0.00475
        rotation 0 1 0 0.52360
        lookupTable [
          0 1000 0
          0.18 0 0
        ]
      }
      DistanceSensor {
        name "fly_prox_03"
        type "infra-red"
        translation 0.00449 0.0034 0.00672
        rotation 0 1 0 0.78540
        lookupTable [
          0 1000 0
          0.18 0 0
        ]
      }
      DistanceSensor {
        name "fly_prox_04"
        type "infra-red"
        translation 0.00200 0.0034 0.00823
        rotation 0 1 0 1.04720
        lookupTable [
          0 1000 0
          0.18 0 0
        ]
      }
      DistanceSensor {
        name "fly_prox_05"
        type "infra-red"
        translation -0.00089 0.0034 0.00918
        rotation 0 1 0 1.30900
        lookupTable [
          0 1000 0
          0.18 0 0
        ]
      }
      DistanceSensor {
        name "fly_prox_06"
        type "infra-red"
        translation -0.00400 0.0034 0.00950
        rotation 0 1 0 1.57080
        lookupTable [
          0 1000 0
          0.18 0 0
        ]
      }
      DistanceSensor {
        name "fly_prox_07"
        type "infra-red"
        translation -0.00711 0.0034 0.00918
        rotation 0 1 0 1.83260
        lookupTable [
          0 1000 0
          0.18 0 0
        ]
      }
      DistanceSensor {
        name "fly_prox_08"
        type "infra-red"
        translation -0.01000 0.0034 0.00823
        rotation 0 1 0 2.09440
        lookupTable [
          0 1000 0
          0.18 0 0
        ]
      }
      DistanceSensor {
        name "fly_prox_09"
        type "infra-red"
        translation -0.01249 0.0034 0.00672
        rotation 0 1 0 2.35619
        lookupTable [
          0 1000 0
          0.18 0 0
        ]
      }
      DistanceSensor {
        name "fly_prox_10"
        type "infra-red"
        translation -0.01439 0.0034 0.00475
        rotation 0 1 0 2.61799
        lookupTable [
          0 1000 0
          0.18 0 0
        ]
      }
      DistanceSensor {
        name "fly_prox_11"
        type "infra-red"
        translation -0.01559 0.0034 0.00246
        rotation 0 1 0 2.87979
        lookupTable [
          0 1000 0
          0.18 0 0
        ]
      }
      DistanceSensor {
        name "fly_prox_12"
        type "infra-red"
        translation -0.01600 0.0034 0.00000
        rotation 0 1 0 3.14159
        lookupTable [
          0 1000 0
          0.18 0 0
        ]
      }
      DistanceSensor {
        name "fly_prox_13"
        type "infra-red"
        translation -0.01559 0.0034 -0.00246
        rotation 0 1 0 3.40339
        lookupTable [
          0 1000 0
          0.18 0 0
        ]
      }
      DistanceSensor {
        name "fly_prox_14"
        type "infra-red"
        translation -0.01439 0.0034 -0.00475
        rotation 0 1 0 3.66519
        lookupTable [
          0 1000 0
          0.18 0 0
        ]
      }
      DistanceSensor {
        name "fly_prox_15"
        type "infra-red"
        translation -0.01249 0.0034 -0.00672
        rotation 0 1 0 3.92699
        lookupTable [
          0 1000 0
          0.18 0 0
        ]
      }
      DistanceSensor {
        name "fly_prox_16"
        type "infra-red"
        translation -0.01000 0.0034 -0.00823
        rotation 0 1 0 4.18879
        lookupTable [
          0 1000 0
          0.18 0 0
        ]
      }
      DistanceSensor {
        name "fly_prox_17"
        type "infra-red"
        translation -0.00711 0.0034 -0.00918
        rotation 0 1 0 4.45059
        lookupTable [
          0 1000 0
          0.18 0 0
        ]
      }
      DistanceSensor {
        name "fly_prox_18"
        type "infra-red"
        translation -0.00400 0.0034 -0.00950
        rotation 0 1 0 4.71239
        lookupTable [
          0 1000 0
          0.18 0 0
        ]
      }
      DistanceSensor {
        name "fly_prox_19"
        type "infra-red"
        translation -0.00089 0.0034 -0.00918
        rotation 0 1 0 4.97419
        lookupTable [
          0 1000 0
          0.18 0 0
        ]
      }
      DistanceSensor {
        name "fly_prox_20"
        type "infra-red"
        translation 0.00200 0.0034 -0.00823
        rotation 0 1 0 5.23599
        lookupTable [
          0 1000 0
          0.18 0 0
        ]
      }
      DistanceSensor {
        name "fly_prox_21"
        type "infra-red"
        translation 0.00449 0.0034 -0.00672
        rotation 0 1 0 5.49779
        lookupTable [
          0 1000 0
          0.18 0 0
        ]
      }
      DistanceSensor {
        name "fly_prox_22"
        type "infra-red"
        translation 0.00639 0.0034 -0.00475
        rotation 0 1 0 5.75959
        lookupTable [
          0 1000 0
          0.18 0 0
        ]
      }
      DistanceSensor {
        name "fly_prox_23"
        type "infra-red"
        translation 0.00759 0.0034 -0.00246
        rotation 0 1 0 6.02139
        lookupTable [
          0 1000 0
          0.18 0 0
        ]
      }

    DEF JOINT_0_720575941493231536 HingeJoint {
      jointParameters HingeJointParameters {
        anchor -0.00300 0.00250 0.00000
        axis 0 1 0
      }
      device [
        RotationalMotor {
          name "720575941493231536"
          maxVelocity 14
          minPosition -1.6
          maxPosition 1.6
        }
      ]
      endPoint DEF SEGMENT_0_720575941493231536 Solid {
        name "SEGMENT_0_720575941493231536"
        translation -0.00300 0.00250 0.00000
        children [
          Shape {
            appearance PBRAppearance {
              baseColor 0.2 0.2 0.2
              roughness 0.55
              metalness 0
              transparency 1
            }
            geometry Sphere {
              radius 0.00035
            }
          }
        ]
        boundingObject Sphere {
          radius 0.0004
        }
        physics Physics {
          density -1
          mass 0.000001
        }
      }
    }
    DEF JOINT_1_720575941643100754 HingeJoint {
      jointParameters HingeJointParameters {
        anchor -0.00300 0.00232 0.00088
        axis 0 1 0
      }
      device [
        RotationalMotor {
          name "720575941643100754"
          maxVelocity 14
          minPosition -1.6
          maxPosition 1.6
        }
      ]
      endPoint DEF SEGMENT_1_720575941643100754 Solid {
        name "SEGMENT_1_720575941643100754"
        translation -0.00300 0.00232 0.00088
        children [
          Shape {
            appearance PBRAppearance {
              baseColor 0.2 0.2 0.2
              roughness 0.55
              metalness 0
              transparency 1
            }
            geometry Sphere {
              radius 0.00035
            }
          }
        ]
        boundingObject Sphere {
          radius 0.0004
        }
        physics Physics {
          density -1
          mass 0.000001
        }
      }
    }
    DEF JOINT_2_720575941488287797 HingeJoint {
      jointParameters HingeJointParameters {
        anchor -0.00300 0.00183 0.00163
        axis 0 1 0
      }
      device [
        RotationalMotor {
          name "720575941488287797"
          maxVelocity 14
          minPosition -1.6
          maxPosition 1.6
        }
      ]
      endPoint DEF SEGMENT_2_720575941488287797 Solid {
        name "SEGMENT_2_720575941488287797"
        translation -0.00300 0.00183 0.00163
        children [
          Shape {
            appearance PBRAppearance {
              baseColor 0.2 0.2 0.2
              roughness 0.55
              metalness 0
              transparency 1
            }
            geometry Sphere {
              radius 0.00035
            }
          }
        ]
        boundingObject Sphere {
          radius 0.0004
        }
        physics Physics {
          density -1
          mass 0.000001
        }
      }
    }
    DEF JOINT_3_720575941720479034 HingeJoint {
      jointParameters HingeJointParameters {
        anchor -0.00300 0.00108 0.00212
        axis 0 1 0
      }
      device [
        RotationalMotor {
          name "720575941720479034"
          maxVelocity 14
          minPosition -1.6
          maxPosition 1.6
        }
      ]
      endPoint DEF SEGMENT_3_720575941720479034 Solid {
        name "SEGMENT_3_720575941720479034"
        translation -0.00300 0.00108 0.00212
        children [
          Shape {
            appearance PBRAppearance {
              baseColor 0.2 0.2 0.2
              roughness 0.55
              metalness 0
              transparency 1
            }
            geometry Sphere {
              radius 0.00035
            }
          }
        ]
        boundingObject Sphere {
          radius 0.0004
        }
        physics Physics {
          density -1
          mass 0.000001
        }
      }
    }
    DEF JOINT_4_720575941470212471 HingeJoint {
      jointParameters HingeJointParameters {
        anchor -0.00300 0.00020 0.00230
        axis 0 1 0
      }
      device [
        RotationalMotor {
          name "720575941470212471"
          maxVelocity 14
          minPosition -1.6
          maxPosition 1.6
        }
      ]
      endPoint DEF SEGMENT_4_720575941470212471 Solid {
        name "SEGMENT_4_720575941470212471"
        translation -0.00300 0.00020 0.00230
        children [
          Shape {
            appearance PBRAppearance {
              baseColor 0.2 0.2 0.2
              roughness 0.55
              metalness 0
              transparency 1
            }
            geometry Sphere {
              radius 0.00035
            }
          }
        ]
        boundingObject Sphere {
          radius 0.0004
        }
        physics Physics {
          density -1
          mass 0.000001
        }
      }
    }
    DEF JOINT_5_720575941471839296 HingeJoint {
      jointParameters HingeJointParameters {
        anchor -0.00300 -0.00068 0.00212
        axis 0 1 0
      }
      device [
        RotationalMotor {
          name "720575941471839296"
          maxVelocity 14
          minPosition -1.6
          maxPosition 1.6
        }
      ]
      endPoint DEF SEGMENT_5_720575941471839296 Solid {
        name "SEGMENT_5_720575941471839296"
        translation -0.00300 -0.00068 0.00212
        children [
          Shape {
            appearance PBRAppearance {
              baseColor 0.2 0.2 0.2
              roughness 0.55
              metalness 0
              transparency 1
            }
            geometry Sphere {
              radius 0.00035
            }
          }
        ]
        boundingObject Sphere {
          radius 0.0004
        }
        physics Physics {
          density -1
          mass 0.000001
        }
      }
    }
    DEF JOINT_6_720575941508453761 HingeJoint {
      jointParameters HingeJointParameters {
        anchor -0.00300 -0.00143 0.00163
        axis 0 1 0
      }
      device [
        RotationalMotor {
          name "720575941508453761"
          maxVelocity 14
          minPosition -1.6
          maxPosition 1.6
        }
      ]
      endPoint DEF SEGMENT_6_720575941508453761 Solid {
        name "SEGMENT_6_720575941508453761"
        translation -0.00300 -0.00143 0.00163
        children [
          Shape {
            appearance PBRAppearance {
              baseColor 0.2 0.2 0.2
              roughness 0.55
              metalness 0
              transparency 1
            }
            geometry Sphere {
              radius 0.00035
            }
          }
        ]
        boundingObject Sphere {
          radius 0.0004
        }
        physics Physics {
          density -1
          mass 0.000001
        }
      }
    }
    DEF JOINT_7_720575941568553330 HingeJoint {
      jointParameters HingeJointParameters {
        anchor -0.00300 -0.00192 0.00088
        axis 0 1 0
      }
      device [
        RotationalMotor {
          name "720575941568553330"
          maxVelocity 14
          minPosition -1.6
          maxPosition 1.6
        }
      ]
      endPoint DEF SEGMENT_7_720575941568553330 Solid {
        name "SEGMENT_7_720575941568553330"
        translation -0.00300 -0.00192 0.00088
        children [
          Shape {
            appearance PBRAppearance {
              baseColor 0.2 0.2 0.2
              roughness 0.55
              metalness 0
              transparency 1
            }
            geometry Sphere {
              radius 0.00035
            }
          }
        ]
        boundingObject Sphere {
          radius 0.0004
        }
        physics Physics {
          density -1
          mass 0.000001
        }
      }
    }
    DEF JOINT_8_720575941475745898 HingeJoint {
      jointParameters HingeJointParameters {
        anchor -0.00300 -0.00210 0.00000
        axis 0 1 0
      }
      device [
        RotationalMotor {
          name "720575941475745898"
          maxVelocity 14
          minPosition -1.6
          maxPosition 1.6
        }
      ]
      endPoint DEF SEGMENT_8_720575941475745898 Solid {
        name "SEGMENT_8_720575941475745898"
        translation -0.00300 -0.00210 0.00000
        children [
          Shape {
            appearance PBRAppearance {
              baseColor 0.2 0.2 0.2
              roughness 0.55
              metalness 0
              transparency 1
            }
            geometry Sphere {
              radius 0.00035
            }
          }
        ]
        boundingObject Sphere {
          radius 0.0004
        }
        physics Physics {
          density -1
          mass 0.000001
        }
      }
    }
    DEF JOINT_9_720575941655597785 HingeJoint {
      jointParameters HingeJointParameters {
        anchor -0.00300 -0.00192 -0.00088
        axis 0 1 0
      }
      device [
        RotationalMotor {
          name "720575941655597785"
          maxVelocity 14
          minPosition -1.6
          maxPosition 1.6
        }
      ]
      endPoint DEF SEGMENT_9_720575941655597785 Solid {
        name "SEGMENT_9_720575941655597785"
        translation -0.00300 -0.00192 -0.00088
        children [
          Shape {
            appearance PBRAppearance {
              baseColor 0.2 0.2 0.2
              roughness 0.55
              metalness 0
              transparency 1
            }
            geometry Sphere {
              radius 0.00035
            }
          }
        ]
        boundingObject Sphere {
          radius 0.0004
        }
        physics Physics {
          density -1
          mass 0.000001
        }
      }
    }
    DEF JOINT_10_720575941593843589 HingeJoint {
      jointParameters HingeJointParameters {
        anchor -0.00300 -0.00143 -0.00163
        axis 0 1 0
      }
      device [
        RotationalMotor {
          name "720575941593843589"
          maxVelocity 14
          minPosition -1.6
          maxPosition 1.6
        }
      ]
      endPoint DEF SEGMENT_10_720575941593843589 Solid {
        name "SEGMENT_10_720575941593843589"
        translation -0.00300 -0.00143 -0.00163
        children [
          Shape {
            appearance PBRAppearance {
              baseColor 0.2 0.2 0.2
              roughness 0.55
              metalness 0
              transparency 1
            }
            geometry Sphere {
              radius 0.00035
            }
          }
        ]
        boundingObject Sphere {
          radius 0.0004
        }
        physics Physics {
          density -1
          mass 0.000001
        }
      }
    }
    DEF JOINT_11_720575941569529458 HingeJoint {
      jointParameters HingeJointParameters {
        anchor -0.00300 -0.00068 -0.00212
        axis 0 1 0
      }
      device [
        RotationalMotor {
          name "720575941569529458"
          maxVelocity 14
          minPosition -1.6
          maxPosition 1.6
        }
      ]
      endPoint DEF SEGMENT_11_720575941569529458 Solid {
        name "SEGMENT_11_720575941569529458"
        translation -0.00300 -0.00068 -0.00212
        children [
          Shape {
            appearance PBRAppearance {
              baseColor 0.2 0.2 0.2
              roughness 0.55
              metalness 0
              transparency 1
            }
            geometry Sphere {
              radius 0.00035
            }
          }
        ]
        boundingObject Sphere {
          radius 0.0004
        }
        physics Physics {
          density -1
          mass 0.000001
        }
      }
    }
    DEF JOINT_12_720575941547394081 HingeJoint {
      jointParameters HingeJointParameters {
        anchor -0.00300 0.00020 -0.00230
        axis 0 1 0
      }
      device [
        RotationalMotor {
          name "720575941547394081"
          maxVelocity 14
          minPosition -1.6
          maxPosition 1.6
        }
      ]
      endPoint DEF SEGMENT_12_720575941547394081 Solid {
        name "SEGMENT_12_720575941547394081"
        translation -0.00300 0.00020 -0.00230
        children [
          Shape {
            appearance PBRAppearance {
              baseColor 0.2 0.2 0.2
              roughness 0.55
              metalness 0
              transparency 1
            }
            geometry Sphere {
              radius 0.00035
            }
          }
        ]
        boundingObject Sphere {
          radius 0.0004
        }
        physics Physics {
          density -1
          mass 0.000001
        }
      }
    }
    DEF JOINT_13_720575941531180261 HingeJoint {
      jointParameters HingeJointParameters {
        anchor -0.00300 0.00108 -0.00212
        axis 0 1 0
      }
      device [
        RotationalMotor {
          name "720575941531180261"
          maxVelocity 14
          minPosition -1.6
          maxPosition 1.6
        }
      ]
      endPoint DEF SEGMENT_13_720575941531180261 Solid {
        name "SEGMENT_13_720575941531180261"
        translation -0.00300 0.00108 -0.00212
        children [
          Shape {
            appearance PBRAppearance {
              baseColor 0.2 0.2 0.2
              roughness 0.55
              metalness 0
              transparency 1
            }
            geometry Sphere {
              radius 0.00035
            }
          }
        ]
        boundingObject Sphere {
          radius 0.0004
        }
        physics Physics {
          density -1
          mass 0.000001
        }
      }
    }
    DEF JOINT_14_720575941478187841 HingeJoint {
      jointParameters HingeJointParameters {
        anchor -0.00300 0.00183 -0.00163
        axis 0 1 0
      }
      device [
        RotationalMotor {
          name "720575941478187841"
          maxVelocity 14
          minPosition -1.6
          maxPosition 1.6
        }
      ]
      endPoint DEF SEGMENT_14_720575941478187841 Solid {
        name "SEGMENT_14_720575941478187841"
        translation -0.00300 0.00183 -0.00163
        children [
          Shape {
            appearance PBRAppearance {
              baseColor 0.2 0.2 0.2
              roughness 0.55
              metalness 0
              transparency 1
            }
            geometry Sphere {
              radius 0.00035
            }
          }
        ]
        boundingObject Sphere {
          radius 0.0004
        }
        physics Physics {
          density -1
          mass 0.000001
        }
      }
    }
    DEF JOINT_15_720575941516874094 HingeJoint {
      jointParameters HingeJointParameters {
        anchor -0.00300 0.00232 -0.00088
        axis 0 1 0
      }
      device [
        RotationalMotor {
          name "720575941516874094"
          maxVelocity 14
          minPosition -1.6
          maxPosition 1.6
        }
      ]
      endPoint DEF SEGMENT_15_720575941516874094 Solid {
        name "SEGMENT_15_720575941516874094"
        translation -0.00300 0.00232 -0.00088
        children [
          Shape {
            appearance PBRAppearance {
              baseColor 0.2 0.2 0.2
              roughness 0.55
              metalness 0
              transparency 1
            }
            geometry Sphere {
              radius 0.00035
            }
          }
        ]
        boundingObject Sphere {
          radius 0.0004
        }
        physics Physics {
          density -1
          mass 0.000001
        }
      }
    }
    DEF JOINT_16_720575941455787245 HingeJoint {
      jointParameters HingeJointParameters {
        anchor -0.00080 0.00350 0.00000
        axis 0 1 0
      }
      device [
        RotationalMotor {
          name "720575941455787245"
          maxVelocity 14
          minPosition -1.6
          maxPosition 1.6
        }
      ]
      endPoint DEF SEGMENT_16_720575941455787245 Solid {
        name "SEGMENT_16_720575941455787245"
        translation -0.00080 0.00350 0.00000
        children [
          Shape {
            appearance PBRAppearance {
              baseColor 0.2 0.2 0.2
              roughness 0.55
              metalness 0
              transparency 1
            }
            geometry Sphere {
              radius 0.00035
            }
          }
        ]
        boundingObject Sphere {
          radius 0.0004
        }
        physics Physics {
          density -1
          mass 0.000001
        }
      }
    }
    DEF JOINT_17_720575941593715569 HingeJoint {
      jointParameters HingeJointParameters {
        anchor -0.00080 0.00325 0.00126
        axis 0 1 0
      }
      device [
        RotationalMotor {
          name "720575941593715569"
          maxVelocity 14
          minPosition -1.6
          maxPosition 1.6
        }
      ]
      endPoint DEF SEGMENT_17_720575941593715569 Solid {
        name "SEGMENT_17_720575941593715569"
        translation -0.00080 0.00325 0.00126
        children [
          Shape {
            appearance PBRAppearance {
              baseColor 0.2 0.2 0.2
              roughness 0.55
              metalness 0
              transparency 1
            }
            geometry Sphere {
              radius 0.00035
            }
          }
        ]
        boundingObject Sphere {
          radius 0.0004
        }
        physics Physics {
          density -1
          mass 0.000001
        }
      }
    }
    DEF JOINT_18_720575941553516167 HingeJoint {
      jointParameters HingeJointParameters {
        anchor -0.00080 0.00253 0.00233
        axis 0 1 0
      }
      device [
        RotationalMotor {
          name "720575941553516167"
          maxVelocity 14
          minPosition -1.6
          maxPosition 1.6
        }
      ]
      endPoint DEF SEGMENT_18_720575941553516167 Solid {
        name "SEGMENT_18_720575941553516167"
        translation -0.00080 0.00253 0.00233
        children [
          Shape {
            appearance PBRAppearance {
              baseColor 0.2 0.2 0.2
              roughness 0.55
              metalness 0
              transparency 1
            }
            geometry Sphere {
              radius 0.00035
            }
          }
        ]
        boundingObject Sphere {
          radius 0.0004
        }
        physics Physics {
          density -1
          mass 0.000001
        }
      }
    }
    DEF JOINT_19_720575941558861839 HingeJoint {
      jointParameters HingeJointParameters {
        anchor -0.00080 0.00146 0.00305
        axis 0 1 0
      }
      device [
        RotationalMotor {
          name "720575941558861839"
          maxVelocity 14
          minPosition -1.6
          maxPosition 1.6
        }
      ]
      endPoint DEF SEGMENT_19_720575941558861839 Solid {
        name "SEGMENT_19_720575941558861839"
        translation -0.00080 0.00146 0.00305
        children [
          Shape {
            appearance PBRAppearance {
              baseColor 0.2 0.2 0.2
              roughness 0.55
              metalness 0
              transparency 1
            }
            geometry Sphere {
              radius 0.00035
            }
          }
        ]
        boundingObject Sphere {
          radius 0.0004
        }
        physics Physics {
          density -1
          mass 0.000001
        }
      }
    }
    DEF JOINT_20_720575941525308582 HingeJoint {
      jointParameters HingeJointParameters {
        anchor -0.00080 0.00020 0.00330
        axis 0 1 0
      }
      device [
        RotationalMotor {
          name "720575941525308582"
          maxVelocity 14
          minPosition -1.6
          maxPosition 1.6
        }
      ]
      endPoint DEF SEGMENT_20_720575941525308582 Solid {
        name "SEGMENT_20_720575941525308582"
        translation -0.00080 0.00020 0.00330
        children [
          Shape {
            appearance PBRAppearance {
              baseColor 0.2 0.2 0.2
              roughness 0.55
              metalness 0
              transparency 1
            }
            geometry Sphere {
              radius 0.00035
            }
          }
        ]
        boundingObject Sphere {
          radius 0.0004
        }
        physics Physics {
          density -1
          mass 0.000001
        }
      }
    }
    DEF JOINT_21_720575941645041313 HingeJoint {
      jointParameters HingeJointParameters {
        anchor -0.00080 -0.00106 0.00305
        axis 0 1 0
      }
      device [
        RotationalMotor {
          name "720575941645041313"
          maxVelocity 14
          minPosition -1.6
          maxPosition 1.6
        }
      ]
      endPoint DEF SEGMENT_21_720575941645041313 Solid {
        name "SEGMENT_21_720575941645041313"
        translation -0.00080 -0.00106 0.00305
        children [
          Shape {
            appearance PBRAppearance {
              baseColor 0.2 0.2 0.2
              roughness 0.55
              metalness 0
              transparency 1
            }
            geometry Sphere {
              radius 0.00035
            }
          }
        ]
        boundingObject Sphere {
          radius 0.0004
        }
        physics Physics {
          density -1
          mass 0.000001
        }
      }
    }
    DEF JOINT_22_720575941573215995 HingeJoint {
      jointParameters HingeJointParameters {
        anchor -0.00080 -0.00213 0.00233
        axis 0 1 0
      }
      device [
        RotationalMotor {
          name "720575941573215995"
          maxVelocity 14
          minPosition -1.6
          maxPosition 1.6
        }
      ]
      endPoint DEF SEGMENT_22_720575941573215995 Solid {
        name "SEGMENT_22_720575941573215995"
        translation -0.00080 -0.00213 0.00233
        children [
          Shape {
            appearance PBRAppearance {
              baseColor 0.2 0.2 0.2
              roughness 0.55
              metalness 0
              transparency 1
            }
            geometry Sphere {
              radius 0.00035
            }
          }
        ]
        boundingObject Sphere {
          radius 0.0004
        }
        physics Physics {
          density -1
          mass 0.000001
        }
      }
    }
    DEF JOINT_23_720575941519664856 HingeJoint {
      jointParameters HingeJointParameters {
        anchor -0.00080 -0.00285 0.00126
        axis 0 1 0
      }
      device [
        RotationalMotor {
          name "720575941519664856"
          maxVelocity 14
          minPosition -1.6
          maxPosition 1.6
        }
      ]
      endPoint DEF SEGMENT_23_720575941519664856 Solid {
        name "SEGMENT_23_720575941519664856"
        translation -0.00080 -0.00285 0.00126
        children [
          Shape {
            appearance PBRAppearance {
              baseColor 0.2 0.2 0.2
              roughness 0.55
              metalness 0
              transparency 1
            }
            geometry Sphere {
              radius 0.00035
            }
          }
        ]
        boundingObject Sphere {
          radius 0.0004
        }
        physics Physics {
          density -1
          mass 0.000001
        }
      }
    }
    DEF JOINT_24_720575941498960546 HingeJoint {
      jointParameters HingeJointParameters {
        anchor -0.00080 -0.00310 0.00000
        axis 0 1 0
      }
      device [
        RotationalMotor {
          name "720575941498960546"
          maxVelocity 14
          minPosition -1.6
          maxPosition 1.6
        }
      ]
      endPoint DEF SEGMENT_24_720575941498960546 Solid {
        name "SEGMENT_24_720575941498960546"
        translation -0.00080 -0.00310 0.00000
        children [
          Shape {
            appearance PBRAppearance {
              baseColor 0.2 0.2 0.2
              roughness 0.55
              metalness 0
              transparency 1
            }
            geometry Sphere {
              radius 0.00035
            }
          }
        ]
        boundingObject Sphere {
          radius 0.0004
        }
        physics Physics {
          density -1
          mass 0.000001
        }
      }
    }
    DEF JOINT_25_720575941573687049 HingeJoint {
      jointParameters HingeJointParameters {
        anchor -0.00080 -0.00285 -0.00126
        axis 0 1 0
      }
      device [
        RotationalMotor {
          name "720575941573687049"
          maxVelocity 14
          minPosition -1.6
          maxPosition 1.6
        }
      ]
      endPoint DEF SEGMENT_25_720575941573687049 Solid {
        name "SEGMENT_25_720575941573687049"
        translation -0.00080 -0.00285 -0.00126
        children [
          Shape {
            appearance PBRAppearance {
              baseColor 0.2 0.2 0.2
              roughness 0.55
              metalness 0
              transparency 1
            }
            geometry Sphere {
              radius 0.00035
            }
          }
        ]
        boundingObject Sphere {
          radius 0.0004
        }
        physics Physics {
          density -1
          mass 0.000001
        }
      }
    }
    DEF JOINT_26_720575941459347411 HingeJoint {
      jointParameters HingeJointParameters {
        anchor -0.00080 -0.00213 -0.00233
        axis 0 1 0
      }
      device [
        RotationalMotor {
          name "720575941459347411"
          maxVelocity 14
          minPosition -1.6
          maxPosition 1.6
        }
      ]
      endPoint DEF SEGMENT_26_720575941459347411 Solid {
        name "SEGMENT_26_720575941459347411"
        translation -0.00080 -0.00213 -0.00233
        children [
          Shape {
            appearance PBRAppearance {
              baseColor 0.2 0.2 0.2
              roughness 0.55
              metalness 0
              transparency 1
            }
            geometry Sphere {
              radius 0.00035
            }
          }
        ]
        boundingObject Sphere {
          radius 0.0004
        }
        physics Physics {
          density -1
          mass 0.000001
        }
      }
    }
    DEF JOINT_27_720575941468687581 HingeJoint {
      jointParameters HingeJointParameters {
        anchor -0.00080 -0.00106 -0.00305
        axis 0 1 0
      }
      device [
        RotationalMotor {
          name "720575941468687581"
          maxVelocity 14
          minPosition -1.6
          maxPosition 1.6
        }
      ]
      endPoint DEF SEGMENT_27_720575941468687581 Solid {
        name "SEGMENT_27_720575941468687581"
        translation -0.00080 -0.00106 -0.00305
        children [
          Shape {
            appearance PBRAppearance {
              baseColor 0.2 0.2 0.2
              roughness 0.55
              metalness 0
              transparency 1
            }
            geometry Sphere {
              radius 0.00035
            }
          }
        ]
        boundingObject Sphere {
          radius 0.0004
        }
        physics Physics {
          density -1
          mass 0.000001
        }
      }
    }
    DEF JOINT_28_720575941580669817 HingeJoint {
      jointParameters HingeJointParameters {
        anchor -0.00080 0.00020 -0.00330
        axis 0 1 0
      }
      device [
        RotationalMotor {
          name "720575941580669817"
          maxVelocity 14
          minPosition -1.6
          maxPosition 1.6
        }
      ]
      endPoint DEF SEGMENT_28_720575941580669817 Solid {
        name "SEGMENT_28_720575941580669817"
        translation -0.00080 0.00020 -0.00330
        children [
          Shape {
            appearance PBRAppearance {
              baseColor 0.2 0.2 0.2
              roughness 0.55
              metalness 0
              transparency 1
            }
            geometry Sphere {
              radius 0.00035
            }
          }
        ]
        boundingObject Sphere {
          radius 0.0004
        }
        physics Physics {
          density -1
          mass 0.000001
        }
      }
    }
    DEF JOINT_29_720575941684824815 HingeJoint {
      jointParameters HingeJointParameters {
        anchor -0.00080 0.00146 -0.00305
        axis 0 1 0
      }
      device [
        RotationalMotor {
          name "720575941684824815"
          maxVelocity 14
          minPosition -1.6
          maxPosition 1.6
        }
      ]
      endPoint DEF SEGMENT_29_720575941684824815 Solid {
        name "SEGMENT_29_720575941684824815"
        translation -0.00080 0.00146 -0.00305
        children [
          Shape {
            appearance PBRAppearance {
              baseColor 0.2 0.2 0.2
              roughness 0.55
              metalness 0
              transparency 1
            }
            geometry Sphere {
              radius 0.00035
            }
          }
        ]
        boundingObject Sphere {
          radius 0.0004
        }
        physics Physics {
          density -1
          mass 0.000001
        }
      }
    }
    DEF JOINT_30_720575941634236347 HingeJoint {
      jointParameters HingeJointParameters {
        anchor -0.00080 0.00253 -0.00233
        axis 0 1 0
      }
      device [
        RotationalMotor {
          name "720575941634236347"
          maxVelocity 14
          minPosition -1.6
          maxPosition 1.6
        }
      ]
      endPoint DEF SEGMENT_30_720575941634236347 Solid {
        name "SEGMENT_30_720575941634236347"
        translation -0.00080 0.00253 -0.00233
        children [
          Shape {
            appearance PBRAppearance {
              baseColor 0.2 0.2 0.2
              roughness 0.55
              metalness 0
              transparency 1
            }
            geometry Sphere {
              radius 0.00035
            }
          }
        ]
        boundingObject Sphere {
          radius 0.0004
        }
        physics Physics {
          density -1
          mass 0.000001
        }
      }
    }
    DEF JOINT_31_720575941508440193 HingeJoint {
      jointParameters HingeJointParameters {
        anchor -0.00080 0.00325 -0.00126
        axis 0 1 0
      }
      device [
        RotationalMotor {
          name "720575941508440193"
          maxVelocity 14
          minPosition -1.6
          maxPosition 1.6
        }
      ]
      endPoint DEF SEGMENT_31_720575941508440193 Solid {
        name "SEGMENT_31_720575941508440193"
        translation -0.00080 0.00325 -0.00126
        children [
          Shape {
            appearance PBRAppearance {
              baseColor 0.2 0.2 0.2
              roughness 0.55
              metalness 0
              transparency 1
            }
            geometry Sphere {
              radius 0.00035
            }
          }
        ]
        boundingObject Sphere {
          radius 0.0004
        }
        physics Physics {
          density -1
          mass 0.000001
        }
      }
    }
    DEF JOINT_32_720575941480138976 HingeJoint {
      jointParameters HingeJointParameters {
        anchor 0.00140 0.00250 0.00000
        axis 0 1 0
      }
      device [
        RotationalMotor {
          name "720575941480138976"
          maxVelocity 14
          minPosition -1.6
          maxPosition 1.6
        }
      ]
      endPoint DEF SEGMENT_32_720575941480138976 Solid {
        name "SEGMENT_32_720575941480138976"
        translation 0.00140 0.00250 0.00000
        children [
          Shape {
            appearance PBRAppearance {
              baseColor 0.2 0.2 0.2
              roughness 0.55
              metalness 0
              transparency 1
            }
            geometry Sphere {
              radius 0.00035
            }
          }
        ]
        boundingObject Sphere {
          radius 0.0004
        }
        physics Physics {
          density -1
          mass 0.000001
        }
      }
    }
    DEF JOINT_33_720575941516770670 HingeJoint {
      jointParameters HingeJointParameters {
        anchor 0.00140 0.00232 0.00088
        axis 0 1 0
      }
      device [
        RotationalMotor {
          name "720575941516770670"
          maxVelocity 14
          minPosition -1.6
          maxPosition 1.6
        }
      ]
      endPoint DEF SEGMENT_33_720575941516770670 Solid {
        name "SEGMENT_33_720575941516770670"
        translation 0.00140 0.00232 0.00088
        children [
          Shape {
            appearance PBRAppearance {
              baseColor 0.2 0.2 0.2
              roughness 0.55
              metalness 0
              transparency 1
            }
            geometry Sphere {
              radius 0.00035
            }
          }
        ]
        boundingObject Sphere {
          radius 0.0004
        }
        physics Physics {
          density -1
          mass 0.000001
        }
      }
    }
    DEF JOINT_34_720575941432965902 HingeJoint {
      jointParameters HingeJointParameters {
        anchor 0.00140 0.00183 0.00163
        axis 0 1 0
      }
      device [
        RotationalMotor {
          name "720575941432965902"
          maxVelocity 14
          minPosition -1.6
          maxPosition 1.6
        }
      ]
      endPoint DEF SEGMENT_34_720575941432965902 Solid {
        name "SEGMENT_34_720575941432965902"
        translation 0.00140 0.00183 0.00163
        children [
          Shape {
            appearance PBRAppearance {
              baseColor 0.2 0.2 0.2
              roughness 0.55
              metalness 0
              transparency 1
            }
            geometry Sphere {
              radius 0.00035
            }
          }
        ]
        boundingObject Sphere {
          radius 0.0004
        }
        physics Physics {
          density -1
          mass 0.000001
        }
      }
    }
    DEF JOINT_35_720575941481634383 HingeJoint {
      jointParameters HingeJointParameters {
        anchor 0.00140 0.00108 0.00212
        axis 0 1 0
      }
      device [
        RotationalMotor {
          name "720575941481634383"
          maxVelocity 14
          minPosition -1.6
          maxPosition 1.6
        }
      ]
      endPoint DEF SEGMENT_35_720575941481634383 Solid {
        name "SEGMENT_35_720575941481634383"
        translation 0.00140 0.00108 0.00212
        children [
          Shape {
            appearance PBRAppearance {
              baseColor 0.2 0.2 0.2
              roughness 0.55
              metalness 0
              transparency 1
            }
            geometry Sphere {
              radius 0.00035
            }
          }
        ]
        boundingObject Sphere {
          radius 0.0004
        }
        physics Physics {
          density -1
          mass 0.000001
        }
      }
    }
    DEF JOINT_36_720575941624155644 HingeJoint {
      jointParameters HingeJointParameters {
        anchor 0.00140 0.00020 0.00230
        axis 0 1 0
      }
      device [
        RotationalMotor {
          name "720575941624155644"
          maxVelocity 14
          minPosition -1.6
          maxPosition 1.6
        }
      ]
      endPoint DEF SEGMENT_36_720575941624155644 Solid {
        name "SEGMENT_36_720575941624155644"
        translation 0.00140 0.00020 0.00230
        children [
          Shape {
            appearance PBRAppearance {
              baseColor 0.2 0.2 0.2
              roughness 0.55
              metalness 0
              transparency 1
            }
            geometry Sphere {
              radius 0.00035
            }
          }
        ]
        boundingObject Sphere {
          radius 0.0004
        }
        physics Physics {
          density -1
          mass 0.000001
        }
      }
    }
    DEF JOINT_37_720575941461179859 HingeJoint {
      jointParameters HingeJointParameters {
        anchor 0.00140 -0.00068 0.00212
        axis 0 1 0
      }
      device [
        RotationalMotor {
          name "720575941461179859"
          maxVelocity 14
          minPosition -1.6
          maxPosition 1.6
        }
      ]
      endPoint DEF SEGMENT_37_720575941461179859 Solid {
        name "SEGMENT_37_720575941461179859"
        translation 0.00140 -0.00068 0.00212
        children [
          Shape {
            appearance PBRAppearance {
              baseColor 0.2 0.2 0.2
              roughness 0.55
              metalness 0
              transparency 1
            }
            geometry Sphere {
              radius 0.00035
            }
          }
        ]
        boundingObject Sphere {
          radius 0.0004
        }
        physics Physics {
          density -1
          mass 0.000001
        }
      }
    }
    DEF JOINT_38_720575941630940642 HingeJoint {
      jointParameters HingeJointParameters {
        anchor 0.00140 -0.00143 0.00163
        axis 0 1 0
      }
      device [
        RotationalMotor {
          name "720575941630940642"
          maxVelocity 14
          minPosition -1.6
          maxPosition 1.6
        }
      ]
      endPoint DEF SEGMENT_38_720575941630940642 Solid {
        name "SEGMENT_38_720575941630940642"
        translation 0.00140 -0.00143 0.00163
        children [
          Shape {
            appearance PBRAppearance {
              baseColor 0.2 0.2 0.2
              roughness 0.55
              metalness 0
              transparency 1
            }
            geometry Sphere {
              radius 0.00035
            }
          }
        ]
        boundingObject Sphere {
          radius 0.0004
        }
        physics Physics {
          density -1
          mass 0.000001
        }
      }
    }
    DEF JOINT_39_720575941470082423 HingeJoint {
      jointParameters HingeJointParameters {
        anchor 0.00140 -0.00192 0.00088
        axis 0 1 0
      }
      device [
        RotationalMotor {
          name "720575941470082423"
          maxVelocity 14
          minPosition -1.6
          maxPosition 1.6
        }
      ]
      endPoint DEF SEGMENT_39_720575941470082423 Solid {
        name "SEGMENT_39_720575941470082423"
        translation 0.00140 -0.00192 0.00088
        children [
          Shape {
            appearance PBRAppearance {
              baseColor 0.2 0.2 0.2
              roughness 0.55
              metalness 0
              transparency 1
            }
            geometry Sphere {
              radius 0.00035
            }
          }
        ]
        boundingObject Sphere {
          radius 0.0004
        }
        physics Physics {
          density -1
          mass 0.000001
        }
      }
    }
    DEF JOINT_40_720575941687653238 HingeJoint {
      jointParameters HingeJointParameters {
        anchor 0.00140 -0.00210 0.00000
        axis 0 1 0
      }
      device [
        RotationalMotor {
          name "720575941687653238"
          maxVelocity 14
          minPosition -1.6
          maxPosition 1.6
        }
      ]
      endPoint DEF SEGMENT_40_720575941687653238 Solid {
        name "SEGMENT_40_720575941687653238"
        translation 0.00140 -0.00210 0.00000
        children [
          Shape {
            appearance PBRAppearance {
              baseColor 0.2 0.2 0.2
              roughness 0.55
              metalness 0
              transparency 1
            }
            geometry Sphere {
              radius 0.00035
            }
          }
        ]
        boundingObject Sphere {
          radius 0.0004
        }
        physics Physics {
          density -1
          mass 0.000001
        }
      }
    }
    DEF JOINT_41_720575941623920586 HingeJoint {
      jointParameters HingeJointParameters {
        anchor 0.00140 -0.00192 -0.00088
        axis 0 1 0
      }
      device [
        RotationalMotor {
          name "720575941623920586"
          maxVelocity 14
          minPosition -1.6
          maxPosition 1.6
        }
      ]
      endPoint DEF SEGMENT_41_720575941623920586 Solid {
        name "SEGMENT_41_720575941623920586"
        translation 0.00140 -0.00192 -0.00088
        children [
          Shape {
            appearance PBRAppearance {
              baseColor 0.2 0.2 0.2
              roughness 0.55
              metalness 0
              transparency 1
            }
            geometry Sphere {
              radius 0.00035
            }
          }
        ]
        boundingObject Sphere {
          radius 0.0004
        }
        physics Physics {
          density -1
          mass 0.000001
        }
      }
    }
    DEF JOINT_42_720575941667762097 HingeJoint {
      jointParameters HingeJointParameters {
        anchor 0.00140 -0.00143 -0.00163
        axis 0 1 0
      }
      device [
        RotationalMotor {
          name "720575941667762097"
          maxVelocity 14
          minPosition -1.6
          maxPosition 1.6
        }
      ]
      endPoint DEF SEGMENT_42_720575941667762097 Solid {
        name "SEGMENT_42_720575941667762097"
        translation 0.00140 -0.00143 -0.00163
        children [
          Shape {
            appearance PBRAppearance {
              baseColor 0.2 0.2 0.2
              roughness 0.55
              metalness 0
              transparency 1
            }
            geometry Sphere {
              radius 0.00035
            }
          }
        ]
        boundingObject Sphere {
          radius 0.0004
        }
        physics Physics {
          density -1
          mass 0.000001
        }
      }
    }
    DEF JOINT_43_720575941596050112 HingeJoint {
      jointParameters HingeJointParameters {
        anchor 0.00140 -0.00068 -0.00212
        axis 0 1 0
      }
      device [
        RotationalMotor {
          name "720575941596050112"
          maxVelocity 14
          minPosition -1.6
          maxPosition 1.6
        }
      ]
      endPoint DEF SEGMENT_43_720575941596050112 Solid {
        name "SEGMENT_43_720575941596050112"
        translation 0.00140 -0.00068 -0.00212
        children [
          Shape {
            appearance PBRAppearance {
              baseColor 0.2 0.2 0.2
              roughness 0.55
              metalness 0
              transparency 1
            }
            geometry Sphere {
              radius 0.00035
            }
          }
        ]
        boundingObject Sphere {
          radius 0.0004
        }
        physics Physics {
          density -1
          mass 0.000001
        }
      }
    }
    DEF JOINT_44_720575941553691876 HingeJoint {
      jointParameters HingeJointParameters {
        anchor 0.00140 0.00020 -0.00230
        axis 0 1 0
      }
      device [
        RotationalMotor {
          name "720575941553691876"
          maxVelocity 14
          minPosition -1.6
          maxPosition 1.6
        }
      ]
      endPoint DEF SEGMENT_44_720575941553691876 Solid {
        name "SEGMENT_44_720575941553691876"
        translation 0.00140 0.00020 -0.00230
        children [
          Shape {
            appearance PBRAppearance {
              baseColor 0.2 0.2 0.2
              roughness 0.55
              metalness 0
              transparency 1
            }
            geometry Sphere {
              radius 0.00035
            }
          }
        ]
        boundingObject Sphere {
          radius 0.0004
        }
        physics Physics {
          density -1
          mass 0.000001
        }
      }
    }
    DEF JOINT_45_720575941534943937 HingeJoint {
      jointParameters HingeJointParameters {
        anchor 0.00140 0.00108 -0.00212
        axis 0 1 0
      }
      device [
        RotationalMotor {
          name "720575941534943937"
          maxVelocity 14
          minPosition -1.6
          maxPosition 1.6
        }
      ]
      endPoint DEF SEGMENT_45_720575941534943937 Solid {
        name "SEGMENT_45_720575941534943937"
        translation 0.00140 0.00108 -0.00212
        children [
          Shape {
            appearance PBRAppearance {
              baseColor 0.2 0.2 0.2
              roughness 0.55
              metalness 0
              transparency 1
            }
            geometry Sphere {
              radius 0.00035
            }
          }
        ]
        boundingObject Sphere {
          radius 0.0004
        }
        physics Physics {
          density -1
          mass 0.000001
        }
      }
    }
    DEF JOINT_46_720575941506261538 HingeJoint {
      jointParameters HingeJointParameters {
        anchor 0.00140 0.00183 -0.00163
        axis 0 1 0
      }
      device [
        RotationalMotor {
          name "720575941506261538"
          maxVelocity 14
          minPosition -1.6
          maxPosition 1.6
        }
      ]
      endPoint DEF SEGMENT_46_720575941506261538 Solid {
        name "SEGMENT_46_720575941506261538"
        translation 0.00140 0.00183 -0.00163
        children [
          Shape {
            appearance PBRAppearance {
              baseColor 0.2 0.2 0.2
              roughness 0.55
              metalness 0
              transparency 1
            }
            geometry Sphere {
              radius 0.00035
            }
          }
        ]
        boundingObject Sphere {
          radius 0.0004
        }
        physics Physics {
          density -1
          mass 0.000001
        }
      }
    }
    DEF JOINT_47_720575941513173763 HingeJoint {
      jointParameters HingeJointParameters {
        anchor 0.00140 0.00232 -0.00088
        axis 0 1 0
      }
      device [
        RotationalMotor {
          name "720575941513173763"
          maxVelocity 14
          minPosition -1.6
          maxPosition 1.6
        }
      ]
      endPoint DEF SEGMENT_47_720575941513173763 Solid {
        name "SEGMENT_47_720575941513173763"
        translation 0.00140 0.00232 -0.00088
        children [
          Shape {
            appearance PBRAppearance {
              baseColor 0.2 0.2 0.2
              roughness 0.55
              metalness 0
              transparency 1
            }
            geometry Sphere {
              radius 0.00035
            }
          }
        ]
        boundingObject Sphere {
          radius 0.0004
        }
        physics Physics {
          density -1
          mass 0.000001
        }
      }
    }

      Group {
        children IS extensionSlot
      }
    ]
    boundingObject Group {
      children [
        Transform {
          translation 0.0002 0.0027 0
          rotation 0 0 1 1.5708
          children [
            Capsule {
              radius 0.0033
              height 0.0078
            }
          ]
        }
        Transform {
          translation 0.0062 0.0029 0
          children [
            Sphere {
              radius 0.0026
            }
          ]
        }
        Transform {
          translation -0.0064 0.0026 0
          rotation 0 0 1 1.5708
          children [
            Capsule {
              radius 0.0030
              height 0.0102
            }
          ]
        }
        Transform {
          translation -0.0122 0.0023 0
          children [
            Sphere {
              radius 0.0019
            }
          ]
        }
      ]
    }
    physics Physics {
      density -1
      mass 0.0008
    }
  }
}
