#VRML_SIM R2025a utf8

PROTO DrosophilaRobot [
  field SFVec3f     translation 0 0.016 0
  field SFRotation  rotation 0 1 0 0
  field SFString    name "drosophila_robot"
  field SFString    controller "nao_nn_controller_uds"
  field MFString    controllerArgs [
    "NM_BRAINS=default"
  ]
  field MFNode      extensionSlot [ ]
]
{
  Robot {
    translation IS translation
    rotation IS rotation
    name IS name
    controller IS controller
    controllerArgs IS controllerArgs
    customData "{\"network\":\"../../network_drosophila.json\",\"config\":\"../configs/config_drosophila_webots.json\"}"
    children [
      # Body plan: head + thorax + abdomen
      Shape {
        appearance PBRAppearance {
          baseColor 0.35 0.24 0.12
          roughness 0.5
          metalness 0
        }
        geometry Sphere {
          radius 0.009
        }
      }
      Solid {
        name "thorax_segment"
        translation -0.010 0 0
        children [
          Shape {
            appearance PBRAppearance {
              baseColor 0.42 0.28 0.14
              roughness 0.45
            }
            geometry Sphere {
              radius 0.012
            }
          }
        ]
        boundingObject Sphere {
          radius 0.012
        }
      }
      Solid {
        name "abdomen_segment"
        translation -0.024 0 0
        children [
          Shape {
            appearance PBRAppearance {
              baseColor 0.53 0.36 0.18
              roughness 0.48
            }
            geometry Capsule {
              radius 0.007
              height 0.018
            }
          }
        ]
        boundingObject Capsule {
          radius 0.007
          height 0.018
        }
      }
      # Inertial sensing
      Accelerometer {
        name "fly_accel"
      }
      Gyro {
        name "fly_gyro"
      }
      # Contact sensing around body perimeter
      TouchSensor {
        name "fly_touch_front"
        type "bumper"
        translation 0.028 0.0 0.0
      }
      TouchSensor {
        name "fly_touch_rear"
        type "bumper"
        translation -0.028 0.0 0.0
      }
      TouchSensor {
        name "fly_touch_left"
        type "bumper"
        translation 0.0 0.0 0.020
      }
      TouchSensor {
        name "fly_touch_right"
        type "bumper"
        translation 0.0 0.0 -0.020
      }
      # Directional proximity ring for odor/obstacle gradient response.
      DistanceSensor {
        name "fly_prox_00"
        type "infra-red"
        translation 0.02050 0.0015 0.00000
        rotation 0 1 0 0.00000
        lookupTable [
          0 1000 0
          0.28 0 0
        ]
      }
      DistanceSensor {
        name "fly_prox_01"
        type "infra-red"
        translation 0.01980 0.0015 0.00531
        rotation 0 1 0 0.26180
        lookupTable [
          0 1000 0
          0.28 0 0
        ]
      }
      DistanceSensor {
        name "fly_prox_02"
        type "infra-red"
        translation 0.01775 0.0015 0.01025
        rotation 0 1 0 0.52360
        lookupTable [
          0 1000 0
          0.28 0 0
        ]
      }
      DistanceSensor {
        name "fly_prox_03"
        type "infra-red"
        translation 0.01450 0.0015 0.01450
        rotation 0 1 0 0.78540
        lookupTable [
          0 1000 0
          0.28 0 0
        ]
      }
      DistanceSensor {
        name "fly_prox_04"
        type "infra-red"
        translation 0.01025 0.0015 0.01775
        rotation 0 1 0 1.04720
        lookupTable [
          0 1000 0
          0.28 0 0
        ]
      }
      DistanceSensor {
        name "fly_prox_05"
        type "infra-red"
        translation 0.00531 0.0015 0.01980
        rotation 0 1 0 1.30900
        lookupTable [
          0 1000 0
          0.28 0 0
        ]
      }
      DistanceSensor {
        name "fly_prox_06"
        type "infra-red"
        translation 0.00000 0.0015 0.02050
        rotation 0 1 0 1.57080
        lookupTable [
          0 1000 0
          0.28 0 0
        ]
      }
      DistanceSensor {
        name "fly_prox_07"
        type "infra-red"
        translation -0.00531 0.0015 0.01980
        rotation 0 1 0 1.83260
        lookupTable [
          0 1000 0
          0.28 0 0
        ]
      }
      DistanceSensor {
        name "fly_prox_08"
        type "infra-red"
        translation -0.01025 0.0015 0.01775
        rotation 0 1 0 2.09440
        lookupTable [
          0 1000 0
          0.28 0 0
        ]
      }
      DistanceSensor {
        name "fly_prox_09"
        type "infra-red"
        translation -0.01450 0.0015 0.01450
        rotation 0 1 0 2.35619
        lookupTable [
          0 1000 0
          0.28 0 0
        ]
      }
      DistanceSensor {
        name "fly_prox_10"
        type "infra-red"
        translation -0.01775 0.0015 0.01025
        rotation 0 1 0 2.61799
        lookupTable [
          0 1000 0
          0.28 0 0
        ]
      }
      DistanceSensor {
        name "fly_prox_11"
        type "infra-red"
        translation -0.01980 0.0015 0.00531
        rotation 0 1 0 2.87979
        lookupTable [
          0 1000 0
          0.28 0 0
        ]
      }
      DistanceSensor {
        name "fly_prox_12"
        type "infra-red"
        translation -0.02050 0.0015 0.00000
        rotation 0 1 0 3.14159
        lookupTable [
          0 1000 0
          0.28 0 0
        ]
      }
      DistanceSensor {
        name "fly_prox_13"
        type "infra-red"
        translation -0.01980 0.0015 -0.00531
        rotation 0 1 0 3.40339
        lookupTable [
          0 1000 0
          0.28 0 0
        ]
      }
      DistanceSensor {
        name "fly_prox_14"
        type "infra-red"
        translation -0.01775 0.0015 -0.01025
        rotation 0 1 0 3.66519
        lookupTable [
          0 1000 0
          0.28 0 0
        ]
      }
      DistanceSensor {
        name "fly_prox_15"
        type "infra-red"
        translation -0.01450 0.0015 -0.01450
        rotation 0 1 0 3.92699
        lookupTable [
          0 1000 0
          0.28 0 0
        ]
      }
      DistanceSensor {
        name "fly_prox_16"
        type "infra-red"
        translation -0.01025 0.0015 -0.01775
        rotation 0 1 0 4.18879
        lookupTable [
          0 1000 0
          0.28 0 0
        ]
      }
      DistanceSensor {
        name "fly_prox_17"
        type "infra-red"
        translation -0.00531 0.0015 -0.01980
        rotation 0 1 0 4.45059
        lookupTable [
          0 1000 0
          0.28 0 0
        ]
      }
      DistanceSensor {
        name "fly_prox_18"
        type "infra-red"
        translation -0.00000 0.0015 -0.02050
        rotation 0 1 0 4.71239
        lookupTable [
          0 1000 0
          0.28 0 0
        ]
      }
      DistanceSensor {
        name "fly_prox_19"
        type "infra-red"
        translation 0.00531 0.0015 -0.01980
        rotation 0 1 0 4.97419
        lookupTable [
          0 1000 0
          0.28 0 0
        ]
      }
      DistanceSensor {
        name "fly_prox_20"
        type "infra-red"
        translation 0.01025 0.0015 -0.01775
        rotation 0 1 0 5.23599
        lookupTable [
          0 1000 0
          0.28 0 0
        ]
      }
      DistanceSensor {
        name "fly_prox_21"
        type "infra-red"
        translation 0.01450 0.0015 -0.01450
        rotation 0 1 0 5.49779
        lookupTable [
          0 1000 0
          0.28 0 0
        ]
      }
      DistanceSensor {
        name "fly_prox_22"
        type "infra-red"
        translation 0.01775 0.0015 -0.01025
        rotation 0 1 0 5.75959
        lookupTable [
          0 1000 0
          0.28 0 0
        ]
      }
      DistanceSensor {
        name "fly_prox_23"
        type "infra-red"
        translation 0.01980 0.0015 -0.00531
        rotation 0 1 0 6.02139
        lookupTable [
          0 1000 0
          0.28 0 0
        ]
      }

    DEF JOINT_0_720575941493231536 HingeJoint {
      jointParameters HingeJointParameters {
        anchor 0.01300 -0.00270 0.00000
        axis 0 1 0
      }
      device [
        RotationalMotor {
          name "720575941493231536"
          maxVelocity 14
          minPosition -1.6
          maxPosition 1.6
        }
      ]
      endPoint DEF SEGMENT_0_720575941493231536 Solid {
        name "SEGMENT_0_720575941493231536"
        translation 0.01300 -0.00270 0.00000
        children [
          Shape {
            appearance PBRAppearance {
              baseColor 0.28 0.22 0.18
              roughness 0.55
              metalness 0
            }
            geometry Capsule {
              radius 0.0015
              height 0.008
            }
          }
        ]
        boundingObject Capsule {
          radius 0.0016
          height 0.008
        }
        physics Physics {
          density -1
          mass 0.00002
        }
      }
    }
    DEF JOINT_1_720575941643100754 HingeJoint {
      jointParameters HingeJointParameters {
        anchor 0.01201 -0.00150 0.00497
        axis 0 1 0
      }
      device [
        RotationalMotor {
          name "720575941643100754"
          maxVelocity 14
          minPosition -1.6
          maxPosition 1.6
        }
      ]
      endPoint DEF SEGMENT_1_720575941643100754 Solid {
        name "SEGMENT_1_720575941643100754"
        translation 0.01201 -0.00150 0.00497
        children [
          Shape {
            appearance PBRAppearance {
              baseColor 0.28 0.22 0.18
              roughness 0.55
              metalness 0
            }
            geometry Capsule {
              radius 0.0015
              height 0.008
            }
          }
        ]
        boundingObject Capsule {
          radius 0.0016
          height 0.008
        }
        physics Physics {
          density -1
          mass 0.00002
        }
      }
    }
    DEF JOINT_2_720575941488287797 HingeJoint {
      jointParameters HingeJointParameters {
        anchor 0.00919 -0.00030 0.00919
        axis 0 1 0
      }
      device [
        RotationalMotor {
          name "720575941488287797"
          maxVelocity 14
          minPosition -1.6
          maxPosition 1.6
        }
      ]
      endPoint DEF SEGMENT_2_720575941488287797 Solid {
        name "SEGMENT_2_720575941488287797"
        translation 0.00919 -0.00030 0.00919
        children [
          Shape {
            appearance PBRAppearance {
              baseColor 0.28 0.22 0.18
              roughness 0.55
              metalness 0
            }
            geometry Capsule {
              radius 0.0015
              height 0.008
            }
          }
        ]
        boundingObject Capsule {
          radius 0.0016
          height 0.008
        }
        physics Physics {
          density -1
          mass 0.00002
        }
      }
    }
    DEF JOINT_3_720575941720479034 HingeJoint {
      jointParameters HingeJointParameters {
        anchor 0.00497 -0.00270 0.01201
        axis 0 1 0
      }
      device [
        RotationalMotor {
          name "720575941720479034"
          maxVelocity 14
          minPosition -1.6
          maxPosition 1.6
        }
      ]
      endPoint DEF SEGMENT_3_720575941720479034 Solid {
        name "SEGMENT_3_720575941720479034"
        translation 0.00497 -0.00270 0.01201
        children [
          Shape {
            appearance PBRAppearance {
              baseColor 0.28 0.22 0.18
              roughness 0.55
              metalness 0
            }
            geometry Capsule {
              radius 0.0015
              height 0.008
            }
          }
        ]
        boundingObject Capsule {
          radius 0.0016
          height 0.008
        }
        physics Physics {
          density -1
          mass 0.00002
        }
      }
    }
    DEF JOINT_4_720575941470212471 HingeJoint {
      jointParameters HingeJointParameters {
        anchor 0.00000 -0.00150 0.01300
        axis 0 1 0
      }
      device [
        RotationalMotor {
          name "720575941470212471"
          maxVelocity 14
          minPosition -1.6
          maxPosition 1.6
        }
      ]
      endPoint DEF SEGMENT_4_720575941470212471 Solid {
        name "SEGMENT_4_720575941470212471"
        translation 0.00000 -0.00150 0.01300
        children [
          Shape {
            appearance PBRAppearance {
              baseColor 0.28 0.22 0.18
              roughness 0.55
              metalness 0
            }
            geometry Capsule {
              radius 0.0015
              height 0.008
            }
          }
        ]
        boundingObject Capsule {
          radius 0.0016
          height 0.008
        }
        physics Physics {
          density -1
          mass 0.00002
        }
      }
    }
    DEF JOINT_5_720575941471839296 HingeJoint {
      jointParameters HingeJointParameters {
        anchor -0.00497 -0.00030 0.01201
        axis 0 1 0
      }
      device [
        RotationalMotor {
          name "720575941471839296"
          maxVelocity 14
          minPosition -1.6
          maxPosition 1.6
        }
      ]
      endPoint DEF SEGMENT_5_720575941471839296 Solid {
        name "SEGMENT_5_720575941471839296"
        translation -0.00497 -0.00030 0.01201
        children [
          Shape {
            appearance PBRAppearance {
              baseColor 0.28 0.22 0.18
              roughness 0.55
              metalness 0
            }
            geometry Capsule {
              radius 0.0015
              height 0.008
            }
          }
        ]
        boundingObject Capsule {
          radius 0.0016
          height 0.008
        }
        physics Physics {
          density -1
          mass 0.00002
        }
      }
    }
    DEF JOINT_6_720575941508453761 HingeJoint {
      jointParameters HingeJointParameters {
        anchor -0.00919 -0.00270 0.00919
        axis 0 1 0
      }
      device [
        RotationalMotor {
          name "720575941508453761"
          maxVelocity 14
          minPosition -1.6
          maxPosition 1.6
        }
      ]
      endPoint DEF SEGMENT_6_720575941508453761 Solid {
        name "SEGMENT_6_720575941508453761"
        translation -0.00919 -0.00270 0.00919
        children [
          Shape {
            appearance PBRAppearance {
              baseColor 0.28 0.22 0.18
              roughness 0.55
              metalness 0
            }
            geometry Capsule {
              radius 0.0015
              height 0.008
            }
          }
        ]
        boundingObject Capsule {
          radius 0.0016
          height 0.008
        }
        physics Physics {
          density -1
          mass 0.00002
        }
      }
    }
    DEF JOINT_7_720575941568553330 HingeJoint {
      jointParameters HingeJointParameters {
        anchor -0.01201 -0.00150 0.00497
        axis 0 1 0
      }
      device [
        RotationalMotor {
          name "720575941568553330"
          maxVelocity 14
          minPosition -1.6
          maxPosition 1.6
        }
      ]
      endPoint DEF SEGMENT_7_720575941568553330 Solid {
        name "SEGMENT_7_720575941568553330"
        translation -0.01201 -0.00150 0.00497
        children [
          Shape {
            appearance PBRAppearance {
              baseColor 0.28 0.22 0.18
              roughness 0.55
              metalness 0
            }
            geometry Capsule {
              radius 0.0015
              height 0.008
            }
          }
        ]
        boundingObject Capsule {
          radius 0.0016
          height 0.008
        }
        physics Physics {
          density -1
          mass 0.00002
        }
      }
    }
    DEF JOINT_8_720575941475745898 HingeJoint {
      jointParameters HingeJointParameters {
        anchor -0.01300 -0.00030 0.00000
        axis 0 1 0
      }
      device [
        RotationalMotor {
          name "720575941475745898"
          maxVelocity 14
          minPosition -1.6
          maxPosition 1.6
        }
      ]
      endPoint DEF SEGMENT_8_720575941475745898 Solid {
        name "SEGMENT_8_720575941475745898"
        translation -0.01300 -0.00030 0.00000
        children [
          Shape {
            appearance PBRAppearance {
              baseColor 0.28 0.22 0.18
              roughness 0.55
              metalness 0
            }
            geometry Capsule {
              radius 0.0015
              height 0.008
            }
          }
        ]
        boundingObject Capsule {
          radius 0.0016
          height 0.008
        }
        physics Physics {
          density -1
          mass 0.00002
        }
      }
    }
    DEF JOINT_9_720575941655597785 HingeJoint {
      jointParameters HingeJointParameters {
        anchor -0.01201 -0.00270 -0.00497
        axis 0 1 0
      }
      device [
        RotationalMotor {
          name "720575941655597785"
          maxVelocity 14
          minPosition -1.6
          maxPosition 1.6
        }
      ]
      endPoint DEF SEGMENT_9_720575941655597785 Solid {
        name "SEGMENT_9_720575941655597785"
        translation -0.01201 -0.00270 -0.00497
        children [
          Shape {
            appearance PBRAppearance {
              baseColor 0.28 0.22 0.18
              roughness 0.55
              metalness 0
            }
            geometry Capsule {
              radius 0.0015
              height 0.008
            }
          }
        ]
        boundingObject Capsule {
          radius 0.0016
          height 0.008
        }
        physics Physics {
          density -1
          mass 0.00002
        }
      }
    }
    DEF JOINT_10_720575941593843589 HingeJoint {
      jointParameters HingeJointParameters {
        anchor -0.00919 -0.00150 -0.00919
        axis 0 1 0
      }
      device [
        RotationalMotor {
          name "720575941593843589"
          maxVelocity 14
          minPosition -1.6
          maxPosition 1.6
        }
      ]
      endPoint DEF SEGMENT_10_720575941593843589 Solid {
        name "SEGMENT_10_720575941593843589"
        translation -0.00919 -0.00150 -0.00919
        children [
          Shape {
            appearance PBRAppearance {
              baseColor 0.28 0.22 0.18
              roughness 0.55
              metalness 0
            }
            geometry Capsule {
              radius 0.0015
              height 0.008
            }
          }
        ]
        boundingObject Capsule {
          radius 0.0016
          height 0.008
        }
        physics Physics {
          density -1
          mass 0.00002
        }
      }
    }
    DEF JOINT_11_720575941569529458 HingeJoint {
      jointParameters HingeJointParameters {
        anchor -0.00497 -0.00030 -0.01201
        axis 0 1 0
      }
      device [
        RotationalMotor {
          name "720575941569529458"
          maxVelocity 14
          minPosition -1.6
          maxPosition 1.6
        }
      ]
      endPoint DEF SEGMENT_11_720575941569529458 Solid {
        name "SEGMENT_11_720575941569529458"
        translation -0.00497 -0.00030 -0.01201
        children [
          Shape {
            appearance PBRAppearance {
              baseColor 0.28 0.22 0.18
              roughness 0.55
              metalness 0
            }
            geometry Capsule {
              radius 0.0015
              height 0.008
            }
          }
        ]
        boundingObject Capsule {
          radius 0.0016
          height 0.008
        }
        physics Physics {
          density -1
          mass 0.00002
        }
      }
    }
    DEF JOINT_12_720575941547394081 HingeJoint {
      jointParameters HingeJointParameters {
        anchor -0.00000 -0.00270 -0.01300
        axis 0 1 0
      }
      device [
        RotationalMotor {
          name "720575941547394081"
          maxVelocity 14
          minPosition -1.6
          maxPosition 1.6
        }
      ]
      endPoint DEF SEGMENT_12_720575941547394081 Solid {
        name "SEGMENT_12_720575941547394081"
        translation -0.00000 -0.00270 -0.01300
        children [
          Shape {
            appearance PBRAppearance {
              baseColor 0.28 0.22 0.18
              roughness 0.55
              metalness 0
            }
            geometry Capsule {
              radius 0.0015
              height 0.008
            }
          }
        ]
        boundingObject Capsule {
          radius 0.0016
          height 0.008
        }
        physics Physics {
          density -1
          mass 0.00002
        }
      }
    }
    DEF JOINT_13_720575941531180261 HingeJoint {
      jointParameters HingeJointParameters {
        anchor 0.00497 -0.00150 -0.01201
        axis 0 1 0
      }
      device [
        RotationalMotor {
          name "720575941531180261"
          maxVelocity 14
          minPosition -1.6
          maxPosition 1.6
        }
      ]
      endPoint DEF SEGMENT_13_720575941531180261 Solid {
        name "SEGMENT_13_720575941531180261"
        translation 0.00497 -0.00150 -0.01201
        children [
          Shape {
            appearance PBRAppearance {
              baseColor 0.28 0.22 0.18
              roughness 0.55
              metalness 0
            }
            geometry Capsule {
              radius 0.0015
              height 0.008
            }
          }
        ]
        boundingObject Capsule {
          radius 0.0016
          height 0.008
        }
        physics Physics {
          density -1
          mass 0.00002
        }
      }
    }
    DEF JOINT_14_720575941478187841 HingeJoint {
      jointParameters HingeJointParameters {
        anchor 0.00919 -0.00030 -0.00919
        axis 0 1 0
      }
      device [
        RotationalMotor {
          name "720575941478187841"
          maxVelocity 14
          minPosition -1.6
          maxPosition 1.6
        }
      ]
      endPoint DEF SEGMENT_14_720575941478187841 Solid {
        name "SEGMENT_14_720575941478187841"
        translation 0.00919 -0.00030 -0.00919
        children [
          Shape {
            appearance PBRAppearance {
              baseColor 0.28 0.22 0.18
              roughness 0.55
              metalness 0
            }
            geometry Capsule {
              radius 0.0015
              height 0.008
            }
          }
        ]
        boundingObject Capsule {
          radius 0.0016
          height 0.008
        }
        physics Physics {
          density -1
          mass 0.00002
        }
      }
    }
    DEF JOINT_15_720575941516874094 HingeJoint {
      jointParameters HingeJointParameters {
        anchor 0.01201 -0.00270 -0.00497
        axis 0 1 0
      }
      device [
        RotationalMotor {
          name "720575941516874094"
          maxVelocity 14
          minPosition -1.6
          maxPosition 1.6
        }
      ]
      endPoint DEF SEGMENT_15_720575941516874094 Solid {
        name "SEGMENT_15_720575941516874094"
        translation 0.01201 -0.00270 -0.00497
        children [
          Shape {
            appearance PBRAppearance {
              baseColor 0.28 0.22 0.18
              roughness 0.55
              metalness 0
            }
            geometry Capsule {
              radius 0.0015
              height 0.008
            }
          }
        ]
        boundingObject Capsule {
          radius 0.0016
          height 0.008
        }
        physics Physics {
          density -1
          mass 0.00002
        }
      }
    }
    DEF JOINT_16_720575941455787245 HingeJoint {
      jointParameters HingeJointParameters {
        anchor 0.01650 -0.00150 0.00000
        axis 0 1 0
      }
      device [
        RotationalMotor {
          name "720575941455787245"
          maxVelocity 14
          minPosition -1.6
          maxPosition 1.6
        }
      ]
      endPoint DEF SEGMENT_16_720575941455787245 Solid {
        name "SEGMENT_16_720575941455787245"
        translation 0.01650 -0.00150 0.00000
        children [
          Shape {
            appearance PBRAppearance {
              baseColor 0.28 0.22 0.18
              roughness 0.55
              metalness 0
            }
            geometry Capsule {
              radius 0.0015
              height 0.008
            }
          }
        ]
        boundingObject Capsule {
          radius 0.0016
          height 0.008
        }
        physics Physics {
          density -1
          mass 0.00002
        }
      }
    }
    DEF JOINT_17_720575941593715569 HingeJoint {
      jointParameters HingeJointParameters {
        anchor 0.01524 -0.00030 0.00631
        axis 0 1 0
      }
      device [
        RotationalMotor {
          name "720575941593715569"
          maxVelocity 14
          minPosition -1.6
          maxPosition 1.6
        }
      ]
      endPoint DEF SEGMENT_17_720575941593715569 Solid {
        name "SEGMENT_17_720575941593715569"
        translation 0.01524 -0.00030 0.00631
        children [
          Shape {
            appearance PBRAppearance {
              baseColor 0.28 0.22 0.18
              roughness 0.55
              metalness 0
            }
            geometry Capsule {
              radius 0.0015
              height 0.008
            }
          }
        ]
        boundingObject Capsule {
          radius 0.0016
          height 0.008
        }
        physics Physics {
          density -1
          mass 0.00002
        }
      }
    }
    DEF JOINT_18_720575941553516167 HingeJoint {
      jointParameters HingeJointParameters {
        anchor 0.01167 -0.00270 0.01167
        axis 0 1 0
      }
      device [
        RotationalMotor {
          name "720575941553516167"
          maxVelocity 14
          minPosition -1.6
          maxPosition 1.6
        }
      ]
      endPoint DEF SEGMENT_18_720575941553516167 Solid {
        name "SEGMENT_18_720575941553516167"
        translation 0.01167 -0.00270 0.01167
        children [
          Shape {
            appearance PBRAppearance {
              baseColor 0.28 0.22 0.18
              roughness 0.55
              metalness 0
            }
            geometry Capsule {
              radius 0.0015
              height 0.008
            }
          }
        ]
        boundingObject Capsule {
          radius 0.0016
          height 0.008
        }
        physics Physics {
          density -1
          mass 0.00002
        }
      }
    }
    DEF JOINT_19_720575941558861839 HingeJoint {
      jointParameters HingeJointParameters {
        anchor 0.00631 -0.00150 0.01524
        axis 0 1 0
      }
      device [
        RotationalMotor {
          name "720575941558861839"
          maxVelocity 14
          minPosition -1.6
          maxPosition 1.6
        }
      ]
      endPoint DEF SEGMENT_19_720575941558861839 Solid {
        name "SEGMENT_19_720575941558861839"
        translation 0.00631 -0.00150 0.01524
        children [
          Shape {
            appearance PBRAppearance {
              baseColor 0.28 0.22 0.18
              roughness 0.55
              metalness 0
            }
            geometry Capsule {
              radius 0.0015
              height 0.008
            }
          }
        ]
        boundingObject Capsule {
          radius 0.0016
          height 0.008
        }
        physics Physics {
          density -1
          mass 0.00002
        }
      }
    }
    DEF JOINT_20_720575941525308582 HingeJoint {
      jointParameters HingeJointParameters {
        anchor 0.00000 -0.00030 0.01650
        axis 0 1 0
      }
      device [
        RotationalMotor {
          name "720575941525308582"
          maxVelocity 14
          minPosition -1.6
          maxPosition 1.6
        }
      ]
      endPoint DEF SEGMENT_20_720575941525308582 Solid {
        name "SEGMENT_20_720575941525308582"
        translation 0.00000 -0.00030 0.01650
        children [
          Shape {
            appearance PBRAppearance {
              baseColor 0.28 0.22 0.18
              roughness 0.55
              metalness 0
            }
            geometry Capsule {
              radius 0.0015
              height 0.008
            }
          }
        ]
        boundingObject Capsule {
          radius 0.0016
          height 0.008
        }
        physics Physics {
          density -1
          mass 0.00002
        }
      }
    }
    DEF JOINT_21_720575941645041313 HingeJoint {
      jointParameters HingeJointParameters {
        anchor -0.00631 -0.00270 0.01524
        axis 0 1 0
      }
      device [
        RotationalMotor {
          name "720575941645041313"
          maxVelocity 14
          minPosition -1.6
          maxPosition 1.6
        }
      ]
      endPoint DEF SEGMENT_21_720575941645041313 Solid {
        name "SEGMENT_21_720575941645041313"
        translation -0.00631 -0.00270 0.01524
        children [
          Shape {
            appearance PBRAppearance {
              baseColor 0.28 0.22 0.18
              roughness 0.55
              metalness 0
            }
            geometry Capsule {
              radius 0.0015
              height 0.008
            }
          }
        ]
        boundingObject Capsule {
          radius 0.0016
          height 0.008
        }
        physics Physics {
          density -1
          mass 0.00002
        }
      }
    }
    DEF JOINT_22_720575941573215995 HingeJoint {
      jointParameters HingeJointParameters {
        anchor -0.01167 -0.00150 0.01167
        axis 0 1 0
      }
      device [
        RotationalMotor {
          name "720575941573215995"
          maxVelocity 14
          minPosition -1.6
          maxPosition 1.6
        }
      ]
      endPoint DEF SEGMENT_22_720575941573215995 Solid {
        name "SEGMENT_22_720575941573215995"
        translation -0.01167 -0.00150 0.01167
        children [
          Shape {
            appearance PBRAppearance {
              baseColor 0.28 0.22 0.18
              roughness 0.55
              metalness 0
            }
            geometry Capsule {
              radius 0.0015
              height 0.008
            }
          }
        ]
        boundingObject Capsule {
          radius 0.0016
          height 0.008
        }
        physics Physics {
          density -1
          mass 0.00002
        }
      }
    }
    DEF JOINT_23_720575941519664856 HingeJoint {
      jointParameters HingeJointParameters {
        anchor -0.01524 -0.00030 0.00631
        axis 0 1 0
      }
      device [
        RotationalMotor {
          name "720575941519664856"
          maxVelocity 14
          minPosition -1.6
          maxPosition 1.6
        }
      ]
      endPoint DEF SEGMENT_23_720575941519664856 Solid {
        name "SEGMENT_23_720575941519664856"
        translation -0.01524 -0.00030 0.00631
        children [
          Shape {
            appearance PBRAppearance {
              baseColor 0.28 0.22 0.18
              roughness 0.55
              metalness 0
            }
            geometry Capsule {
              radius 0.0015
              height 0.008
            }
          }
        ]
        boundingObject Capsule {
          radius 0.0016
          height 0.008
        }
        physics Physics {
          density -1
          mass 0.00002
        }
      }
    }
    DEF JOINT_24_720575941498960546 HingeJoint {
      jointParameters HingeJointParameters {
        anchor -0.01650 -0.00270 0.00000
        axis 0 1 0
      }
      device [
        RotationalMotor {
          name "720575941498960546"
          maxVelocity 14
          minPosition -1.6
          maxPosition 1.6
        }
      ]
      endPoint DEF SEGMENT_24_720575941498960546 Solid {
        name "SEGMENT_24_720575941498960546"
        translation -0.01650 -0.00270 0.00000
        children [
          Shape {
            appearance PBRAppearance {
              baseColor 0.28 0.22 0.18
              roughness 0.55
              metalness 0
            }
            geometry Capsule {
              radius 0.0015
              height 0.008
            }
          }
        ]
        boundingObject Capsule {
          radius 0.0016
          height 0.008
        }
        physics Physics {
          density -1
          mass 0.00002
        }
      }
    }
    DEF JOINT_25_720575941573687049 HingeJoint {
      jointParameters HingeJointParameters {
        anchor -0.01524 -0.00150 -0.00631
        axis 0 1 0
      }
      device [
        RotationalMotor {
          name "720575941573687049"
          maxVelocity 14
          minPosition -1.6
          maxPosition 1.6
        }
      ]
      endPoint DEF SEGMENT_25_720575941573687049 Solid {
        name "SEGMENT_25_720575941573687049"
        translation -0.01524 -0.00150 -0.00631
        children [
          Shape {
            appearance PBRAppearance {
              baseColor 0.28 0.22 0.18
              roughness 0.55
              metalness 0
            }
            geometry Capsule {
              radius 0.0015
              height 0.008
            }
          }
        ]
        boundingObject Capsule {
          radius 0.0016
          height 0.008
        }
        physics Physics {
          density -1
          mass 0.00002
        }
      }
    }
    DEF JOINT_26_720575941459347411 HingeJoint {
      jointParameters HingeJointParameters {
        anchor -0.01167 -0.00030 -0.01167
        axis 0 1 0
      }
      device [
        RotationalMotor {
          name "720575941459347411"
          maxVelocity 14
          minPosition -1.6
          maxPosition 1.6
        }
      ]
      endPoint DEF SEGMENT_26_720575941459347411 Solid {
        name "SEGMENT_26_720575941459347411"
        translation -0.01167 -0.00030 -0.01167
        children [
          Shape {
            appearance PBRAppearance {
              baseColor 0.28 0.22 0.18
              roughness 0.55
              metalness 0
            }
            geometry Capsule {
              radius 0.0015
              height 0.008
            }
          }
        ]
        boundingObject Capsule {
          radius 0.0016
          height 0.008
        }
        physics Physics {
          density -1
          mass 0.00002
        }
      }
    }
    DEF JOINT_27_720575941468687581 HingeJoint {
      jointParameters HingeJointParameters {
        anchor -0.00631 -0.00270 -0.01524
        axis 0 1 0
      }
      device [
        RotationalMotor {
          name "720575941468687581"
          maxVelocity 14
          minPosition -1.6
          maxPosition 1.6
        }
      ]
      endPoint DEF SEGMENT_27_720575941468687581 Solid {
        name "SEGMENT_27_720575941468687581"
        translation -0.00631 -0.00270 -0.01524
        children [
          Shape {
            appearance PBRAppearance {
              baseColor 0.28 0.22 0.18
              roughness 0.55
              metalness 0
            }
            geometry Capsule {
              radius 0.0015
              height 0.008
            }
          }
        ]
        boundingObject Capsule {
          radius 0.0016
          height 0.008
        }
        physics Physics {
          density -1
          mass 0.00002
        }
      }
    }
    DEF JOINT_28_720575941580669817 HingeJoint {
      jointParameters HingeJointParameters {
        anchor -0.00000 -0.00150 -0.01650
        axis 0 1 0
      }
      device [
        RotationalMotor {
          name "720575941580669817"
          maxVelocity 14
          minPosition -1.6
          maxPosition 1.6
        }
      ]
      endPoint DEF SEGMENT_28_720575941580669817 Solid {
        name "SEGMENT_28_720575941580669817"
        translation -0.00000 -0.00150 -0.01650
        children [
          Shape {
            appearance PBRAppearance {
              baseColor 0.28 0.22 0.18
              roughness 0.55
              metalness 0
            }
            geometry Capsule {
              radius 0.0015
              height 0.008
            }
          }
        ]
        boundingObject Capsule {
          radius 0.0016
          height 0.008
        }
        physics Physics {
          density -1
          mass 0.00002
        }
      }
    }
    DEF JOINT_29_720575941684824815 HingeJoint {
      jointParameters HingeJointParameters {
        anchor 0.00631 -0.00030 -0.01524
        axis 0 1 0
      }
      device [
        RotationalMotor {
          name "720575941684824815"
          maxVelocity 14
          minPosition -1.6
          maxPosition 1.6
        }
      ]
      endPoint DEF SEGMENT_29_720575941684824815 Solid {
        name "SEGMENT_29_720575941684824815"
        translation 0.00631 -0.00030 -0.01524
        children [
          Shape {
            appearance PBRAppearance {
              baseColor 0.28 0.22 0.18
              roughness 0.55
              metalness 0
            }
            geometry Capsule {
              radius 0.0015
              height 0.008
            }
          }
        ]
        boundingObject Capsule {
          radius 0.0016
          height 0.008
        }
        physics Physics {
          density -1
          mass 0.00002
        }
      }
    }
    DEF JOINT_30_720575941634236347 HingeJoint {
      jointParameters HingeJointParameters {
        anchor 0.01167 -0.00270 -0.01167
        axis 0 1 0
      }
      device [
        RotationalMotor {
          name "720575941634236347"
          maxVelocity 14
          minPosition -1.6
          maxPosition 1.6
        }
      ]
      endPoint DEF SEGMENT_30_720575941634236347 Solid {
        name "SEGMENT_30_720575941634236347"
        translation 0.01167 -0.00270 -0.01167
        children [
          Shape {
            appearance PBRAppearance {
              baseColor 0.28 0.22 0.18
              roughness 0.55
              metalness 0
            }
            geometry Capsule {
              radius 0.0015
              height 0.008
            }
          }
        ]
        boundingObject Capsule {
          radius 0.0016
          height 0.008
        }
        physics Physics {
          density -1
          mass 0.00002
        }
      }
    }
    DEF JOINT_31_720575941508440193 HingeJoint {
      jointParameters HingeJointParameters {
        anchor 0.01524 -0.00150 -0.00631
        axis 0 1 0
      }
      device [
        RotationalMotor {
          name "720575941508440193"
          maxVelocity 14
          minPosition -1.6
          maxPosition 1.6
        }
      ]
      endPoint DEF SEGMENT_31_720575941508440193 Solid {
        name "SEGMENT_31_720575941508440193"
        translation 0.01524 -0.00150 -0.00631
        children [
          Shape {
            appearance PBRAppearance {
              baseColor 0.28 0.22 0.18
              roughness 0.55
              metalness 0
            }
            geometry Capsule {
              radius 0.0015
              height 0.008
            }
          }
        ]
        boundingObject Capsule {
          radius 0.0016
          height 0.008
        }
        physics Physics {
          density -1
          mass 0.00002
        }
      }
    }
    DEF JOINT_32_720575941480138976 HingeJoint {
      jointParameters HingeJointParameters {
        anchor 0.02000 -0.00030 0.00000
        axis 0 1 0
      }
      device [
        RotationalMotor {
          name "720575941480138976"
          maxVelocity 14
          minPosition -1.6
          maxPosition 1.6
        }
      ]
      endPoint DEF SEGMENT_32_720575941480138976 Solid {
        name "SEGMENT_32_720575941480138976"
        translation 0.02000 -0.00030 0.00000
        children [
          Shape {
            appearance PBRAppearance {
              baseColor 0.28 0.22 0.18
              roughness 0.55
              metalness 0
            }
            geometry Capsule {
              radius 0.0015
              height 0.008
            }
          }
        ]
        boundingObject Capsule {
          radius 0.0016
          height 0.008
        }
        physics Physics {
          density -1
          mass 0.00002
        }
      }
    }
    DEF JOINT_33_720575941516770670 HingeJoint {
      jointParameters HingeJointParameters {
        anchor 0.01848 -0.00270 0.00765
        axis 0 1 0
      }
      device [
        RotationalMotor {
          name "720575941516770670"
          maxVelocity 14
          minPosition -1.6
          maxPosition 1.6
        }
      ]
      endPoint DEF SEGMENT_33_720575941516770670 Solid {
        name "SEGMENT_33_720575941516770670"
        translation 0.01848 -0.00270 0.00765
        children [
          Shape {
            appearance PBRAppearance {
              baseColor 0.28 0.22 0.18
              roughness 0.55
              metalness 0
            }
            geometry Capsule {
              radius 0.0015
              height 0.008
            }
          }
        ]
        boundingObject Capsule {
          radius 0.0016
          height 0.008
        }
        physics Physics {
          density -1
          mass 0.00002
        }
      }
    }
    DEF JOINT_34_720575941432965902 HingeJoint {
      jointParameters HingeJointParameters {
        anchor 0.01414 -0.00150 0.01414
        axis 0 1 0
      }
      device [
        RotationalMotor {
          name "720575941432965902"
          maxVelocity 14
          minPosition -1.6
          maxPosition 1.6
        }
      ]
      endPoint DEF SEGMENT_34_720575941432965902 Solid {
        name "SEGMENT_34_720575941432965902"
        translation 0.01414 -0.00150 0.01414
        children [
          Shape {
            appearance PBRAppearance {
              baseColor 0.28 0.22 0.18
              roughness 0.55
              metalness 0
            }
            geometry Capsule {
              radius 0.0015
              height 0.008
            }
          }
        ]
        boundingObject Capsule {
          radius 0.0016
          height 0.008
        }
        physics Physics {
          density -1
          mass 0.00002
        }
      }
    }
    DEF JOINT_35_720575941481634383 HingeJoint {
      jointParameters HingeJointParameters {
        anchor 0.00765 -0.00030 0.01848
        axis 0 1 0
      }
      device [
        RotationalMotor {
          name "720575941481634383"
          maxVelocity 14
          minPosition -1.6
          maxPosition 1.6
        }
      ]
      endPoint DEF SEGMENT_35_720575941481634383 Solid {
        name "SEGMENT_35_720575941481634383"
        translation 0.00765 -0.00030 0.01848
        children [
          Shape {
            appearance PBRAppearance {
              baseColor 0.28 0.22 0.18
              roughness 0.55
              metalness 0
            }
            geometry Capsule {
              radius 0.0015
              height 0.008
            }
          }
        ]
        boundingObject Capsule {
          radius 0.0016
          height 0.008
        }
        physics Physics {
          density -1
          mass 0.00002
        }
      }
    }
    DEF JOINT_36_720575941624155644 HingeJoint {
      jointParameters HingeJointParameters {
        anchor 0.00000 -0.00270 0.02000
        axis 0 1 0
      }
      device [
        RotationalMotor {
          name "720575941624155644"
          maxVelocity 14
          minPosition -1.6
          maxPosition 1.6
        }
      ]
      endPoint DEF SEGMENT_36_720575941624155644 Solid {
        name "SEGMENT_36_720575941624155644"
        translation 0.00000 -0.00270 0.02000
        children [
          Shape {
            appearance PBRAppearance {
              baseColor 0.28 0.22 0.18
              roughness 0.55
              metalness 0
            }
            geometry Capsule {
              radius 0.0015
              height 0.008
            }
          }
        ]
        boundingObject Capsule {
          radius 0.0016
          height 0.008
        }
        physics Physics {
          density -1
          mass 0.00002
        }
      }
    }
    DEF JOINT_37_720575941461179859 HingeJoint {
      jointParameters HingeJointParameters {
        anchor -0.00765 -0.00150 0.01848
        axis 0 1 0
      }
      device [
        RotationalMotor {
          name "720575941461179859"
          maxVelocity 14
          minPosition -1.6
          maxPosition 1.6
        }
      ]
      endPoint DEF SEGMENT_37_720575941461179859 Solid {
        name "SEGMENT_37_720575941461179859"
        translation -0.00765 -0.00150 0.01848
        children [
          Shape {
            appearance PBRAppearance {
              baseColor 0.28 0.22 0.18
              roughness 0.55
              metalness 0
            }
            geometry Capsule {
              radius 0.0015
              height 0.008
            }
          }
        ]
        boundingObject Capsule {
          radius 0.0016
          height 0.008
        }
        physics Physics {
          density -1
          mass 0.00002
        }
      }
    }
    DEF JOINT_38_720575941630940642 HingeJoint {
      jointParameters HingeJointParameters {
        anchor -0.01414 -0.00030 0.01414
        axis 0 1 0
      }
      device [
        RotationalMotor {
          name "720575941630940642"
          maxVelocity 14
          minPosition -1.6
          maxPosition 1.6
        }
      ]
      endPoint DEF SEGMENT_38_720575941630940642 Solid {
        name "SEGMENT_38_720575941630940642"
        translation -0.01414 -0.00030 0.01414
        children [
          Shape {
            appearance PBRAppearance {
              baseColor 0.28 0.22 0.18
              roughness 0.55
              metalness 0
            }
            geometry Capsule {
              radius 0.0015
              height 0.008
            }
          }
        ]
        boundingObject Capsule {
          radius 0.0016
          height 0.008
        }
        physics Physics {
          density -1
          mass 0.00002
        }
      }
    }
    DEF JOINT_39_720575941470082423 HingeJoint {
      jointParameters HingeJointParameters {
        anchor -0.01848 -0.00270 0.00765
        axis 0 1 0
      }
      device [
        RotationalMotor {
          name "720575941470082423"
          maxVelocity 14
          minPosition -1.6
          maxPosition 1.6
        }
      ]
      endPoint DEF SEGMENT_39_720575941470082423 Solid {
        name "SEGMENT_39_720575941470082423"
        translation -0.01848 -0.00270 0.00765
        children [
          Shape {
            appearance PBRAppearance {
              baseColor 0.28 0.22 0.18
              roughness 0.55
              metalness 0
            }
            geometry Capsule {
              radius 0.0015
              height 0.008
            }
          }
        ]
        boundingObject Capsule {
          radius 0.0016
          height 0.008
        }
        physics Physics {
          density -1
          mass 0.00002
        }
      }
    }
    DEF JOINT_40_720575941687653238 HingeJoint {
      jointParameters HingeJointParameters {
        anchor -0.02000 -0.00150 0.00000
        axis 0 1 0
      }
      device [
        RotationalMotor {
          name "720575941687653238"
          maxVelocity 14
          minPosition -1.6
          maxPosition 1.6
        }
      ]
      endPoint DEF SEGMENT_40_720575941687653238 Solid {
        name "SEGMENT_40_720575941687653238"
        translation -0.02000 -0.00150 0.00000
        children [
          Shape {
            appearance PBRAppearance {
              baseColor 0.28 0.22 0.18
              roughness 0.55
              metalness 0
            }
            geometry Capsule {
              radius 0.0015
              height 0.008
            }
          }
        ]
        boundingObject Capsule {
          radius 0.0016
          height 0.008
        }
        physics Physics {
          density -1
          mass 0.00002
        }
      }
    }
    DEF JOINT_41_720575941623920586 HingeJoint {
      jointParameters HingeJointParameters {
        anchor -0.01848 -0.00030 -0.00765
        axis 0 1 0
      }
      device [
        RotationalMotor {
          name "720575941623920586"
          maxVelocity 14
          minPosition -1.6
          maxPosition 1.6
        }
      ]
      endPoint DEF SEGMENT_41_720575941623920586 Solid {
        name "SEGMENT_41_720575941623920586"
        translation -0.01848 -0.00030 -0.00765
        children [
          Shape {
            appearance PBRAppearance {
              baseColor 0.28 0.22 0.18
              roughness 0.55
              metalness 0
            }
            geometry Capsule {
              radius 0.0015
              height 0.008
            }
          }
        ]
        boundingObject Capsule {
          radius 0.0016
          height 0.008
        }
        physics Physics {
          density -1
          mass 0.00002
        }
      }
    }
    DEF JOINT_42_720575941667762097 HingeJoint {
      jointParameters HingeJointParameters {
        anchor -0.01414 -0.00270 -0.01414
        axis 0 1 0
      }
      device [
        RotationalMotor {
          name "720575941667762097"
          maxVelocity 14
          minPosition -1.6
          maxPosition 1.6
        }
      ]
      endPoint DEF SEGMENT_42_720575941667762097 Solid {
        name "SEGMENT_42_720575941667762097"
        translation -0.01414 -0.00270 -0.01414
        children [
          Shape {
            appearance PBRAppearance {
              baseColor 0.28 0.22 0.18
              roughness 0.55
              metalness 0
            }
            geometry Capsule {
              radius 0.0015
              height 0.008
            }
          }
        ]
        boundingObject Capsule {
          radius 0.0016
          height 0.008
        }
        physics Physics {
          density -1
          mass 0.00002
        }
      }
    }
    DEF JOINT_43_720575941596050112 HingeJoint {
      jointParameters HingeJointParameters {
        anchor -0.00765 -0.00150 -0.01848
        axis 0 1 0
      }
      device [
        RotationalMotor {
          name "720575941596050112"
          maxVelocity 14
          minPosition -1.6
          maxPosition 1.6
        }
      ]
      endPoint DEF SEGMENT_43_720575941596050112 Solid {
        name "SEGMENT_43_720575941596050112"
        translation -0.00765 -0.00150 -0.01848
        children [
          Shape {
            appearance PBRAppearance {
              baseColor 0.28 0.22 0.18
              roughness 0.55
              metalness 0
            }
            geometry Capsule {
              radius 0.0015
              height 0.008
            }
          }
        ]
        boundingObject Capsule {
          radius 0.0016
          height 0.008
        }
        physics Physics {
          density -1
          mass 0.00002
        }
      }
    }
    DEF JOINT_44_720575941553691876 HingeJoint {
      jointParameters HingeJointParameters {
        anchor -0.00000 -0.00030 -0.02000
        axis 0 1 0
      }
      device [
        RotationalMotor {
          name "720575941553691876"
          maxVelocity 14
          minPosition -1.6
          maxPosition 1.6
        }
      ]
      endPoint DEF SEGMENT_44_720575941553691876 Solid {
        name "SEGMENT_44_720575941553691876"
        translation -0.00000 -0.00030 -0.02000
        children [
          Shape {
            appearance PBRAppearance {
              baseColor 0.28 0.22 0.18
              roughness 0.55
              metalness 0
            }
            geometry Capsule {
              radius 0.0015
              height 0.008
            }
          }
        ]
        boundingObject Capsule {
          radius 0.0016
          height 0.008
        }
        physics Physics {
          density -1
          mass 0.00002
        }
      }
    }
    DEF JOINT_45_720575941534943937 HingeJoint {
      jointParameters HingeJointParameters {
        anchor 0.00765 -0.00270 -0.01848
        axis 0 1 0
      }
      device [
        RotationalMotor {
          name "720575941534943937"
          maxVelocity 14
          minPosition -1.6
          maxPosition 1.6
        }
      ]
      endPoint DEF SEGMENT_45_720575941534943937 Solid {
        name "SEGMENT_45_720575941534943937"
        translation 0.00765 -0.00270 -0.01848
        children [
          Shape {
            appearance PBRAppearance {
              baseColor 0.28 0.22 0.18
              roughness 0.55
              metalness 0
            }
            geometry Capsule {
              radius 0.0015
              height 0.008
            }
          }
        ]
        boundingObject Capsule {
          radius 0.0016
          height 0.008
        }
        physics Physics {
          density -1
          mass 0.00002
        }
      }
    }
    DEF JOINT_46_720575941506261538 HingeJoint {
      jointParameters HingeJointParameters {
        anchor 0.01414 -0.00150 -0.01414
        axis 0 1 0
      }
      device [
        RotationalMotor {
          name "720575941506261538"
          maxVelocity 14
          minPosition -1.6
          maxPosition 1.6
        }
      ]
      endPoint DEF SEGMENT_46_720575941506261538 Solid {
        name "SEGMENT_46_720575941506261538"
        translation 0.01414 -0.00150 -0.01414
        children [
          Shape {
            appearance PBRAppearance {
              baseColor 0.28 0.22 0.18
              roughness 0.55
              metalness 0
            }
            geometry Capsule {
              radius 0.0015
              height 0.008
            }
          }
        ]
        boundingObject Capsule {
          radius 0.0016
          height 0.008
        }
        physics Physics {
          density -1
          mass 0.00002
        }
      }
    }
    DEF JOINT_47_720575941513173763 HingeJoint {
      jointParameters HingeJointParameters {
        anchor 0.01848 -0.00030 -0.00765
        axis 0 1 0
      }
      device [
        RotationalMotor {
          name "720575941513173763"
          maxVelocity 14
          minPosition -1.6
          maxPosition 1.6
        }
      ]
      endPoint DEF SEGMENT_47_720575941513173763 Solid {
        name "SEGMENT_47_720575941513173763"
        translation 0.01848 -0.00030 -0.00765
        children [
          Shape {
            appearance PBRAppearance {
              baseColor 0.28 0.22 0.18
              roughness 0.55
              metalness 0
            }
            geometry Capsule {
              radius 0.0015
              height 0.008
            }
          }
        ]
        boundingObject Capsule {
          radius 0.0016
          height 0.008
        }
        physics Physics {
          density -1
          mass 0.00002
        }
      }
    }

      Group {
        children IS extensionSlot
      }
    ]
    boundingObject Group {
      children [
        Sphere {
          radius 0.0125
        }
        Transform {
          translation -0.020 0 0
          children [
            Capsule {
              radius 0.008
              height 0.022
            }
          ]
        }
      ]
    }
    physics Physics {
      density -1
      mass 0.008
    }
  }
}
