#VRML_SIM R2025a utf8

# Collision bounding boxes for the long acrylic leg links are intentionally thicker/heavier than their visual geometry to avoid Webots light-oblong inertia edge-case warnings.

PROTO HexapodRobot [
  field SFVec3f     translation 0 0 0.190
  field SFRotation  rotation 0 0 1 0
  field SFString    name "hexapod_robot"
  field SFString    controller "nao_nn_controller_uds"
  field MFString    controllerArgs [
    "NM_BRAINS=default"
    "NM_SENSORS_default=^hex_s_[0-9]{2}_.*$"
    "NM_ACTUATORS_default=^hex_o_[0-9]{3}_.*$"
  ]
  field MFNode      extensionSlot [ ]
]
{
  Robot {
    translation IS translation
    rotation IS rotation
    name IS name
    controller IS controller
    controllerArgs IS controllerArgs
    customData "{\"network\":\"../../network_hexapod.json\",\"config\":\"../configs/config_hexapod_webots.json\"}"
    children [
      Transform {
        translation 0 0 0
        children [
          Shape {
            appearance DEF HEX_BODY_APP PBRAppearance {
              # Freenove-style black acrylic chassis.
              baseColor 0.005 0.005 0.006
              roughness 0.32
              metalness 0.02
            }
            geometry Box {
              size 0.270 0.170 0.036
            }
          }
        ]
      }
      Transform {
        translation 0 0 0.022
        children [
          Shape {
            appearance PBRAppearance {
              baseColor 0.010 0.010 0.012
              roughness 0.26
              metalness 0.02
            }
            geometry Box {
              size 0.226 0.132 0.008
            }
          }
        ]
      }
      # Freenove Big Hexapod inspired visual detail: upper acrylic plate with vents,
      # exposed controller board, ultrasonic "eyes", front camera, top camera mast,
      # brass standoffs, servo casings and simplified wiring. These are deliberately
      # Shape/Solid visuals only, so the NN sensor/actuator ownership regexes and
      # auto-detected device counts are not changed.
      Transform {
        translation 0 0 0.058
        children [
          Shape {
            appearance USE HEX_BODY_APP
            geometry Box {
              size 0.245 0.155 0.008
            }
          }
        ]
      }
      # Vent slots on the upper acrylic cover.
      Transform {
        translation 0.035 0.000 0.063
        children [
          Shape {
            appearance DEF HEX_SLOT_APP PBRAppearance {
              baseColor 0.000 0.000 0.000
              roughness 0.70
              metalness 0.00
            }
            geometry Box { size 0.012 0.112 0.002 }
          }
        ]
      }
      Transform { translation 0.065 0.000 0.063 children [ Shape { appearance USE HEX_SLOT_APP geometry Box { size 0.012 0.112 0.002 } } ] }
      Transform { translation -0.035 0.000 0.063 children [ Shape { appearance USE HEX_SLOT_APP geometry Box { size 0.012 0.112 0.002 } } ] }
      Transform { translation -0.065 0.000 0.063 children [ Shape { appearance USE HEX_SLOT_APP geometry Box { size 0.012 0.112 0.002 } } ] }

      # Raspberry-Pi-like controller board visible between the chassis plates.
      Transform {
        translation 0.000 -0.012 0.037
        children [
          Shape {
            appearance DEF HEX_PCB_APP PBRAppearance {
              baseColor 0.000 0.145 0.050
              roughness 0.48
              metalness 0.02
            }
            geometry Box { size 0.095 0.065 0.006 }
          }
        ]
      }
      Transform { translation 0.035 -0.048 0.043 children [ Shape { appearance DEF HEX_USB_APP PBRAppearance { baseColor 0.50 0.52 0.54 roughness 0.30 metalness 0.65 } geometry Box { size 0.030 0.014 0.014 } } ] }
      Transform { translation -0.020 -0.047 0.043 children [ Shape { appearance USE HEX_USB_APP geometry Box { size 0.024 0.012 0.012 } } ] }

      # Brass/gold standoffs at the corners of the stacked body.
      Transform { translation 0.105 0.065 0.039 children [ Shape { appearance DEF HEX_BRASS_APP PBRAppearance { baseColor 0.95 0.67 0.22 roughness 0.25 metalness 0.75 } geometry Cylinder { radius 0.004 height 0.052 } } ] }
      Transform { translation 0.105 -0.065 0.039 children [ Shape { appearance USE HEX_BRASS_APP geometry Cylinder { radius 0.004 height 0.052 } } ] }
      Transform { translation -0.105 0.065 0.039 children [ Shape { appearance USE HEX_BRASS_APP geometry Cylinder { radius 0.004 height 0.052 } } ] }
      Transform { translation -0.105 -0.065 0.039 children [ Shape { appearance USE HEX_BRASS_APP geometry Cylinder { radius 0.004 height 0.052 } } ] }

      # Front face plate carrying ultrasonic transducers and a small camera.
      Transform {
        translation 0.164 0 0.040
        rotation 0 0 1 1.5708
        children [
          Shape {
            appearance USE HEX_BODY_APP
            geometry Box { size 0.070 0.010 0.060 }
          }
        ]
      }
      Transform {
        translation 0.171 0.020 0.050
        rotation 0 0 1 1.5708
        children [
          Shape {
            appearance DEF HEX_ULTRASONIC_RING_APP PBRAppearance {
              baseColor 0.76 0.77 0.78
              roughness 0.18
              metalness 0.78
            }
            geometry Cylinder { radius 0.011 height 0.006 }
          }
        ]
      }
      Transform { translation 0.171 -0.020 0.050 rotation 0 0 1 1.5708 children [ Shape { appearance USE HEX_ULTRASONIC_RING_APP geometry Cylinder { radius 0.011 height 0.006 } } ] }
      Transform { translation 0.174 0.020 0.050 rotation 0 0 1 1.5708 children [ Shape { appearance DEF HEX_SENSOR_DARK_APP PBRAppearance { baseColor 0.020 0.021 0.022 roughness 0.36 metalness 0.12 } geometry Cylinder { radius 0.007 height 0.004 } } ] }
      Transform { translation 0.174 -0.020 0.050 rotation 0 0 1 1.5708 children [ Shape { appearance USE HEX_SENSOR_DARK_APP geometry Cylinder { radius 0.007 height 0.004 } } ] }
      Transform { translation 0.176 0.000 0.025 rotation 0 0 1 1.5708 children [ Shape { appearance USE HEX_SENSOR_DARK_APP geometry Box { size 0.018 0.006 0.014 } } ] }

      # Camera mast and raised camera module above the body.
      Transform { translation -0.020 0.036 0.105 children [ Shape { appearance USE HEX_BODY_APP geometry Cylinder { radius 0.003 height 0.090 } } ] }
      Transform { translation -0.020 -0.036 0.105 children [ Shape { appearance USE HEX_BODY_APP geometry Cylinder { radius 0.003 height 0.090 } } ] }
      Transform {
        translation 0.015 0 0.158
        children [
          Shape { appearance USE HEX_BODY_APP geometry Box { size 0.038 0.018 0.032 } }
        ]
      }
      Transform { translation 0.036 0 0.158 rotation 0 0 1 1.5708 children [ Shape { appearance USE HEX_SENSOR_DARK_APP geometry Cylinder { radius 0.009 height 0.006 } } ] }
      Transform { translation 0.039 0 0.158 rotation 0 0 1 1.5708 children [ Shape { appearance USE HEX_ULTRASONIC_RING_APP geometry Cylinder { radius 0.005 height 0.003 } } ] }

      # Active camera/ultrasonic devices aligned with the visual front module.
      # Camera channels are event-encoded by DeviceMapper as:
      #   <name>.on/off.rXXcYY
      # with retina dimensions set via environment overrides.
      Camera {
        translation 0.165 0 0.050
        rotation 0 1 0 0
        name "hex_s_26_head_camera"
        width 32
        height 24
        fieldOfView 1.117
      }
      DistanceSensor {
        translation 0.165 0.024 0.050
        rotation 0 0 1 1.5708
        name "hex_s_27_ultrasonic_left"
        type "sonar"
        lookupTable [
          0.00 1000 0
          0.40 620 0
          0.80 280 0
          1.20 120 0
        ]
      }
      DistanceSensor {
        translation 0.165 -0.024 0.050
        rotation 0 0 1 1.5708
        name "hex_s_28_ultrasonic_right"
        type "sonar"
        lookupTable [
          0.00 1000 0
          0.40 620 0
          0.80 280 0
          1.20 120 0
        ]
      }

      # Simplified black servo blocks around the chassis, matching the Freenove kit silhouette.
      Transform { translation 0.125 0.115 0.004 rotation 0 0 1 0.785 children [ Shape { appearance DEF HEX_SERVO_APP PBRAppearance { baseColor 0.018 0.018 0.020 roughness 0.42 metalness 0.05 } geometry Box { size 0.045 0.030 0.028 } } ] }
      Transform { translation 0.125 -0.115 0.004 rotation 0 0 1 -0.785 children [ Shape { appearance USE HEX_SERVO_APP geometry Box { size 0.045 0.030 0.028 } } ] }
      Transform { translation 0.000 0.142 0.004 children [ Shape { appearance USE HEX_SERVO_APP geometry Box { size 0.050 0.030 0.028 } } ] }
      Transform { translation 0.000 -0.142 0.004 children [ Shape { appearance USE HEX_SERVO_APP geometry Box { size 0.050 0.030 0.028 } } ] }
      Transform { translation -0.125 0.115 0.004 rotation 0 0 1 -0.785 children [ Shape { appearance USE HEX_SERVO_APP geometry Box { size 0.045 0.030 0.028 } } ] }
      Transform { translation -0.125 -0.115 0.004 rotation 0 0 1 0.785 children [ Shape { appearance USE HEX_SERVO_APP geometry Box { size 0.045 0.030 0.028 } } ] }

      # Coarse orange/brown wire runs. They are intentionally approximate visual cables.
      Transform { translation 0.084 0.102 0.039 rotation 1 0 0 1.5708 children [ Shape { appearance DEF HEX_WIRE_APP PBRAppearance { baseColor 0.90 0.24 0.03 roughness 0.52 metalness 0.00 } geometry Cylinder { radius 0.0020 height 0.095 } } ] }
      Transform { translation 0.084 -0.102 0.039 rotation 1 0 0 1.5708 children [ Shape { appearance USE HEX_WIRE_APP geometry Cylinder { radius 0.0020 height 0.095 } } ] }
      Transform { translation -0.084 0.102 0.039 rotation 1 0 0 1.5708 children [ Shape { appearance USE HEX_WIRE_APP geometry Cylinder { radius 0.0020 height 0.095 } } ] }
      Transform { translation -0.084 -0.102 0.039 rotation 1 0 0 1.5708 children [ Shape { appearance USE HEX_WIRE_APP geometry Cylinder { radius 0.0020 height 0.095 } } ] }
      Transform { translation 0.104 0.000 0.026 rotation 0 0 1 1.5708 children [ Shape { appearance DEF HEX_RIBBON_APP PBRAppearance { baseColor 0.88 0.88 0.82 roughness 0.65 metalness 0.00 } geometry Box { size 0.012 0.120 0.003 } } ] }

      Accelerometer {
        name "hex_s_24_body_accel"
      }
      Gyro {
        name "hex_s_25_body_gyro"
      }

      # Left-front leg
      Transform {
        translation 0.1371 0.1894 -0.006
        rotation 0 0 1 0.9440
        children [
          HingeJoint {
            jointParameters HingeJointParameters {
              anchor 0 0 0
              axis 0 0 1
            }
            device [
              RotationalMotor {
                name "hex_o_000_lf_coxa"
                minPosition -0.70
                maxPosition 0.70
                maxVelocity 7.5
                maxTorque 3.2
              }
              PositionSensor {
                name "hex_s_00_lf_coxa"
              }
            ]
            endPoint Solid {
              name "hex_lf_coxa_link"
              children [
                Transform {
                  translation 0.0165 0 0
                  children [
                    Shape {
                      appearance DEF HEX_LEG_APP PBRAppearance {
                        # Black acrylic / plastic leg links and servo brackets.
                        baseColor 0.006 0.006 0.007
                        roughness 0.34
                        metalness 0.03
                      }
                      geometry Box {
                        size 0.0330 0.0160 0.0160
                      }
                    }
                  ]
                }
                HingeJoint {
                  jointParameters HingeJointParameters {
                    anchor 0.0330 0 0
                    axis 0 1 0
                    position -0.80
                  }
                  device [
                    RotationalMotor {
                      name "hex_o_001_lf_femur"
                      minPosition -1.40
                      maxPosition -0.20
                      maxVelocity 6.5
                      maxTorque 4.0
                    }
                    PositionSensor {
                      name "hex_s_01_lf_femur"
                    }
                  ]
                  endPoint Solid {
                    name "hex_lf_femur_link"
                    children [
                      Transform {
                        translation 0.0450 0 0
                        children [
                          Shape {
                            appearance USE HEX_LEG_APP
                            geometry Box {
                              size 0.0900 0.0140 0.0140
                            }
                          }
                        ]
                      }
                      HingeJoint {
                        jointParameters HingeJointParameters {
                          anchor 0.0900 0 0
                          axis 0 1 0
                          position -1.20
                        }
                        device [
                          RotationalMotor {
                            name "hex_o_002_lf_tibia"
                            minPosition -1.90
                            maxPosition -0.50
                            maxVelocity 6.0
                            maxTorque 3.6
                          }
                          PositionSensor {
                            name "hex_s_02_lf_tibia"
                          }
                        ]
                        endPoint Solid {
                          name "hex_lf_tibia_link"
                          children [
                            Transform {
                              translation 0.0550 0 0
                              children [
                                Shape {
                                  appearance USE HEX_LEG_APP
                                  geometry Box {
                                    size 0.1100 0.0120 0.0120
                                  }
                                }
                              ]
                            }
                            TouchSensor {
                              translation 0.1120 0 0
                              name "hex_s_18_lf_foot"
                              type "bumper"
                              children [
                                Shape {
                                  appearance DEF HEX_FOOT_APP PBRAppearance {
                                    baseColor 0.13 0.14 0.15
                                    roughness 0.68
                                    metalness 0.02
                                  }
                                  geometry Sphere {
                                    radius 0.010
                                  }
                                }
                              ]
                              boundingObject Sphere {
                                radius 0.010
                              }
                              physics Physics {
                                density -1
                                mass 0.010
                              }
                            }
                          ]
                          boundingObject Transform {
                            translation 0.0550 0 0
                            children [
                              Box {
                                size 0.1100 0.0340 0.0300
                              }
                            ]
                          }
                          physics Physics {
                            density -1
                            mass 0.140
                          }
                        }
                      }
                    ]
                    boundingObject Transform {
                      translation 0.0450 0 0
                      children [
                        Box {
                          size 0.0900 0.0340 0.0300
                        }
                      ]
                    }
                    physics Physics {
                      density -1
                      mass 0.150
                    }
                  }
                }
              ]
              boundingObject Transform {
                translation 0.0165 0 0
                children [
                  Box {
                    size 0.0330 0.0160 0.0160
                  }
                ]
              }
              physics Physics {
                density -1
                mass 0.040
              }
            }
          }
        ]
      }

      # Left-mid leg
      Transform {
        translation 0.2250 0.0000 -0.006
        rotation 0 0 1 0.0000
        children [
          HingeJoint {
            jointParameters HingeJointParameters {
              anchor 0 0 0
              axis 0 0 1
            }
            device [
              RotationalMotor {
                name "hex_o_003_lm_coxa"
                minPosition -0.70
                maxPosition 0.70
                maxVelocity 7.5
                maxTorque 3.2
              }
              PositionSensor {
                name "hex_s_03_lm_coxa"
              }
            ]
            endPoint Solid {
              name "hex_lm_coxa_link"
              children [
                Transform {
                  translation 0.0165 0 0
                  children [
                    Shape {
                      appearance USE HEX_LEG_APP
                      geometry Box {
                        size 0.0330 0.0160 0.0160
                      }
                    }
                  ]
                }
                HingeJoint {
                  jointParameters HingeJointParameters {
                    anchor 0.0330 0 0
                    axis 0 1 0
                    position -0.80
                  }
                  device [
                    RotationalMotor {
                      name "hex_o_004_lm_femur"
                      minPosition -1.40
                      maxPosition -0.20
                      maxVelocity 6.5
                      maxTorque 4.0
                    }
                    PositionSensor {
                      name "hex_s_04_lm_femur"
                    }
                  ]
                  endPoint Solid {
                    name "hex_lm_femur_link"
                    children [
                      Transform {
                        translation 0.0450 0 0
                        children [
                          Shape {
                            appearance USE HEX_LEG_APP
                            geometry Box {
                              size 0.0900 0.0140 0.0140
                            }
                          }
                        ]
                      }
                      HingeJoint {
                        jointParameters HingeJointParameters {
                          anchor 0.0900 0 0
                          axis 0 1 0
                          position -1.20
                        }
                        device [
                          RotationalMotor {
                            name "hex_o_005_lm_tibia"
                            minPosition -1.90
                            maxPosition -0.50
                            maxVelocity 6.0
                            maxTorque 3.6
                          }
                          PositionSensor {
                            name "hex_s_05_lm_tibia"
                          }
                        ]
                        endPoint Solid {
                          name "hex_lm_tibia_link"
                          children [
                            Transform {
                              translation 0.0550 0 0
                              children [
                                Shape {
                                  appearance USE HEX_LEG_APP
                                  geometry Box {
                                    size 0.1100 0.0120 0.0120
                                  }
                                }
                              ]
                            }
                            TouchSensor {
                              translation 0.1120 0 0
                              name "hex_s_19_lm_foot"
                              type "bumper"
                              children [
                                Shape {
                                  appearance USE HEX_FOOT_APP
                                  geometry Sphere {
                                    radius 0.010
                                  }
                                }
                              ]
                              boundingObject Sphere {
                                radius 0.010
                              }
                              physics Physics {
                                density -1
                                mass 0.010
                              }
                            }
                          ]
                          boundingObject Transform {
                            translation 0.0550 0 0
                            children [
                              Box {
                                size 0.1100 0.0340 0.0300
                              }
                            ]
                          }
                          physics Physics {
                            density -1
                            mass 0.140
                          }
                        }
                      }
                    ]
                    boundingObject Transform {
                      translation 0.0450 0 0
                      children [
                        Box {
                          size 0.0900 0.0340 0.0300
                        }
                      ]
                    }
                    physics Physics {
                      density -1
                      mass 0.150
                    }
                  }
                }
              ]
              boundingObject Transform {
                translation 0.0165 0 0
                children [
                  Box {
                    size 0.0330 0.0160 0.0160
                  }
                ]
              }
              physics Physics {
                density -1
                mass 0.040
              }
            }
          }
        ]
      }

      # Left-rear leg
      Transform {
        translation 0.1371 -0.1894 -0.006
        rotation 0 0 1 -0.9440
        children [
          HingeJoint {
            jointParameters HingeJointParameters {
              anchor 0 0 0
              axis 0 0 1
            }
            device [
              RotationalMotor {
                name "hex_o_006_lr_coxa"
                minPosition -0.70
                maxPosition 0.70
                maxVelocity 7.5
                maxTorque 3.2
              }
              PositionSensor {
                name "hex_s_06_lr_coxa"
              }
            ]
            endPoint Solid {
              name "hex_lr_coxa_link"
              children [
                Transform {
                  translation 0.0165 0 0
                  children [
                    Shape {
                      appearance USE HEX_LEG_APP
                      geometry Box {
                        size 0.0330 0.0160 0.0160
                      }
                    }
                  ]
                }
                HingeJoint {
                  jointParameters HingeJointParameters {
                    anchor 0.0330 0 0
                    axis 0 1 0
                    position -0.80
                  }
                  device [
                    RotationalMotor {
                      name "hex_o_007_lr_femur"
                      minPosition -1.40
                      maxPosition -0.20
                      maxVelocity 6.5
                      maxTorque 4.0
                    }
                    PositionSensor {
                      name "hex_s_07_lr_femur"
                    }
                  ]
                  endPoint Solid {
                    name "hex_lr_femur_link"
                    children [
                      Transform {
                        translation 0.0450 0 0
                        children [
                          Shape {
                            appearance USE HEX_LEG_APP
                            geometry Box {
                              size 0.0900 0.0140 0.0140
                            }
                          }
                        ]
                      }
                      HingeJoint {
                        jointParameters HingeJointParameters {
                          anchor 0.0900 0 0
                          axis 0 1 0
                          position -1.20
                        }
                        device [
                          RotationalMotor {
                            name "hex_o_008_lr_tibia"
                            minPosition -1.90
                            maxPosition -0.50
                            maxVelocity 6.0
                            maxTorque 3.6
                          }
                          PositionSensor {
                            name "hex_s_08_lr_tibia"
                          }
                        ]
                        endPoint Solid {
                          name "hex_lr_tibia_link"
                          children [
                            Transform {
                              translation 0.0550 0 0
                              children [
                                Shape {
                                  appearance USE HEX_LEG_APP
                                  geometry Box {
                                    size 0.1100 0.0120 0.0120
                                  }
                                }
                              ]
                            }
                            TouchSensor {
                              translation 0.1120 0 0
                              name "hex_s_20_lr_foot"
                              type "bumper"
                              children [
                                Shape {
                                  appearance USE HEX_FOOT_APP
                                  geometry Sphere {
                                    radius 0.010
                                  }
                                }
                              ]
                              boundingObject Sphere {
                                radius 0.010
                              }
                              physics Physics {
                                density -1
                                mass 0.010
                              }
                            }
                          ]
                          boundingObject Transform {
                            translation 0.0550 0 0
                            children [
                              Box {
                                size 0.1100 0.0340 0.0300
                              }
                            ]
                          }
                          physics Physics {
                            density -1
                            mass 0.140
                          }
                        }
                      }
                    ]
                    boundingObject Transform {
                      translation 0.0450 0 0
                      children [
                        Box {
                          size 0.0900 0.0340 0.0300
                        }
                      ]
                    }
                    physics Physics {
                      density -1
                      mass 0.150
                    }
                  }
                }
              ]
              boundingObject Transform {
                translation 0.0165 0 0
                children [
                  Box {
                    size 0.0330 0.0160 0.0160
                  }
                ]
              }
              physics Physics {
                density -1
                mass 0.040
              }
            }
          }
        ]
      }

      # Right-front leg
      Transform {
        translation -0.1371 0.1894 -0.006
        rotation 0 0 1 2.1980
        children [
          HingeJoint {
            jointParameters HingeJointParameters {
              anchor 0 0 0
              axis 0 0 1
            }
            device [
              RotationalMotor {
                name "hex_o_009_rf_coxa"
                minPosition -0.70
                maxPosition 0.70
                maxVelocity 7.5
                maxTorque 3.2
              }
              PositionSensor {
                name "hex_s_09_rf_coxa"
              }
            ]
            endPoint Solid {
              name "hex_rf_coxa_link"
              children [
                Transform {
                  translation 0.0165 0 0
                  children [
                    Shape {
                      appearance USE HEX_LEG_APP
                      geometry Box {
                        size 0.0330 0.0160 0.0160
                      }
                    }
                  ]
                }
                HingeJoint {
                  jointParameters HingeJointParameters {
                    anchor 0.0330 0 0
                    axis 0 1 0
                    position -0.80
                  }
                  device [
                    RotationalMotor {
                      name "hex_o_010_rf_femur"
                      minPosition -1.40
                      maxPosition -0.20
                      maxVelocity 6.5
                      maxTorque 4.0
                    }
                    PositionSensor {
                      name "hex_s_10_rf_femur"
                    }
                  ]
                  endPoint Solid {
                    name "hex_rf_femur_link"
                    children [
                      Transform {
                        translation 0.0450 0 0
                        children [
                          Shape {
                            appearance USE HEX_LEG_APP
                            geometry Box {
                              size 0.0900 0.0140 0.0140
                            }
                          }
                        ]
                      }
                      HingeJoint {
                        jointParameters HingeJointParameters {
                          anchor 0.0900 0 0
                          axis 0 1 0
                          position -1.20
                        }
                        device [
                          RotationalMotor {
                            name "hex_o_011_rf_tibia"
                            minPosition -1.90
                            maxPosition -0.50
                            maxVelocity 6.0
                            maxTorque 3.6
                          }
                          PositionSensor {
                            name "hex_s_11_rf_tibia"
                          }
                        ]
                        endPoint Solid {
                          name "hex_rf_tibia_link"
                          children [
                            Transform {
                              translation 0.0550 0 0
                              children [
                                Shape {
                                  appearance USE HEX_LEG_APP
                                  geometry Box {
                                    size 0.1100 0.0120 0.0120
                                  }
                                }
                              ]
                            }
                            TouchSensor {
                              translation 0.1120 0 0
                              name "hex_s_21_rf_foot"
                              type "bumper"
                              children [
                                Shape {
                                  appearance USE HEX_FOOT_APP
                                  geometry Sphere {
                                    radius 0.010
                                  }
                                }
                              ]
                              boundingObject Sphere {
                                radius 0.010
                              }
                              physics Physics {
                                density -1
                                mass 0.010
                              }
                            }
                          ]
                          boundingObject Transform {
                            translation 0.0550 0 0
                            children [
                              Box {
                                size 0.1100 0.0340 0.0300
                              }
                            ]
                          }
                          physics Physics {
                            density -1
                            mass 0.140
                          }
                        }
                      }
                    ]
                    boundingObject Transform {
                      translation 0.0450 0 0
                      children [
                        Box {
                          size 0.0900 0.0340 0.0300
                        }
                      ]
                    }
                    physics Physics {
                      density -1
                      mass 0.150
                    }
                  }
                }
              ]
              boundingObject Transform {
                translation 0.0165 0 0
                children [
                  Box {
                    size 0.0330 0.0160 0.0160
                  }
                ]
              }
              physics Physics {
                density -1
                mass 0.040
              }
            }
          }
        ]
      }

      # Right-mid leg
      Transform {
        translation -0.2250 0.0000 -0.006
        rotation 0 0 1 3.1416
        children [
          HingeJoint {
            jointParameters HingeJointParameters {
              anchor 0 0 0
              axis 0 0 1
            }
            device [
              RotationalMotor {
                name "hex_o_012_rm_coxa"
                minPosition -0.70
                maxPosition 0.70
                maxVelocity 7.5
                maxTorque 3.2
              }
              PositionSensor {
                name "hex_s_12_rm_coxa"
              }
            ]
            endPoint Solid {
              name "hex_rm_coxa_link"
              children [
                Transform {
                  translation 0.0165 0 0
                  children [
                    Shape {
                      appearance USE HEX_LEG_APP
                      geometry Box {
                        size 0.0330 0.0160 0.0160
                      }
                    }
                  ]
                }
                HingeJoint {
                  jointParameters HingeJointParameters {
                    anchor 0.0330 0 0
                    axis 0 1 0
                    position -0.80
                  }
                  device [
                    RotationalMotor {
                      name "hex_o_013_rm_femur"
                      minPosition -1.40
                      maxPosition -0.20
                      maxVelocity 6.5
                      maxTorque 4.0
                    }
                    PositionSensor {
                      name "hex_s_13_rm_femur"
                    }
                  ]
                  endPoint Solid {
                    name "hex_rm_femur_link"
                    children [
                      Transform {
                        translation 0.0450 0 0
                        children [
                          Shape {
                            appearance USE HEX_LEG_APP
                            geometry Box {
                              size 0.0900 0.0140 0.0140
                            }
                          }
                        ]
                      }
                      HingeJoint {
                        jointParameters HingeJointParameters {
                          anchor 0.0900 0 0
                          axis 0 1 0
                          position -1.20
                        }
                        device [
                          RotationalMotor {
                            name "hex_o_014_rm_tibia"
                            minPosition -1.90
                            maxPosition -0.50
                            maxVelocity 6.0
                            maxTorque 3.6
                          }
                          PositionSensor {
                            name "hex_s_14_rm_tibia"
                          }
                        ]
                        endPoint Solid {
                          name "hex_rm_tibia_link"
                          children [
                            Transform {
                              translation 0.0550 0 0
                              children [
                                Shape {
                                  appearance USE HEX_LEG_APP
                                  geometry Box {
                                    size 0.1100 0.0120 0.0120
                                  }
                                }
                              ]
                            }
                            TouchSensor {
                              translation 0.1120 0 0
                              name "hex_s_22_rm_foot"
                              type "bumper"
                              children [
                                Shape {
                                  appearance USE HEX_FOOT_APP
                                  geometry Sphere {
                                    radius 0.010
                                  }
                                }
                              ]
                              boundingObject Sphere {
                                radius 0.010
                              }
                              physics Physics {
                                density -1
                                mass 0.010
                              }
                            }
                          ]
                          boundingObject Transform {
                            translation 0.0550 0 0
                            children [
                              Box {
                                size 0.1100 0.0340 0.0300
                              }
                            ]
                          }
                          physics Physics {
                            density -1
                            mass 0.140
                          }
                        }
                      }
                    ]
                    boundingObject Transform {
                      translation 0.0450 0 0
                      children [
                        Box {
                          size 0.0900 0.0340 0.0300
                        }
                      ]
                    }
                    physics Physics {
                      density -1
                      mass 0.150
                    }
                  }
                }
              ]
              boundingObject Transform {
                translation 0.0165 0 0
                children [
                  Box {
                    size 0.0330 0.0160 0.0160
                  }
                ]
              }
              physics Physics {
                density -1
                mass 0.040
              }
            }
          }
        ]
      }

      # Right-rear leg
      Transform {
        translation -0.1371 -0.1894 -0.006
        rotation 0 0 1 -2.1980
        children [
          HingeJoint {
            jointParameters HingeJointParameters {
              anchor 0 0 0
              axis 0 0 1
            }
            device [
              RotationalMotor {
                name "hex_o_015_rr_coxa"
                minPosition -0.70
                maxPosition 0.70
                maxVelocity 7.5
                maxTorque 3.2
              }
              PositionSensor {
                name "hex_s_15_rr_coxa"
              }
            ]
            endPoint Solid {
              name "hex_rr_coxa_link"
              children [
                Transform {
                  translation 0.0165 0 0
                  children [
                    Shape {
                      appearance USE HEX_LEG_APP
                      geometry Box {
                        size 0.0330 0.0160 0.0160
                      }
                    }
                  ]
                }
                HingeJoint {
                  jointParameters HingeJointParameters {
                    anchor 0.0330 0 0
                    axis 0 1 0
                    position -0.80
                  }
                  device [
                    RotationalMotor {
                      name "hex_o_016_rr_femur"
                      minPosition -1.40
                      maxPosition -0.20
                      maxVelocity 6.5
                      maxTorque 4.0
                    }
                    PositionSensor {
                      name "hex_s_16_rr_femur"
                    }
                  ]
                  endPoint Solid {
                    name "hex_rr_femur_link"
                    children [
                      Transform {
                        translation 0.0450 0 0
                        children [
                          Shape {
                            appearance USE HEX_LEG_APP
                            geometry Box {
                              size 0.0900 0.0140 0.0140
                            }
                          }
                        ]
                      }
                      HingeJoint {
                        jointParameters HingeJointParameters {
                          anchor 0.0900 0 0
                          axis 0 1 0
                          position -1.20
                        }
                        device [
                          RotationalMotor {
                            name "hex_o_017_rr_tibia"
                            minPosition -1.90
                            maxPosition -0.50
                            maxVelocity 6.0
                            maxTorque 3.6
                          }
                          PositionSensor {
                            name "hex_s_17_rr_tibia"
                          }
                        ]
                        endPoint Solid {
                          name "hex_rr_tibia_link"
                          children [
                            Transform {
                              translation 0.0550 0 0
                              children [
                                Shape {
                                  appearance USE HEX_LEG_APP
                                  geometry Box {
                                    size 0.1100 0.0120 0.0120
                                  }
                                }
                              ]
                            }
                            TouchSensor {
                              translation 0.1120 0 0
                              name "hex_s_23_rr_foot"
                              type "bumper"
                              children [
                                Shape {
                                  appearance USE HEX_FOOT_APP
                                  geometry Sphere {
                                    radius 0.010
                                  }
                                }
                              ]
                              boundingObject Sphere {
                                radius 0.010
                              }
                              physics Physics {
                                density -1
                                mass 0.010
                              }
                            }
                          ]
                          boundingObject Transform {
                            translation 0.0550 0 0
                            children [
                              Box {
                                size 0.1100 0.0340 0.0300
                              }
                            ]
                          }
                          physics Physics {
                            density -1
                            mass 0.140
                          }
                        }
                      }
                    ]
                    boundingObject Transform {
                      translation 0.0450 0 0
                      children [
                        Box {
                          size 0.0900 0.0340 0.0300
                        }
                      ]
                    }
                    physics Physics {
                      density -1
                      mass 0.150
                    }
                  }
                }
              ]
              boundingObject Transform {
                translation 0.0165 0 0
                children [
                  Box {
                    size 0.0330 0.0160 0.0160
                  }
                ]
              }
              physics Physics {
                density -1
                mass 0.040
              }
            }
          }
        ]
      }

      Group {
        children IS extensionSlot
      }
    ]
    boundingObject Box {
      size 0.270 0.170 0.036
    }
    physics Physics {
      density -1
      mass 1.200
    }
  }
}
